extrapolation_detection.use_cases.s1_split_data executed
extrapolation_detection.use_cases.s2_tune_ml_regressor executed
extrapolation_detection.use_cases.s3_regressor_error_calculation executed
extrapolation_detection.use_cases.s4_true_validity_domain executed
  0%|          | 0/50 [00:00<?, ?trial/s, best loss=?]
 96%|#########6| 48/50 [00:00<00:00, 978.42trial/s, best loss: -0.46913580246913583]
  0%|          | 0/50 [00:00<?, ?trial/s, best loss=?]
 60%|######    | 30/50 [00:00<00:00, 1199.92trial/s, best loss: -0.46956521739130436]
  0%|          | 0/50 [00:00<?, ?trial/s, best loss=?]
 84%|########4 | 42/50 [00:00<00:00, 1047.83trial/s, best loss: -0.4705882352941176]
  0%|          | 0/50 [00:00<?, ?trial/s, best loss=?]
 70%|#######   | 35/50 [00:00<00:00, 1092.14trial/s, best loss: -0.38461538461538464]
  0%|          | 0/50 [00:00<?, ?trial/s, best loss=?]
 94%|#########3| 47/50 [00:00<00:00, 886.75trial/s, best loss: -0.38823529411764707]
  0%|          | 0/50 [00:00<?, ?trial/s, best loss=?]
100%|##########| 50/50 [00:00<00:00, 925.97trial/s, best loss: -0.35820895522388063]
  0%|          | 0/50 [00:00<?, ?trial/s, best loss=?]
100%|##########| 50/50 [00:00<00:00, 948.87trial/s, best loss: -0.4878048780487805]
  0%|          | 0/50 [00:00<?, ?trial/s, best loss=?]
 56%|#####6    | 28/50 [00:00<00:00, 987.85trial/s, best loss: -0.3786407766990291]
  0%|          | 0/50 [00:00<?, ?trial/s, best loss=?]
 94%|#########3| 47/50 [00:00<00:00, 919.90trial/s, best loss: -0.3686635944700461]
  0%|          | 0/50 [00:00<?, ?trial/s, best loss=?]
 98%|#########8| 49/50 [00:00<00:00, 859.64trial/s, best loss: -0.3692307692307692]
  0%|          | 0/50 [00:00<?, ?trial/s, best loss=?]
 90%|######### | 45/50 [00:00<00:00, 966.74trial/s, best loss: -0.5185185185185185]
  0%|          | 0/50 [00:00<?, ?trial/s, best loss=?]
100%|##########| 50/50 [00:00<00:00, 918.66trial/s, best loss: -0.6938775510204082]
  0%|          | 0/50 [00:00<?, ?trial/s, best loss=?]
 94%|#########3| 47/50 [00:00<00:00, 959.38trial/s, best loss: -0.32231404958677684]
  0%|          | 0/50 [00:00<?, ?trial/s, best loss=?]
 96%|#########6| 48/50 [00:00<00:00, 921.78trial/s, best loss: -0.4166666666666667]
  0%|          | 0/50 [00:00<?, ?trial/s, best loss=?]
 84%|########4 | 42/50 [00:00<00:00, 953.20trial/s, best loss: -0.4615384615384615]
  0%|          | 0/50 [00:00<?, ?trial/s, best loss=?]
 58%|#####8    | 29/50 [00:00<00:00, 1159.88trial/s, best loss: -0.3287671232876712]
  0%|          | 0/50 [00:00<?, ?trial/s, best loss=?]
 98%|#########8| 49/50 [00:00<00:00, 940.56trial/s, best loss: -0.4357541899441341]
  0%|          | 0/50 [00:00<?, ?trial/s, best loss=?]
100%|##########| 50/50 [00:00<00:00, 925.67trial/s, best loss: -0.42944785276073616]
  0%|          | 0/50 [00:00<?, ?trial/s, best loss=?]
 56%|#####6    | 28/50 [00:00<00:00, 1117.94trial/s, best loss: -0.33488372093023255]
  0%|          | 0/50 [00:00<?, ?trial/s, best loss=?]
 92%|#########2| 46/50 [00:00<00:00, 978.79trial/s, best loss: -0.693069306930693]
  0%|          | 0/50 [00:00<?, ?trial/s, best loss=?]
 60%|######    | 30/50 [00:00<00:00, 1154.01trial/s, best loss: -0.6851851851851852]
  0%|          | 0/50 [00:00<?, ?trial/s, best loss=?]
 50%|#####     | 25/50 [00:00<00:00, 1315.11trial/s, best loss: -0.6060606060606061]
  0%|          | 0/50 [00:00<?, ?trial/s, best loss=?]
 94%|#########3| 47/50 [00:00<00:00, 979.29trial/s, best loss: -0.5470085470085471]
  0%|          | 0/50 [00:00<?, ?trial/s, best loss=?]
100%|##########| 50/50 [00:00<00:00, 960.02trial/s, best loss: -0.7184466019417476]
  0%|          | 0/50 [00:00<?, ?trial/s, best loss=?]
100%|##########| 50/50 [00:00<00:00, 942.12trial/s, best loss: -0.5576923076923078]
  0%|          | 0/50 [00:00<?, ?trial/s, best loss=?]
100%|##########| 50/50 [00:00<00:00, 909.14trial/s, best loss: -0.5038167938931297]
  0%|          | 0/50 [00:00<?, ?trial/s, best loss=?]
 76%|#######6  | 38/50 [00:00<00:00, 1053.42trial/s, best loss: -0.4047619047619048]
  0%|          | 0/50 [00:00<?, ?trial/s, best loss=?]
100%|##########| 50/50 [00:00<00:00, 924.74trial/s, best loss: -0.7169811320754716]
  0%|          | 0/50 [00:00<?, ?trial/s, best loss=?]
 90%|######### | 45/50 [00:00<00:00, 976.57trial/s, best loss: -0.5112781954887219]
  0%|          | 0/50 [00:00<?, ?trial/s, best loss=?]
 94%|#########3| 47/50 [00:00<00:00, 979.21trial/s, best loss: -0.591304347826087]
  0%|          | 0/50 [00:00<?, ?trial/s, best loss=?]
100%|##########| 50/50 [00:00<00:00, 924.68trial/s, best loss: -0.6285714285714284]
  0%|          | 0/50 [00:00<?, ?trial/s, best loss=?]
100%|##########| 50/50 [00:00<00:00, 938.78trial/s, best loss: -0.44720496894409933]
  0%|          | 0/50 [00:00<?, ?trial/s, best loss=?]
100%|##########| 50/50 [00:00<00:00, 944.02trial/s, best loss: -0.39080459770114945]
  0%|          | 0/50 [00:00<?, ?trial/s, best loss=?]
 60%|######    | 30/50 [00:00<00:00, 1111.15trial/s, best loss: -0.46616541353383456]
  0%|          | 0/50 [00:00<?, ?trial/s, best loss=?]
100%|##########| 50/50 [00:00<00:00, 941.82trial/s, best loss: -0.7184466019417476]
  0%|          | 0/50 [00:00<?, ?trial/s, best loss=?]
100%|##########| 50/50 [00:00<00:00, 861.99trial/s, best loss: -0.3870967741935484]
  0%|          | 0/50 [00:00<?, ?trial/s, best loss=?]
100%|##########| 50/50 [00:00<00:00, 943.33trial/s, best loss: -0.6138613861386139]
  0%|          | 0/50 [00:00<?, ?trial/s, best loss=?]
 98%|#########8| 49/50 [00:00<00:00, 941.28trial/s, best loss: -0.3565217391304348]
  0%|          | 0/50 [00:00<?, ?trial/s, best loss=?]
100%|##########| 50/50 [00:00<00:00, 889.97trial/s, best loss: -0.3859649122807017]
  0%|          | 0/50 [00:00<?, ?trial/s, best loss=?]
100%|##########| 50/50 [00:00<00:00, 921.25trial/s, best loss: -0.4634146341463415]
  0%|          | 0/50 [00:00<?, ?trial/s, best loss=?]
 74%|#######4  | 37/50 [00:00<00:00, 1040.61trial/s, best loss: -0.38095238095238093]
  0%|          | 0/50 [00:00<?, ?trial/s, best loss=?]
100%|##########| 50/50 [00:00<00:00, 960.50trial/s, best loss: -0.45283018867924524]
  0%|          | 0/50 [00:00<?, ?trial/s, best loss=?]
 92%|#########2| 46/50 [00:00<00:00, 970.35trial/s, best loss: -0.6542056074766356]
  0%|          | 0/50 [00:00<?, ?trial/s, best loss=?]
 94%|#########3| 47/50 [00:00<00:00, 979.28trial/s, best loss: -0.5190839694656488]
  0%|          | 0/50 [00:00<?, ?trial/s, best loss=?]
 94%|#########3| 47/50 [00:00<00:00, 961.67trial/s, best loss: -0.3771428571428571]
  0%|          | 0/50 [00:00<?, ?trial/s, best loss=?]
 92%|#########2| 46/50 [00:00<00:00, 958.43trial/s, best loss: -0.36363636363636365]
  0%|          | 0/50 [00:00<?, ?trial/s, best loss=?]
 84%|########4 | 42/50 [00:00<00:00, 953.65trial/s, best loss: -0.7169811320754716]
  0%|          | 0/50 [00:00<?, ?trial/s, best loss=?]
 68%|######8   | 34/50 [00:00<00:00, 1092.68trial/s, best loss: -0.452054794520548]
  0%|          | 0/50 [00:00<?, ?trial/s, best loss=?]
 68%|######8   | 34/50 [00:00<00:00, 968.04trial/s, best loss: -0.4390243902439024]7]
  0%|          | 0/50 [00:00<?, ?trial/s, best loss=?]
 68%|######8   | 34/50 [00:00<00:00, 968.04trial/s, best loss: -0.4390243902439024]7]
  0%|          | 0/50 [00:00<?, ?trial/s, best loss=?]
 78%|#######8  | 39/50 [00:00<00:00, 1024.08trial/s, best loss: -0.45962732919254656]
  0%|          | 0/50 [00:00<?, ?trial/s, best loss=?]
100%|##########| 50/50 [00:00<00:00, 925.90trial/s, best loss: -0.39751552795031053]
  0%|          | 0/50 [00:00<?, ?trial/s, best loss=?]
 54%|#####4    | 27/50 [00:00<00:00, 1223.77trial/s, best loss: -0.3804878048780488]
  0%|          | 0/50 [00:00<?, ?trial/s, best loss=?]
100%|##########| 50/50 [00:00<00:00, 942.73trial/s, best loss: -0.4852941176470588]
  0%|          | 0/50 [00:00<?, ?trial/s, best loss=?]
 50%|#####     | 25/50 [00:00<00:00, 1316.02trial/s, best loss: -0.4390243902439024]
  0%|          | 0/50 [00:00<?, ?trial/s, best loss=?]
100%|##########| 50/50 [00:00<00:00, 934.96trial/s, best loss: -0.4126984126984127]
  0%|          | 0/50 [00:00<?, ?trial/s, best loss=?]
100%|##########| 50/50 [00:00<00:00, 939.40trial/s, best loss: -0.4268292682926829]
  0%|          | 0/50 [00:00<?, ?trial/s, best loss=?]
100%|##########| 50/50 [00:00<00:00, 943.38trial/s, best loss: -0.693069306930693]
  0%|          | 0/50 [00:00<?, ?trial/s, best loss=?]
 92%|#########2| 46/50 [00:00<00:00, 964.93trial/s, best loss: -0.7441860465116279]
  0%|          | 0/50 [00:00<?, ?trial/s, best loss=?]
100%|##########| 50/50 [00:00<00:00, 940.52trial/s, best loss: -0.33663366336633666]
  0%|          | 0/50 [00:00<?, ?trial/s, best loss=?]
100%|##########| 50/50 [00:00<00:00, 961.74trial/s, best loss: -0.6101694915254237]
  0%|          | 0/50 [00:00<?, ?trial/s, best loss=?]
 98%|#########8| 49/50 [00:00<00:00, 924.56trial/s, best loss: -0.7]
  0%|          | 0/50 [00:00<?, ?trial/s, best loss=?]
 92%|#########2| 46/50 [00:00<00:00, 958.29trial/s, best loss: -0.45517241379310347]
  0%|          | 0/50 [00:00<?, ?trial/s, best loss=?]
 58%|#####8    | 29/50 [00:00<00:00, 1204.50trial/s, best loss: -0.5686274509803921]
  0%|          | 0/50 [00:00<?, ?trial/s, best loss=?]
100%|##########| 50/50 [00:00<00:00, 924.99trial/s, best loss: -0.3888888888888889]
  0%|          | 0/50 [00:00<?, ?trial/s, best loss=?]
 58%|#####8    | 29/50 [00:00<00:00, 1156.22trial/s, best loss: -0.7441860465116279]
  0%|          | 0/50 [00:00<?, ?trial/s, best loss=?]
100%|##########| 50/50 [00:00<00:00, 926.02trial/s, best loss: -0.7526881720430108]
  0%|          | 0/50 [00:00<?, ?trial/s, best loss=?]
100%|##########| 50/50 [00:00<00:00, 942.43trial/s, best loss: -0.6938775510204082]
  0%|          | 0/50 [00:00<?, ?trial/s, best loss=?]
 94%|#########3| 47/50 [00:00<00:00, 958.21trial/s, best loss: -0.594059405940594]
  0%|          | 0/50 [00:00<?, ?trial/s, best loss=?]
 92%|#########2| 46/50 [00:00<00:00, 978.77trial/s, best loss: -0.660377358490566]
 70%|███████   | 70/100 [00:13<00:05,  5.13trial/s, best loss: -0.7526881720430108]
 98%|#########8| 49/50 [00:00<00:00, 959.80trial/s, best loss: -0.7526881720430108]]
  0%|          | 0/50 [00:00<?, ?trial/s, best loss=?]
100%|##########| 50/50 [00:00<00:00, 943.46trial/s, best loss: -0.5714285714285713]
  0%|          | 0/50 [00:00<?, ?trial/s, best loss=?]
 98%|#########8| 49/50 [00:00<00:00, 741.83trial/s, best loss: -0.5544554455445545]
  0%|          | 0/50 [00:00<?, ?trial/s, best loss=?]
100%|##########| 50/50 [00:00<00:00, 942.49trial/s, best loss: -0.6538461538461539]
  0%|          | 0/50 [00:00<?, ?trial/s, best loss=?]
 92%|#########2| 46/50 [00:00<00:00, 978.72trial/s, best loss: -0.48695652173913045]
  0%|          | 0/50 [00:00<?, ?trial/s, best loss=?]
 92%|#########2| 46/50 [00:00<00:00, 976.14trial/s, best loss: -0.7526881720430108]
  0%|          | 0/50 [00:00<?, ?trial/s, best loss=?]
 64%|######4   | 32/50 [00:00<00:00, 1138.75trial/s, best loss: -0.6194690265486726]
  0%|          | 0/50 [00:00<?, ?trial/s, best loss=?]
 92%|#########2| 46/50 [00:00<00:00, 957.29trial/s, best loss: -0.7]
  0%|          | 0/50 [00:00<?, ?trial/s, best loss=?]
 88%|########8 | 44/50 [00:00<00:00, 1000.05trial/s, best loss: -0.46979865771812074]
  0%|          | 0/50 [00:00<?, ?trial/s, best loss=?]
100%|##########| 50/50 [00:00<00:00, 920.23trial/s, best loss: -0.5686274509803921]
 80%|████████  | 80/100 [00:15<00:04,  5.00trial/s, best loss: -0.7526881720430108]
 60%|######    | 30/50 [00:00<00:00, 1197.48trial/s, best loss: -0.5714285714285713]
  0%|          | 0/50 [00:00<?, ?trial/s, best loss=?]
 76%|#######6  | 38/50 [00:00<00:00, 1027.03trial/s, best loss: -0.660377358490566]
  0%|          | 0/50 [00:00<?, ?trial/s, best loss=?]
 98%|#########8| 49/50 [00:00<00:00, 940.57trial/s, best loss: -0.4153846153846154]
  0%|          | 0/50 [00:00<?, ?trial/s, best loss=?]
100%|##########| 50/50 [00:00<00:00, 943.43trial/s, best loss: -0.5233644859813084]
  0%|          | 0/50 [00:00<?, ?trial/s, best loss=?]
100%|##########| 50/50 [00:00<00:00, 942.74trial/s, best loss: -0.3861386138613861]
  0%|          | 0/50 [00:00<?, ?trial/s, best loss=?]
100%|##########| 50/50 [00:00<00:00, 947.42trial/s, best loss: -0.7]
  0%|          | 0/50 [00:00<?, ?trial/s, best loss=?]
100%|##########| 50/50 [00:00<00:00, 934.34trial/s, best loss: -0.6260869565217392]
  0%|          | 0/50 [00:00<?, ?trial/s, best loss=?]
 74%|#######4  | 37/50 [00:00<00:00, 1055.60trial/s, best loss: -0.38461538461538464]
  0%|          | 0/50 [00:00<?, ?trial/s, best loss=?]
 98%|#########8| 49/50 [00:00<00:00, 959.26trial/s, best loss: -0.3567567567567568]
  0%|          | 0/50 [00:00<?, ?trial/s, best loss=?]
 90%|█████████ | 90/100 [00:17<00:01,  5.23trial/s, best loss: -0.7526881720430108]
100%|##########| 50/50 [00:00<00:00, 961.75trial/s, best loss: -0.4666666666666667]]
  0%|          | 0/50 [00:00<?, ?trial/s, best loss=?]
 50%|#####     | 25/50 [00:00<00:00, 1311.21trial/s, best loss: -0.5319148936170213]
  0%|          | 0/50 [00:00<?, ?trial/s, best loss=?]
100%|##########| 50/50 [00:00<00:00, 941.90trial/s, best loss: -0.33613445378151263]
  0%|          | 0/50 [00:00<?, ?trial/s, best loss=?]
100%|##########| 50/50 [00:00<00:00, 943.52trial/s, best loss: -0.660377358490566]
  0%|          | 0/50 [00:00<?, ?trial/s, best loss=?]
100%|##########| 50/50 [00:00<00:00, 877.16trial/s, best loss: -0.5742574257425742]
  0%|          | 0/50 [00:00<?, ?trial/s, best loss=?]
100%|##########| 50/50 [00:00<00:00, 906.28trial/s, best loss: -0.380952380952381]
  0%|          | 0/50 [00:00<?, ?trial/s, best loss=?]
100%|##########| 50/50 [00:00<00:00, 860.90trial/s, best loss: -0.36111111111111105]
  0%|          | 0/50 [00:00<?, ?trial/s, best loss=?]
 94%|#########3| 47/50 [00:00<00:00, 956.52trial/s, best loss: -0.5]
100%|██████████| 100/100 [00:19<00:00,  5.24trial/s, best loss: -0.7526881720430108]
KNN N_Neighbors : 2
KNN p: 2
KNN method: mean
  0%|          | 0/120 [00:00<?, ?trial/s, best loss=?]
100%|##########| 50/50 [00:00<00:00, 961.75trial/s, best loss: -0.4666666666666667]]
 54%|#####4    | 27/50 [00:00<00:00, 1033.71trial/s, best loss: -0.3116883116883117]
 54%|#####4    | 27/50 [00:00<00:00, 1033.71trial/s, best loss: -0.3116883116883117]
 54%|#####4    | 27/50 [00:00<00:00, 1033.71trial/s, best loss: -0.3116883116883117]
 54%|#####4    | 27/50 [00:00<00:00, 1033.71trial/s, best loss: -0.3116883116883117]
 54%|#####4    | 27/50 [00:00<00:00, 1033.71trial/s, best loss: -0.3116883116883117]
 54%|#####4    | 27/50 [00:00<00:00, 1033.71trial/s, best loss: -0.3116883116883117]
 54%|#####4    | 27/50 [00:00<00:00, 1033.71trial/s, best loss: -0.3116883116883117]
 54%|#####4    | 27/50 [00:00<00:00, 1033.71trial/s, best loss: -0.3116883116883117]
 54%|#####4    | 27/50 [00:00<00:00, 1033.71trial/s, best loss: -0.3116883116883117]
 54%|#####4    | 27/50 [00:00<00:00, 1033.71trial/s, best loss: -0.3116883116883117]
 54%|#####4    | 27/50 [00:00<00:00, 1033.71trial/s, best loss: -0.3116883116883117]
 54%|#####4    | 27/50 [00:00<00:00, 1033.71trial/s, best loss: -0.3116883116883117]
 54%|#####4    | 27/50 [00:00<00:00, 1033.71trial/s, best loss: -0.3116883116883117]
 54%|#####4    | 27/50 [00:00<00:00, 1033.71trial/s, best loss: -0.3116883116883117]
 54%|#####4    | 27/50 [00:00<00:00, 1033.71trial/s, best loss: -0.3116883116883117]
 54%|#####4    | 27/50 [00:00<00:00, 1033.71trial/s, best loss: -0.3116883116883117]
 54%|#####4    | 27/50 [00:00<00:00, 1033.71trial/s, best loss: -0.3116883116883117]
 54%|#####4    | 27/50 [00:00<00:00, 1033.71trial/s, best loss: -0.3116883116883117]
 54%|#####4    | 27/50 [00:00<00:00, 1033.71trial/s, best loss: -0.3116883116883117]
 54%|#####4    | 27/50 [00:00<00:00, 1033.71trial/s, best loss: -0.3116883116883117]
 54%|#####4    | 27/50 [00:00<00:00, 1033.71trial/s, best loss: -0.3116883116883117]
 54%|#####4    | 27/50 [00:00<00:00, 1033.71trial/s, best loss: -0.3116883116883117]
 54%|#####4    | 27/50 [00:00<00:00, 1033.71trial/s, best loss: -0.3116883116883117]
 54%|#####4    | 27/50 [00:00<00:00, 1033.71trial/s, best loss: -0.3116883116883117]
 54%|#####4    | 27/50 [00:00<00:00, 1033.71trial/s, best loss: -0.3116883116883117]
 54%|#####4    | 27/50 [00:00<00:00, 1033.71trial/s, best loss: -0.3116883116883117]
 54%|#####4    | 27/50 [00:00<00:00, 1033.71trial/s, best loss: -0.3116883116883117]
 54%|#####4    | 27/50 [00:00<00:00, 1033.71trial/s, best loss: -0.3116883116883117]
 54%|#####4    | 27/50 [00:00<00:00, 1033.71trial/s, best loss: -0.3116883116883117]
 54%|#####4    | 27/50 [00:00<00:00, 1033.71trial/s, best loss: -0.3116883116883117]
 54%|#####4    | 27/50 [00:00<00:00, 1033.71trial/s, best loss: -0.3116883116883117]
 54%|#####4    | 27/50 [00:00<00:00, 1033.71trial/s, best loss: -0.3116883116883117]
 54%|#####4    | 27/50 [00:00<00:00, 1033.71trial/s, best loss: -0.3116883116883117]
 54%|#####4    | 27/50 [00:00<00:00, 1033.71trial/s, best loss: -0.3116883116883117]
 54%|#####4    | 27/50 [00:00<00:00, 1033.71trial/s, best loss: -0.3116883116883117]
 54%|#####4    | 27/50 [00:00<00:00, 1033.71trial/s, best loss: -0.3116883116883117]
 54%|#####4    | 27/50 [00:00<00:00, 1033.71trial/s, best loss: -0.3116883116883117]
 54%|#####4    | 27/50 [00:00<00:00, 1033.71trial/s, best loss: -0.3116883116883117]
 54%|#####4    | 27/50 [00:00<00:00, 1033.71trial/s, best loss: -0.3116883116883117]
 54%|#####4    | 27/50 [00:00<00:00, 1033.71trial/s, best loss: -0.3116883116883117]
 54%|#####4    | 27/50 [00:00<00:00, 1033.71trial/s, best loss: -0.3116883116883117]
 54%|#####4    | 27/50 [00:00<00:00, 1033.71trial/s, best loss: -0.3116883116883117]
 54%|#####4    | 27/50 [00:00<00:00, 1033.71trial/s, best loss: -0.3116883116883117]
 54%|#####4    | 27/50 [00:00<00:00, 1033.71trial/s, best loss: -0.3116883116883117]
 54%|#####4    | 27/50 [00:00<00:00, 1033.71trial/s, best loss: -0.3116883116883117]
 54%|#####4    | 27/50 [00:00<00:00, 1033.71trial/s, best loss: -0.3116883116883117]
 54%|#####4    | 27/50 [00:00<00:00, 1033.71trial/s, best loss: -0.3116883116883117]
 54%|#####4    | 27/50 [00:00<00:00, 1033.71trial/s, best loss: -0.3116883116883117]
 54%|#####4    | 27/50 [00:00<00:00, 1033.71trial/s, best loss: -0.3116883116883117]
 54%|#####4    | 27/50 [00:00<00:00, 1033.71trial/s, best loss: -0.3116883116883117]
 54%|#####4    | 27/50 [00:00<00:00, 1033.71trial/s, best loss: -0.3116883116883117]
 54%|#####4    | 27/50 [00:00<00:00, 1033.71trial/s, best loss: -0.3116883116883117]
 54%|#####4    | 27/50 [00:00<00:00, 1033.71trial/s, best loss: -0.3116883116883117]
 54%|#####4    | 27/50 [00:00<00:00, 1033.71trial/s, best loss: -0.3116883116883117]
 54%|#####4    | 27/50 [00:00<00:00, 1033.71trial/s, best loss: -0.3116883116883117]
 54%|#####4    | 27/50 [00:00<00:00, 1033.71trial/s, best loss: -0.3116883116883117]
 54%|#####4    | 27/50 [00:00<00:00, 1033.71trial/s, best loss: -0.3116883116883117]
 54%|#####4    | 27/50 [00:00<00:00, 1033.71trial/s, best loss: -0.3116883116883117]
 54%|#####4    | 27/50 [00:00<00:00, 1033.71trial/s, best loss: -0.3116883116883117]
 54%|#####4    | 27/50 [00:00<00:00, 1033.71trial/s, best loss: -0.3116883116883117]
 54%|#####4    | 27/50 [00:00<00:00, 1033.71trial/s, best loss: -0.3116883116883117]
 54%|#####4    | 27/50 [00:00<00:00, 1033.71trial/s, best loss: -0.3116883116883117]
 54%|#####4    | 27/50 [00:00<00:00, 1033.71trial/s, best loss: -0.3116883116883117]
 54%|#####4    | 27/50 [00:00<00:00, 1033.71trial/s, best loss: -0.3116883116883117]
 54%|#####4    | 27/50 [00:00<00:00, 1033.71trial/s, best loss: -0.3116883116883117]
 54%|#####4    | 27/50 [00:00<00:00, 1033.71trial/s, best loss: -0.3116883116883117]
 54%|#####4    | 27/50 [00:00<00:00, 1033.71trial/s, best loss: -0.3116883116883117]
 54%|#####4    | 27/50 [00:00<00:00, 1033.71trial/s, best loss: -0.3116883116883117]
 54%|#####4    | 27/50 [00:00<00:00, 1033.71trial/s, best loss: -0.3116883116883117]
 54%|#####4    | 27/50 [00:00<00:00, 1033.71trial/s, best loss: -0.3116883116883117]
 54%|#####4    | 27/50 [00:00<00:00, 1033.71trial/s, best loss: -0.3116883116883117]
 54%|#####4    | 27/50 [00:00<00:00, 1033.71trial/s, best loss: -0.3116883116883117]
 54%|#####4    | 27/50 [00:00<00:00, 1033.71trial/s, best loss: -0.3116883116883117]
100%|##########| 50/50 [00:00<00:00, 909.13trial/s, best loss: -0.07133243606998654]
 39%|███▉      | 47/120 [00:02<00:04, 16.84trial/s, best loss: -0.1360544217687075]]
 94%|#########3| 47/50 [00:00<00:00, 689.48trial/s, best loss: -0.07784431137724551]
  0%|          | 0/50 [00:00<?, ?trial/s, best loss=?]
 96%|#########6| 48/50 [00:00<00:00, 919.51trial/s, best loss: -0.07720861172976985]
  0%|          | 0/50 [00:00<?, ?trial/s, best loss=?]
 68%|######8   | 34/50 [00:00<00:00, 970.23trial/s, best loss: -0.13513513513513514]
  0%|          | 0/50 [00:00<?, ?trial/s, best loss=?]
 94%|#########3| 47/50 [00:00<00:00, 901.11trial/s, best loss: -0.07652685798381162]
  0%|          | 0/50 [00:00<?, ?trial/s, best loss=?]
 82%|########2 | 41/50 [00:00<00:00, 1024.79trial/s, best loss: -0.1342281879194631]
  0%|          | 0/50 [00:00<?, ?trial/s, best loss=?]
 82%|########2 | 41/50 [00:00<00:00, 1025.04trial/s, best loss: -0.07658321060382917]
  0%|          | 0/50 [00:00<?, ?trial/s, best loss=?]
100%|##########| 50/50 [00:00<00:00, 892.88trial/s, best loss: -0.07071380920613742]
  0%|          | 0/50 [00:00<?, ?trial/s, best loss=?]
100%|##########| 50/50 [00:00<00:00, 925.95trial/s, best loss: -0.07784431137724551]
  0%|          | 0/50 [00:00<?, ?trial/s, best loss=?]
100%|##########| 50/50 [00:00<00:00, 922.30trial/s, best loss: -0.07778608825729245]
  0%|          | 0/50 [00:00<?, ?trial/s, best loss=?]
 94%|#########3| 47/50 [00:00<00:00, 723.12trial/s, best loss: -0.0774962742175857]
  0%|          | 0/50 [00:00<?, ?trial/s, best loss=?]
 74%|#######4  | 37/50 [00:00<00:00, 785.77trial/s, best loss: -0.07784431137724551]
  0%|          | 0/50 [00:00<?, ?trial/s, best loss=?]
 94%|#########3| 47/50 [00:00<00:00, 689.48trial/s, best loss: -0.07784431137724551]
  0%|          | 0/50 [00:00<?, ?trial/s, best loss=?]
100%|##########| 50/50 [00:00<00:00, 611.67trial/s, best loss: -0.07715133531157269]
  0%|          | 0/50 [00:00<?, ?trial/s, best loss=?]
100%|##########| 50/50 [00:00<00:00, 908.40trial/s, best loss: -0.07653429602888086]
  0%|          | 0/50 [00:00<?, ?trial/s, best loss=?]
100%|##########| 50/50 [00:00<00:00, 832.66trial/s, best loss: -0.07240437158469945]
  0%|          | 0/50 [00:00<?, ?trial/s, best loss=?]
 92%|#########2| 46/50 [00:00<00:00, 938.81trial/s, best loss: -0.0762589928057554]
  0%|          | 0/50 [00:00<?, ?trial/s, best loss=?]
 98%|#########8| 49/50 [00:00<00:00, 923.31trial/s, best loss: -0.07784431137724551]
  0%|          | 0/50 [00:00<?, ?trial/s, best loss=?]
 98%|#########8| 49/50 [00:00<00:00, 907.40trial/s, best loss: -0.07720861172976985]
  0%|          | 0/50 [00:00<?, ?trial/s, best loss=?]
 98%|#########8| 49/50 [00:00<00:00, 825.09trial/s, best loss: -0.07361111111111111]
  0%|          | 0/50 [00:00<?, ?trial/s, best loss=?]
100%|##########| 50/50 [00:00<00:00, 909.14trial/s, best loss: -0.0726525017135024]
  0%|          | 0/50 [00:00<?, ?trial/s, best loss=?]
100%|##########| 50/50 [00:00<00:00, 906.52trial/s, best loss: -0.0748587570621469]
  0%|          | 0/50 [00:00<?, ?trial/s, best loss=?]
100%|##########| 50/50 [00:00<00:00, 905.69trial/s, best loss: -0.07614942528735633]
  0%|          | 0/50 [00:00<?, ?trial/s, best loss=?]
 62%|######2   | 31/50 [00:00<00:00, 1068.67trial/s, best loss: -0.07669616519174041]
  0%|          | 0/50 [00:00<?, ?trial/s, best loss=?]
100%|##########| 50/50 [00:00<00:00, 908.03trial/s, best loss: -0.07109322602280348]
  0%|          | 0/50 [00:00<?, ?trial/s, best loss=?]
 92%|#########2| 46/50 [00:00<00:00, 978.77trial/s, best loss: -0.07772795216741404]
  0%|          | 0/50 [00:00<?, ?trial/s, best loss=?]
 94%|#########3| 47/50 [00:00<00:00, 959.22trial/s, best loss: -0.07784431137724551]
  0%|          | 0/50 [00:00<?, ?trial/s, best loss=?]
100%|##########| 50/50 [00:00<00:00, 908.40trial/s, best loss: -0.07653429602888086]
  0%|          | 0/50 [00:00<?, ?trial/s, best loss=?]
100%|##########| 50/50 [00:00<00:00, 939.01trial/s, best loss: -0.07703703703703703]
  0%|          | 0/50 [00:00<?, ?trial/s, best loss=?]
100%|##########| 50/50 [00:00<00:00, 909.21trial/s, best loss: -0.07366226546212648]
  0%|          | 0/50 [00:00<?, ?trial/s, best loss=?]
100%|##########| 50/50 [00:00<00:00, 892.93trial/s, best loss: -0.07475317348377997]
  0%|          | 0/50 [00:00<?, ?trial/s, best loss=?]
100%|##########| 50/50 [00:00<00:00, 892.75trial/s, best loss: -0.0762589928057554]
  0%|          | 0/50 [00:00<?, ?trial/s, best loss=?]
100%|##########| 50/50 [00:00<00:00, 847.07trial/s, best loss: -0.0757142857142857]
  0%|          | 0/50 [00:00<?, ?trial/s, best loss=?]
100%|##########| 50/50 [00:00<00:00, 909.14trial/s, best loss: -0.07663964627855564]
  0%|          | 0/50 [00:00<?, ?trial/s, best loss=?]
100%|##########| 50/50 [00:00<00:00, 958.03trial/s, best loss: -0.07755406413124534]
  0%|          | 0/50 [00:00<?, ?trial/s, best loss=?]
100%|##########| 50/50 [00:00<00:00, 909.11trial/s, best loss: -0.07641440117560618]
  0%|          | 0/50 [00:00<?, ?trial/s, best loss=?]
 96%|#########6| 48/50 [00:00<00:00, 923.13trial/s, best loss: -0.07386759581881533]
  0%|          | 0/50 [00:00<?, ?trial/s, best loss=?]
 70%|#######   | 35/50 [00:00<00:00, 1092.31trial/s, best loss: -0.0774385703648548]
  0%|          | 0/50 [00:00<?, ?trial/s, best loss=?]
100%|##########| 50/50 [00:00<00:00, 943.43trial/s, best loss: -0.13793103448275862]
  0%|          | 0/50 [00:00<?, ?trial/s, best loss=?]
100%|##########| 50/50 [00:00<00:00, 906.27trial/s, best loss: -0.07651912978244561]
  0%|          | 0/50 [00:00<?, ?trial/s, best loss=?]
100%|##########| 50/50 [00:00<00:00, 925.79trial/s, best loss: -0.07784431137724551]
  0%|          | 0/50 [00:00<?, ?trial/s, best loss=?]
100%|##########| 50/50 [00:00<00:00, 909.13trial/s, best loss: -0.10256410256410255]
  0%|          | 0/50 [00:00<?, ?trial/s, best loss=?]
100%|##########| 50/50 [00:00<00:00, 938.39trial/s, best loss: -0.07784431137724551]
  0%|          | 0/50 [00:00<?, ?trial/s, best loss=?]
100%|##########| 50/50 [00:00<00:00, 862.11trial/s, best loss: -0.07614942528735633]
  0%|          | 0/50 [00:00<?, ?trial/s, best loss=?]
100%|##########| 50/50 [00:00<00:00, 920.46trial/s, best loss: -0.0725034199726402]
  0%|          | 0/50 [00:00<?, ?trial/s, best loss=?]
 96%|#########6| 48/50 [00:00<00:00, 905.71trial/s, best loss: -0.07669616519174041]
  0%|          | 0/50 [00:00<?, ?trial/s, best loss=?]
 50%|#####     | 25/50 [00:00<00:00, 1315.87trial/s, best loss: -0.07772795216741404]
  0%|          | 0/50 [00:00<?, ?trial/s, best loss=?]
100%|##########| 50/50 [00:00<00:00, 892.99trial/s, best loss: -0.07407407407407407]
  0%|          | 0/50 [00:00<?, ?trial/s, best loss=?]
100%|##########| 50/50 [00:00<00:00, 908.29trial/s, best loss: -0.07167004732927654]
  0%|          | 0/50 [00:00<?, ?trial/s, best loss=?]
100%|##########| 50/50 [00:00<00:00, 905.06trial/s, best loss: -0.07658959537572255]
  0%|          | 0/50 [00:00<?, ?trial/s, best loss=?]
 96%|#########6| 48/50 [00:00<00:00, 923.10trial/s, best loss: -0.07658959537572255]
  0%|          | 0/50 [00:00<?, ?trial/s, best loss=?]
100%|##########| 50/50 [00:00<00:00, 921.89trial/s, best loss: -0.07720861172976985]
100%|██████████| 120/120 [00:06<00:00, 17.34trial/s, best loss: -0.13793103448275862]
OCSVM Gamma : 0.5413530219428809
extrapolation_detection.use_cases.s5_tune_detector executed
100%|##########| 50/50 [00:00<00:00, 905.06trial/s, best loss: -0.07658959537572255]
100%|##########| 50/50 [00:00<00:00, 905.06trial/s, best loss: -0.07658959537572255]
100%|##########| 50/50 [00:00<00:00, 905.06trial/s, best loss: -0.07658959537572255]
100%|##########| 50/50 [00:00<00:00, 905.06trial/s, best loss: -0.07658959537572255]
Error: failed to send plot to http://127.0.0.1:63342
Traceback (most recent call last):
  File "D:\02_PyCharm\PyCharm 2022.3.2\plugins\python\helpers\pycharm_display\datalore\display\display_.py", line 86, in _send_display_message
    urllib_request.urlopen(url, buffer)
  File "D:\01_Anaconda\envs\ADDMo-Extra\Lib\urllib\request.py", line 216, in urlopen
    return opener.open(url, data, timeout)
           ^^^^^^^^^^^^^^^^^^^^^^^^^^^^^^^
  File "D:\01_Anaconda\envs\ADDMo-Extra\Lib\urllib\request.py", line 525, in open
    response = meth(req, response)
               ^^^^^^^^^^^^^^^^^^^
  File "D:\01_Anaconda\envs\ADDMo-Extra\Lib\urllib\request.py", line 634, in http_response
    response = self.parent.error(
               ^^^^^^^^^^^^^^^^^^
  File "D:\01_Anaconda\envs\ADDMo-Extra\Lib\urllib\request.py", line 563, in error
    return self._call_chain(*args)
           ^^^^^^^^^^^^^^^^^^^^^^^
  File "D:\01_Anaconda\envs\ADDMo-Extra\Lib\urllib\request.py", line 496, in _call_chain
    result = func(*args)
             ^^^^^^^^^^^
  File "D:\01_Anaconda\envs\ADDMo-Extra\Lib\urllib\request.py", line 643, in http_error_default
    raise HTTPError(req.full_url, code, msg, hdrs, fp)
urllib.error.HTTPError: HTTP Error 500: Internal Server Error
During handling of the above exception, another exception occurred:
Traceback (most recent call last):
  File "D:\02_PyCharm\PyCharm 2022.3.2\plugins\python\helpers\pycharm_display\datalore\display\display_.py", line 61, in try_empty_proxy
    urllib_request.urlopen(url, buffer)
  File "D:\01_Anaconda\envs\ADDMo-Extra\Lib\urllib\request.py", line 216, in urlopen
    return opener.open(url, data, timeout)
           ^^^^^^^^^^^^^^^^^^^^^^^^^^^^^^^
  File "D:\01_Anaconda\envs\ADDMo-Extra\Lib\urllib\request.py", line 525, in open
    response = meth(req, response)
               ^^^^^^^^^^^^^^^^^^^
  File "D:\01_Anaconda\envs\ADDMo-Extra\Lib\urllib\request.py", line 634, in http_response
    response = self.parent.error(
               ^^^^^^^^^^^^^^^^^^
  File "D:\01_Anaconda\envs\ADDMo-Extra\Lib\urllib\request.py", line 563, in error
    return self._call_chain(*args)
           ^^^^^^^^^^^^^^^^^^^^^^^
  File "D:\01_Anaconda\envs\ADDMo-Extra\Lib\urllib\request.py", line 496, in _call_chain
    result = func(*args)
             ^^^^^^^^^^^
  File "D:\01_Anaconda\envs\ADDMo-Extra\Lib\urllib\request.py", line 643, in http_error_default
    raise HTTPError(req.full_url, code, msg, hdrs, fp)
urllib.error.HTTPError: HTTP Error 500: Internal Server Error
Error: failed to send plot to http://127.0.0.1:63342
Traceback (most recent call last):
  File "D:\02_PyCharm\PyCharm 2022.3.2\plugins\python\helpers\pycharm_display\datalore\display\display_.py", line 86, in _send_display_message
    urllib_request.urlopen(url, buffer)
  File "D:\01_Anaconda\envs\ADDMo-Extra\Lib\urllib\request.py", line 216, in urlopen
    return opener.open(url, data, timeout)
           ^^^^^^^^^^^^^^^^^^^^^^^^^^^^^^^
  File "D:\01_Anaconda\envs\ADDMo-Extra\Lib\urllib\request.py", line 525, in open
    response = meth(req, response)
               ^^^^^^^^^^^^^^^^^^^
  File "D:\01_Anaconda\envs\ADDMo-Extra\Lib\urllib\request.py", line 634, in http_response
    response = self.parent.error(
               ^^^^^^^^^^^^^^^^^^
  File "D:\01_Anaconda\envs\ADDMo-Extra\Lib\urllib\request.py", line 563, in error
    return self._call_chain(*args)
           ^^^^^^^^^^^^^^^^^^^^^^^
  File "D:\01_Anaconda\envs\ADDMo-Extra\Lib\urllib\request.py", line 496, in _call_chain
    result = func(*args)
             ^^^^^^^^^^^
  File "D:\01_Anaconda\envs\ADDMo-Extra\Lib\urllib\request.py", line 643, in http_error_default
    raise HTTPError(req.full_url, code, msg, hdrs, fp)
urllib.error.HTTPError: HTTP Error 500: Internal Server Error
During handling of the above exception, another exception occurred:
Traceback (most recent call last):
  File "D:\02_PyCharm\PyCharm 2022.3.2\plugins\python\helpers\pycharm_display\datalore\display\display_.py", line 61, in try_empty_proxy
    urllib_request.urlopen(url, buffer)
  File "D:\01_Anaconda\envs\ADDMo-Extra\Lib\urllib\request.py", line 216, in urlopen
    return opener.open(url, data, timeout)
           ^^^^^^^^^^^^^^^^^^^^^^^^^^^^^^^
  File "D:\01_Anaconda\envs\ADDMo-Extra\Lib\urllib\request.py", line 525, in open
    response = meth(req, response)
               ^^^^^^^^^^^^^^^^^^^
  File "D:\01_Anaconda\envs\ADDMo-Extra\Lib\urllib\request.py", line 634, in http_response
    response = self.parent.error(
               ^^^^^^^^^^^^^^^^^^
  File "D:\01_Anaconda\envs\ADDMo-Extra\Lib\urllib\request.py", line 563, in error
    return self._call_chain(*args)
           ^^^^^^^^^^^^^^^^^^^^^^^
  File "D:\01_Anaconda\envs\ADDMo-Extra\Lib\urllib\request.py", line 496, in _call_chain
    result = func(*args)
             ^^^^^^^^^^^
  File "D:\01_Anaconda\envs\ADDMo-Extra\Lib\urllib\request.py", line 643, in http_error_default
    raise HTTPError(req.full_url, code, msg, hdrs, fp)
urllib.error.HTTPError: HTTP Error 500: Internal Server Error
Error: failed to send plot to http://127.0.0.1:63342
Traceback (most recent call last):
  File "D:\02_PyCharm\PyCharm 2022.3.2\plugins\python\helpers\pycharm_display\datalore\display\display_.py", line 86, in _send_display_message
    urllib_request.urlopen(url, buffer)
  File "D:\01_Anaconda\envs\ADDMo-Extra\Lib\urllib\request.py", line 216, in urlopen
    return opener.open(url, data, timeout)
           ^^^^^^^^^^^^^^^^^^^^^^^^^^^^^^^
  File "D:\01_Anaconda\envs\ADDMo-Extra\Lib\urllib\request.py", line 525, in open
    response = meth(req, response)
               ^^^^^^^^^^^^^^^^^^^
  File "D:\01_Anaconda\envs\ADDMo-Extra\Lib\urllib\request.py", line 634, in http_response
    response = self.parent.error(
               ^^^^^^^^^^^^^^^^^^
  File "D:\01_Anaconda\envs\ADDMo-Extra\Lib\urllib\request.py", line 563, in error
    return self._call_chain(*args)
           ^^^^^^^^^^^^^^^^^^^^^^^
  File "D:\01_Anaconda\envs\ADDMo-Extra\Lib\urllib\request.py", line 496, in _call_chain
    result = func(*args)
             ^^^^^^^^^^^
  File "D:\01_Anaconda\envs\ADDMo-Extra\Lib\urllib\request.py", line 643, in http_error_default
    raise HTTPError(req.full_url, code, msg, hdrs, fp)
urllib.error.HTTPError: HTTP Error 500: Internal Server Error
During handling of the above exception, another exception occurred:
Traceback (most recent call last):
  File "D:\02_PyCharm\PyCharm 2022.3.2\plugins\python\helpers\pycharm_display\datalore\display\display_.py", line 61, in try_empty_proxy
    urllib_request.urlopen(url, buffer)
  File "D:\01_Anaconda\envs\ADDMo-Extra\Lib\urllib\request.py", line 216, in urlopen
    return opener.open(url, data, timeout)
           ^^^^^^^^^^^^^^^^^^^^^^^^^^^^^^^
  File "D:\01_Anaconda\envs\ADDMo-Extra\Lib\urllib\request.py", line 525, in open
    response = meth(req, response)
               ^^^^^^^^^^^^^^^^^^^
  File "D:\01_Anaconda\envs\ADDMo-Extra\Lib\urllib\request.py", line 634, in http_response
    response = self.parent.error(
               ^^^^^^^^^^^^^^^^^^
  File "D:\01_Anaconda\envs\ADDMo-Extra\Lib\urllib\request.py", line 563, in error
    return self._call_chain(*args)
           ^^^^^^^^^^^^^^^^^^^^^^^
  File "D:\01_Anaconda\envs\ADDMo-Extra\Lib\urllib\request.py", line 496, in _call_chain
    result = func(*args)
             ^^^^^^^^^^^
  File "D:\01_Anaconda\envs\ADDMo-Extra\Lib\urllib\request.py", line 643, in http_error_default
    raise HTTPError(req.full_url, code, msg, hdrs, fp)
urllib.error.HTTPError: HTTP Error 500: Internal Server Error
Error: failed to send plot to http://127.0.0.1:63342
Traceback (most recent call last):
  File "D:\02_PyCharm\PyCharm 2022.3.2\plugins\python\helpers\pycharm_display\datalore\display\display_.py", line 86, in _send_display_message
    urllib_request.urlopen(url, buffer)
  File "D:\01_Anaconda\envs\ADDMo-Extra\Lib\urllib\request.py", line 216, in urlopen
    return opener.open(url, data, timeout)
           ^^^^^^^^^^^^^^^^^^^^^^^^^^^^^^^
  File "D:\01_Anaconda\envs\ADDMo-Extra\Lib\urllib\request.py", line 525, in open
    response = meth(req, response)
               ^^^^^^^^^^^^^^^^^^^
  File "D:\01_Anaconda\envs\ADDMo-Extra\Lib\urllib\request.py", line 634, in http_response
    response = self.parent.error(
               ^^^^^^^^^^^^^^^^^^
  File "D:\01_Anaconda\envs\ADDMo-Extra\Lib\urllib\request.py", line 563, in error
    return self._call_chain(*args)
           ^^^^^^^^^^^^^^^^^^^^^^^
  File "D:\01_Anaconda\envs\ADDMo-Extra\Lib\urllib\request.py", line 496, in _call_chain
    result = func(*args)
             ^^^^^^^^^^^
  File "D:\01_Anaconda\envs\ADDMo-Extra\Lib\urllib\request.py", line 643, in http_error_default
    raise HTTPError(req.full_url, code, msg, hdrs, fp)
urllib.error.HTTPError: HTTP Error 500: Internal Server Error
During handling of the above exception, another exception occurred:
Traceback (most recent call last):
  File "D:\02_PyCharm\PyCharm 2022.3.2\plugins\python\helpers\pycharm_display\datalore\display\display_.py", line 61, in try_empty_proxy
    urllib_request.urlopen(url, buffer)
  File "D:\01_Anaconda\envs\ADDMo-Extra\Lib\urllib\request.py", line 216, in urlopen
    return opener.open(url, data, timeout)
           ^^^^^^^^^^^^^^^^^^^^^^^^^^^^^^^
  File "D:\01_Anaconda\envs\ADDMo-Extra\Lib\urllib\request.py", line 525, in open
    response = meth(req, response)
               ^^^^^^^^^^^^^^^^^^^
  File "D:\01_Anaconda\envs\ADDMo-Extra\Lib\urllib\request.py", line 634, in http_response
    response = self.parent.error(
               ^^^^^^^^^^^^^^^^^^
  File "D:\01_Anaconda\envs\ADDMo-Extra\Lib\urllib\request.py", line 563, in error
    return self._call_chain(*args)
           ^^^^^^^^^^^^^^^^^^^^^^^
  File "D:\01_Anaconda\envs\ADDMo-Extra\Lib\urllib\request.py", line 496, in _call_chain
    result = func(*args)
             ^^^^^^^^^^^
  File "D:\01_Anaconda\envs\ADDMo-Extra\Lib\urllib\request.py", line 643, in http_error_default
    raise HTTPError(req.full_url, code, msg, hdrs, fp)
urllib.error.HTTPError: HTTP Error 500: Internal Server Error
Error: failed to send plot to http://127.0.0.1:63342
Traceback (most recent call last):
  File "D:\02_PyCharm\PyCharm 2022.3.2\plugins\python\helpers\pycharm_display\datalore\display\display_.py", line 86, in _send_display_message
    urllib_request.urlopen(url, buffer)
  File "D:\01_Anaconda\envs\ADDMo-Extra\Lib\urllib\request.py", line 216, in urlopen
    return opener.open(url, data, timeout)
           ^^^^^^^^^^^^^^^^^^^^^^^^^^^^^^^
  File "D:\01_Anaconda\envs\ADDMo-Extra\Lib\urllib\request.py", line 525, in open
    response = meth(req, response)
               ^^^^^^^^^^^^^^^^^^^
  File "D:\01_Anaconda\envs\ADDMo-Extra\Lib\urllib\request.py", line 634, in http_response
    response = self.parent.error(
               ^^^^^^^^^^^^^^^^^^
  File "D:\01_Anaconda\envs\ADDMo-Extra\Lib\urllib\request.py", line 563, in error
    return self._call_chain(*args)
           ^^^^^^^^^^^^^^^^^^^^^^^
  File "D:\01_Anaconda\envs\ADDMo-Extra\Lib\urllib\request.py", line 496, in _call_chain
    result = func(*args)
             ^^^^^^^^^^^
  File "D:\01_Anaconda\envs\ADDMo-Extra\Lib\urllib\request.py", line 643, in http_error_default
    raise HTTPError(req.full_url, code, msg, hdrs, fp)
urllib.error.HTTPError: HTTP Error 500: Internal Server Error
During handling of the above exception, another exception occurred:
Traceback (most recent call last):
  File "D:\02_PyCharm\PyCharm 2022.3.2\plugins\python\helpers\pycharm_display\datalore\display\display_.py", line 61, in try_empty_proxy
    urllib_request.urlopen(url, buffer)
  File "D:\01_Anaconda\envs\ADDMo-Extra\Lib\urllib\request.py", line 216, in urlopen
    return opener.open(url, data, timeout)
           ^^^^^^^^^^^^^^^^^^^^^^^^^^^^^^^
  File "D:\01_Anaconda\envs\ADDMo-Extra\Lib\urllib\request.py", line 525, in open
    response = meth(req, response)
               ^^^^^^^^^^^^^^^^^^^
  File "D:\01_Anaconda\envs\ADDMo-Extra\Lib\urllib\request.py", line 634, in http_response
    response = self.parent.error(
               ^^^^^^^^^^^^^^^^^^
  File "D:\01_Anaconda\envs\ADDMo-Extra\Lib\urllib\request.py", line 563, in error
    return self._call_chain(*args)
           ^^^^^^^^^^^^^^^^^^^^^^^
  File "D:\01_Anaconda\envs\ADDMo-Extra\Lib\urllib\request.py", line 496, in _call_chain
    result = func(*args)
             ^^^^^^^^^^^
  File "D:\01_Anaconda\envs\ADDMo-Extra\Lib\urllib\request.py", line 643, in http_error_default
    raise HTTPError(req.full_url, code, msg, hdrs, fp)
urllib.error.HTTPError: HTTP Error 500: Internal Server Error
Error: failed to send plot to http://127.0.0.1:63342
Traceback (most recent call last):
  File "D:\02_PyCharm\PyCharm 2022.3.2\plugins\python\helpers\pycharm_display\datalore\display\display_.py", line 86, in _send_display_message
    urllib_request.urlopen(url, buffer)
  File "D:\01_Anaconda\envs\ADDMo-Extra\Lib\urllib\request.py", line 216, in urlopen
    return opener.open(url, data, timeout)
           ^^^^^^^^^^^^^^^^^^^^^^^^^^^^^^^
  File "D:\01_Anaconda\envs\ADDMo-Extra\Lib\urllib\request.py", line 525, in open
    response = meth(req, response)
               ^^^^^^^^^^^^^^^^^^^
  File "D:\01_Anaconda\envs\ADDMo-Extra\Lib\urllib\request.py", line 634, in http_response
    response = self.parent.error(
               ^^^^^^^^^^^^^^^^^^
  File "D:\01_Anaconda\envs\ADDMo-Extra\Lib\urllib\request.py", line 563, in error
    return self._call_chain(*args)
           ^^^^^^^^^^^^^^^^^^^^^^^
  File "D:\01_Anaconda\envs\ADDMo-Extra\Lib\urllib\request.py", line 496, in _call_chain
    result = func(*args)
             ^^^^^^^^^^^
  File "D:\01_Anaconda\envs\ADDMo-Extra\Lib\urllib\request.py", line 643, in http_error_default
    raise HTTPError(req.full_url, code, msg, hdrs, fp)
urllib.error.HTTPError: HTTP Error 500: Internal Server Error
During handling of the above exception, another exception occurred:
Traceback (most recent call last):
  File "D:\02_PyCharm\PyCharm 2022.3.2\plugins\python\helpers\pycharm_display\datalore\display\display_.py", line 61, in try_empty_proxy
    urllib_request.urlopen(url, buffer)
  File "D:\01_Anaconda\envs\ADDMo-Extra\Lib\urllib\request.py", line 216, in urlopen
    return opener.open(url, data, timeout)
           ^^^^^^^^^^^^^^^^^^^^^^^^^^^^^^^
  File "D:\01_Anaconda\envs\ADDMo-Extra\Lib\urllib\request.py", line 525, in open
    response = meth(req, response)
               ^^^^^^^^^^^^^^^^^^^
  File "D:\01_Anaconda\envs\ADDMo-Extra\Lib\urllib\request.py", line 634, in http_response
    response = self.parent.error(
               ^^^^^^^^^^^^^^^^^^
  File "D:\01_Anaconda\envs\ADDMo-Extra\Lib\urllib\request.py", line 563, in error
    return self._call_chain(*args)
           ^^^^^^^^^^^^^^^^^^^^^^^
  File "D:\01_Anaconda\envs\ADDMo-Extra\Lib\urllib\request.py", line 496, in _call_chain
    result = func(*args)
             ^^^^^^^^^^^
  File "D:\01_Anaconda\envs\ADDMo-Extra\Lib\urllib\request.py", line 643, in http_error_default
    raise HTTPError(req.full_url, code, msg, hdrs, fp)
urllib.error.HTTPError: HTTP Error 500: Internal Server Error
Error: failed to send plot to http://127.0.0.1:63342
Traceback (most recent call last):
  File "D:\02_PyCharm\PyCharm 2022.3.2\plugins\python\helpers\pycharm_display\datalore\display\display_.py", line 86, in _send_display_message
    urllib_request.urlopen(url, buffer)
  File "D:\01_Anaconda\envs\ADDMo-Extra\Lib\urllib\request.py", line 216, in urlopen
    return opener.open(url, data, timeout)
           ^^^^^^^^^^^^^^^^^^^^^^^^^^^^^^^
  File "D:\01_Anaconda\envs\ADDMo-Extra\Lib\urllib\request.py", line 525, in open
    response = meth(req, response)
               ^^^^^^^^^^^^^^^^^^^
  File "D:\01_Anaconda\envs\ADDMo-Extra\Lib\urllib\request.py", line 634, in http_response
    response = self.parent.error(
               ^^^^^^^^^^^^^^^^^^
  File "D:\01_Anaconda\envs\ADDMo-Extra\Lib\urllib\request.py", line 563, in error
    return self._call_chain(*args)
           ^^^^^^^^^^^^^^^^^^^^^^^
  File "D:\01_Anaconda\envs\ADDMo-Extra\Lib\urllib\request.py", line 496, in _call_chain
    result = func(*args)
             ^^^^^^^^^^^
  File "D:\01_Anaconda\envs\ADDMo-Extra\Lib\urllib\request.py", line 643, in http_error_default
    raise HTTPError(req.full_url, code, msg, hdrs, fp)
urllib.error.HTTPError: HTTP Error 500: Internal Server Error
During handling of the above exception, another exception occurred:
Traceback (most recent call last):
  File "D:\02_PyCharm\PyCharm 2022.3.2\plugins\python\helpers\pycharm_display\datalore\display\display_.py", line 61, in try_empty_proxy
    urllib_request.urlopen(url, buffer)
  File "D:\01_Anaconda\envs\ADDMo-Extra\Lib\urllib\request.py", line 216, in urlopen
    return opener.open(url, data, timeout)
           ^^^^^^^^^^^^^^^^^^^^^^^^^^^^^^^
  File "D:\01_Anaconda\envs\ADDMo-Extra\Lib\urllib\request.py", line 525, in open
    response = meth(req, response)
               ^^^^^^^^^^^^^^^^^^^
  File "D:\01_Anaconda\envs\ADDMo-Extra\Lib\urllib\request.py", line 634, in http_response
    response = self.parent.error(
               ^^^^^^^^^^^^^^^^^^
  File "D:\01_Anaconda\envs\ADDMo-Extra\Lib\urllib\request.py", line 563, in error
    return self._call_chain(*args)
           ^^^^^^^^^^^^^^^^^^^^^^^
  File "D:\01_Anaconda\envs\ADDMo-Extra\Lib\urllib\request.py", line 496, in _call_chain
    result = func(*args)
             ^^^^^^^^^^^
  File "D:\01_Anaconda\envs\ADDMo-Extra\Lib\urllib\request.py", line 643, in http_error_default
    raise HTTPError(req.full_url, code, msg, hdrs, fp)
urllib.error.HTTPError: HTTP Error 500: Internal Server Error
Error: failed to send plot to http://127.0.0.1:63342
Traceback (most recent call last):
  File "D:\02_PyCharm\PyCharm 2022.3.2\plugins\python\helpers\pycharm_display\datalore\display\display_.py", line 86, in _send_display_message
    urllib_request.urlopen(url, buffer)
  File "D:\01_Anaconda\envs\ADDMo-Extra\Lib\urllib\request.py", line 216, in urlopen
    return opener.open(url, data, timeout)
           ^^^^^^^^^^^^^^^^^^^^^^^^^^^^^^^
  File "D:\01_Anaconda\envs\ADDMo-Extra\Lib\urllib\request.py", line 525, in open
    response = meth(req, response)
               ^^^^^^^^^^^^^^^^^^^
  File "D:\01_Anaconda\envs\ADDMo-Extra\Lib\urllib\request.py", line 634, in http_response
    response = self.parent.error(
               ^^^^^^^^^^^^^^^^^^
  File "D:\01_Anaconda\envs\ADDMo-Extra\Lib\urllib\request.py", line 563, in error
    return self._call_chain(*args)
           ^^^^^^^^^^^^^^^^^^^^^^^
  File "D:\01_Anaconda\envs\ADDMo-Extra\Lib\urllib\request.py", line 496, in _call_chain
    result = func(*args)
             ^^^^^^^^^^^
  File "D:\01_Anaconda\envs\ADDMo-Extra\Lib\urllib\request.py", line 643, in http_error_default
    raise HTTPError(req.full_url, code, msg, hdrs, fp)
urllib.error.HTTPError: HTTP Error 500: Internal Server Error
During handling of the above exception, another exception occurred:
Traceback (most recent call last):
  File "D:\02_PyCharm\PyCharm 2022.3.2\plugins\python\helpers\pycharm_display\datalore\display\display_.py", line 61, in try_empty_proxy
    urllib_request.urlopen(url, buffer)
  File "D:\01_Anaconda\envs\ADDMo-Extra\Lib\urllib\request.py", line 216, in urlopen
    return opener.open(url, data, timeout)
           ^^^^^^^^^^^^^^^^^^^^^^^^^^^^^^^
  File "D:\01_Anaconda\envs\ADDMo-Extra\Lib\urllib\request.py", line 525, in open
    response = meth(req, response)
               ^^^^^^^^^^^^^^^^^^^
  File "D:\01_Anaconda\envs\ADDMo-Extra\Lib\urllib\request.py", line 634, in http_response
    response = self.parent.error(
               ^^^^^^^^^^^^^^^^^^
  File "D:\01_Anaconda\envs\ADDMo-Extra\Lib\urllib\request.py", line 563, in error
    return self._call_chain(*args)
           ^^^^^^^^^^^^^^^^^^^^^^^
  File "D:\01_Anaconda\envs\ADDMo-Extra\Lib\urllib\request.py", line 496, in _call_chain
    result = func(*args)
             ^^^^^^^^^^^
  File "D:\01_Anaconda\envs\ADDMo-Extra\Lib\urllib\request.py", line 643, in http_error_default
    raise HTTPError(req.full_url, code, msg, hdrs, fp)
urllib.error.HTTPError: HTTP Error 500: Internal Server Error
Error: failed to send plot to http://127.0.0.1:63342
Traceback (most recent call last):
  File "D:\02_PyCharm\PyCharm 2022.3.2\plugins\python\helpers\pycharm_display\datalore\display\display_.py", line 86, in _send_display_message
    urllib_request.urlopen(url, buffer)
  File "D:\01_Anaconda\envs\ADDMo-Extra\Lib\urllib\request.py", line 216, in urlopen
    return opener.open(url, data, timeout)
           ^^^^^^^^^^^^^^^^^^^^^^^^^^^^^^^
  File "D:\01_Anaconda\envs\ADDMo-Extra\Lib\urllib\request.py", line 525, in open
    response = meth(req, response)
               ^^^^^^^^^^^^^^^^^^^
  File "D:\01_Anaconda\envs\ADDMo-Extra\Lib\urllib\request.py", line 634, in http_response
    response = self.parent.error(
               ^^^^^^^^^^^^^^^^^^
  File "D:\01_Anaconda\envs\ADDMo-Extra\Lib\urllib\request.py", line 563, in error
    return self._call_chain(*args)
           ^^^^^^^^^^^^^^^^^^^^^^^
  File "D:\01_Anaconda\envs\ADDMo-Extra\Lib\urllib\request.py", line 496, in _call_chain
    result = func(*args)
             ^^^^^^^^^^^
  File "D:\01_Anaconda\envs\ADDMo-Extra\Lib\urllib\request.py", line 643, in http_error_default
    raise HTTPError(req.full_url, code, msg, hdrs, fp)
urllib.error.HTTPError: HTTP Error 500: Internal Server Error
During handling of the above exception, another exception occurred:
Traceback (most recent call last):
  File "D:\02_PyCharm\PyCharm 2022.3.2\plugins\python\helpers\pycharm_display\datalore\display\display_.py", line 61, in try_empty_proxy
    urllib_request.urlopen(url, buffer)
  File "D:\01_Anaconda\envs\ADDMo-Extra\Lib\urllib\request.py", line 216, in urlopen
    return opener.open(url, data, timeout)
           ^^^^^^^^^^^^^^^^^^^^^^^^^^^^^^^
  File "D:\01_Anaconda\envs\ADDMo-Extra\Lib\urllib\request.py", line 525, in open
    response = meth(req, response)
               ^^^^^^^^^^^^^^^^^^^
  File "D:\01_Anaconda\envs\ADDMo-Extra\Lib\urllib\request.py", line 634, in http_response
    response = self.parent.error(
               ^^^^^^^^^^^^^^^^^^
  File "D:\01_Anaconda\envs\ADDMo-Extra\Lib\urllib\request.py", line 563, in error
    return self._call_chain(*args)
           ^^^^^^^^^^^^^^^^^^^^^^^
  File "D:\01_Anaconda\envs\ADDMo-Extra\Lib\urllib\request.py", line 496, in _call_chain
    result = func(*args)
             ^^^^^^^^^^^
  File "D:\01_Anaconda\envs\ADDMo-Extra\Lib\urllib\request.py", line 643, in http_error_default
    raise HTTPError(req.full_url, code, msg, hdrs, fp)
urllib.error.HTTPError: HTTP Error 500: Internal Server Error
Error: failed to send plot to http://127.0.0.1:63342
Traceback (most recent call last):
  File "D:\02_PyCharm\PyCharm 2022.3.2\plugins\python\helpers\pycharm_display\datalore\display\display_.py", line 86, in _send_display_message
    urllib_request.urlopen(url, buffer)
  File "D:\01_Anaconda\envs\ADDMo-Extra\Lib\urllib\request.py", line 216, in urlopen
    return opener.open(url, data, timeout)
           ^^^^^^^^^^^^^^^^^^^^^^^^^^^^^^^
  File "D:\01_Anaconda\envs\ADDMo-Extra\Lib\urllib\request.py", line 525, in open
    response = meth(req, response)
               ^^^^^^^^^^^^^^^^^^^
  File "D:\01_Anaconda\envs\ADDMo-Extra\Lib\urllib\request.py", line 634, in http_response
    response = self.parent.error(
               ^^^^^^^^^^^^^^^^^^
  File "D:\01_Anaconda\envs\ADDMo-Extra\Lib\urllib\request.py", line 563, in error
    return self._call_chain(*args)
           ^^^^^^^^^^^^^^^^^^^^^^^
  File "D:\01_Anaconda\envs\ADDMo-Extra\Lib\urllib\request.py", line 496, in _call_chain
    result = func(*args)
             ^^^^^^^^^^^
  File "D:\01_Anaconda\envs\ADDMo-Extra\Lib\urllib\request.py", line 643, in http_error_default
    raise HTTPError(req.full_url, code, msg, hdrs, fp)
urllib.error.HTTPError: HTTP Error 500: Internal Server Error
During handling of the above exception, another exception occurred:
Traceback (most recent call last):
  File "D:\02_PyCharm\PyCharm 2022.3.2\plugins\python\helpers\pycharm_display\datalore\display\display_.py", line 61, in try_empty_proxy
    urllib_request.urlopen(url, buffer)
  File "D:\01_Anaconda\envs\ADDMo-Extra\Lib\urllib\request.py", line 216, in urlopen
    return opener.open(url, data, timeout)
           ^^^^^^^^^^^^^^^^^^^^^^^^^^^^^^^
  File "D:\01_Anaconda\envs\ADDMo-Extra\Lib\urllib\request.py", line 525, in open
    response = meth(req, response)
               ^^^^^^^^^^^^^^^^^^^
  File "D:\01_Anaconda\envs\ADDMo-Extra\Lib\urllib\request.py", line 634, in http_response
    response = self.parent.error(
               ^^^^^^^^^^^^^^^^^^
  File "D:\01_Anaconda\envs\ADDMo-Extra\Lib\urllib\request.py", line 563, in error
    return self._call_chain(*args)
           ^^^^^^^^^^^^^^^^^^^^^^^
  File "D:\01_Anaconda\envs\ADDMo-Extra\Lib\urllib\request.py", line 496, in _call_chain
    result = func(*args)
             ^^^^^^^^^^^
  File "D:\01_Anaconda\envs\ADDMo-Extra\Lib\urllib\request.py", line 643, in http_error_default
    raise HTTPError(req.full_url, code, msg, hdrs, fp)
urllib.error.HTTPError: HTTP Error 500: Internal Server Error
Error: failed to send plot to http://127.0.0.1:63342
Traceback (most recent call last):
  File "D:\02_PyCharm\PyCharm 2022.3.2\plugins\python\helpers\pycharm_display\datalore\display\display_.py", line 86, in _send_display_message
    urllib_request.urlopen(url, buffer)
  File "D:\01_Anaconda\envs\ADDMo-Extra\Lib\urllib\request.py", line 216, in urlopen
    return opener.open(url, data, timeout)
           ^^^^^^^^^^^^^^^^^^^^^^^^^^^^^^^
  File "D:\01_Anaconda\envs\ADDMo-Extra\Lib\urllib\request.py", line 525, in open
    response = meth(req, response)
               ^^^^^^^^^^^^^^^^^^^
  File "D:\01_Anaconda\envs\ADDMo-Extra\Lib\urllib\request.py", line 634, in http_response
    response = self.parent.error(
               ^^^^^^^^^^^^^^^^^^
  File "D:\01_Anaconda\envs\ADDMo-Extra\Lib\urllib\request.py", line 563, in error
    return self._call_chain(*args)
           ^^^^^^^^^^^^^^^^^^^^^^^
  File "D:\01_Anaconda\envs\ADDMo-Extra\Lib\urllib\request.py", line 496, in _call_chain
    result = func(*args)
             ^^^^^^^^^^^
  File "D:\01_Anaconda\envs\ADDMo-Extra\Lib\urllib\request.py", line 643, in http_error_default
    raise HTTPError(req.full_url, code, msg, hdrs, fp)
urllib.error.HTTPError: HTTP Error 500: Internal Server Error
During handling of the above exception, another exception occurred:
Traceback (most recent call last):
  File "D:\02_PyCharm\PyCharm 2022.3.2\plugins\python\helpers\pycharm_display\datalore\display\display_.py", line 61, in try_empty_proxy
    urllib_request.urlopen(url, buffer)
  File "D:\01_Anaconda\envs\ADDMo-Extra\Lib\urllib\request.py", line 216, in urlopen
    return opener.open(url, data, timeout)
           ^^^^^^^^^^^^^^^^^^^^^^^^^^^^^^^
  File "D:\01_Anaconda\envs\ADDMo-Extra\Lib\urllib\request.py", line 525, in open
    response = meth(req, response)
               ^^^^^^^^^^^^^^^^^^^
  File "D:\01_Anaconda\envs\ADDMo-Extra\Lib\urllib\request.py", line 634, in http_response
    response = self.parent.error(
               ^^^^^^^^^^^^^^^^^^
  File "D:\01_Anaconda\envs\ADDMo-Extra\Lib\urllib\request.py", line 563, in error
    return self._call_chain(*args)
           ^^^^^^^^^^^^^^^^^^^^^^^
  File "D:\01_Anaconda\envs\ADDMo-Extra\Lib\urllib\request.py", line 496, in _call_chain
    result = func(*args)
             ^^^^^^^^^^^
  File "D:\01_Anaconda\envs\ADDMo-Extra\Lib\urllib\request.py", line 643, in http_error_default
    raise HTTPError(req.full_url, code, msg, hdrs, fp)
urllib.error.HTTPError: HTTP Error 500: Internal Server Error
Error: failed to send plot to http://127.0.0.1:63342
Traceback (most recent call last):
  File "D:\02_PyCharm\PyCharm 2022.3.2\plugins\python\helpers\pycharm_display\datalore\display\display_.py", line 86, in _send_display_message
    urllib_request.urlopen(url, buffer)
  File "D:\01_Anaconda\envs\ADDMo-Extra\Lib\urllib\request.py", line 216, in urlopen
    return opener.open(url, data, timeout)
           ^^^^^^^^^^^^^^^^^^^^^^^^^^^^^^^
  File "D:\01_Anaconda\envs\ADDMo-Extra\Lib\urllib\request.py", line 525, in open
    response = meth(req, response)
               ^^^^^^^^^^^^^^^^^^^
  File "D:\01_Anaconda\envs\ADDMo-Extra\Lib\urllib\request.py", line 634, in http_response
    response = self.parent.error(
               ^^^^^^^^^^^^^^^^^^
  File "D:\01_Anaconda\envs\ADDMo-Extra\Lib\urllib\request.py", line 563, in error
    return self._call_chain(*args)
           ^^^^^^^^^^^^^^^^^^^^^^^
  File "D:\01_Anaconda\envs\ADDMo-Extra\Lib\urllib\request.py", line 496, in _call_chain
    result = func(*args)
             ^^^^^^^^^^^
  File "D:\01_Anaconda\envs\ADDMo-Extra\Lib\urllib\request.py", line 643, in http_error_default
    raise HTTPError(req.full_url, code, msg, hdrs, fp)
urllib.error.HTTPError: HTTP Error 500: Internal Server Error
During handling of the above exception, another exception occurred:
Traceback (most recent call last):
  File "D:\02_PyCharm\PyCharm 2022.3.2\plugins\python\helpers\pycharm_display\datalore\display\display_.py", line 61, in try_empty_proxy
    urllib_request.urlopen(url, buffer)
  File "D:\01_Anaconda\envs\ADDMo-Extra\Lib\urllib\request.py", line 216, in urlopen
    return opener.open(url, data, timeout)
           ^^^^^^^^^^^^^^^^^^^^^^^^^^^^^^^
  File "D:\01_Anaconda\envs\ADDMo-Extra\Lib\urllib\request.py", line 525, in open
    response = meth(req, response)
               ^^^^^^^^^^^^^^^^^^^
  File "D:\01_Anaconda\envs\ADDMo-Extra\Lib\urllib\request.py", line 634, in http_response
    response = self.parent.error(
               ^^^^^^^^^^^^^^^^^^
  File "D:\01_Anaconda\envs\ADDMo-Extra\Lib\urllib\request.py", line 563, in error
    return self._call_chain(*args)
           ^^^^^^^^^^^^^^^^^^^^^^^
  File "D:\01_Anaconda\envs\ADDMo-Extra\Lib\urllib\request.py", line 496, in _call_chain
    result = func(*args)
             ^^^^^^^^^^^
  File "D:\01_Anaconda\envs\ADDMo-Extra\Lib\urllib\request.py", line 643, in http_error_default
    raise HTTPError(req.full_url, code, msg, hdrs, fp)
urllib.error.HTTPError: HTTP Error 500: Internal Server Error
Error: failed to send plot to http://127.0.0.1:63342
Traceback (most recent call last):
  File "D:\02_PyCharm\PyCharm 2022.3.2\plugins\python\helpers\pycharm_display\datalore\display\display_.py", line 86, in _send_display_message
    urllib_request.urlopen(url, buffer)
  File "D:\01_Anaconda\envs\ADDMo-Extra\Lib\urllib\request.py", line 216, in urlopen
    return opener.open(url, data, timeout)
           ^^^^^^^^^^^^^^^^^^^^^^^^^^^^^^^
  File "D:\01_Anaconda\envs\ADDMo-Extra\Lib\urllib\request.py", line 525, in open
    response = meth(req, response)
               ^^^^^^^^^^^^^^^^^^^
  File "D:\01_Anaconda\envs\ADDMo-Extra\Lib\urllib\request.py", line 634, in http_response
    response = self.parent.error(
               ^^^^^^^^^^^^^^^^^^
  File "D:\01_Anaconda\envs\ADDMo-Extra\Lib\urllib\request.py", line 563, in error
    return self._call_chain(*args)
           ^^^^^^^^^^^^^^^^^^^^^^^
  File "D:\01_Anaconda\envs\ADDMo-Extra\Lib\urllib\request.py", line 496, in _call_chain
    result = func(*args)
             ^^^^^^^^^^^
  File "D:\01_Anaconda\envs\ADDMo-Extra\Lib\urllib\request.py", line 643, in http_error_default
    raise HTTPError(req.full_url, code, msg, hdrs, fp)
urllib.error.HTTPError: HTTP Error 500: Internal Server Error
During handling of the above exception, another exception occurred:
Traceback (most recent call last):
  File "D:\02_PyCharm\PyCharm 2022.3.2\plugins\python\helpers\pycharm_display\datalore\display\display_.py", line 61, in try_empty_proxy
    urllib_request.urlopen(url, buffer)
  File "D:\01_Anaconda\envs\ADDMo-Extra\Lib\urllib\request.py", line 216, in urlopen
    return opener.open(url, data, timeout)
           ^^^^^^^^^^^^^^^^^^^^^^^^^^^^^^^
  File "D:\01_Anaconda\envs\ADDMo-Extra\Lib\urllib\request.py", line 525, in open
    response = meth(req, response)
               ^^^^^^^^^^^^^^^^^^^
  File "D:\01_Anaconda\envs\ADDMo-Extra\Lib\urllib\request.py", line 634, in http_response
    response = self.parent.error(
               ^^^^^^^^^^^^^^^^^^
  File "D:\01_Anaconda\envs\ADDMo-Extra\Lib\urllib\request.py", line 563, in error
    return self._call_chain(*args)
           ^^^^^^^^^^^^^^^^^^^^^^^
  File "D:\01_Anaconda\envs\ADDMo-Extra\Lib\urllib\request.py", line 496, in _call_chain
    result = func(*args)
             ^^^^^^^^^^^
  File "D:\01_Anaconda\envs\ADDMo-Extra\Lib\urllib\request.py", line 643, in http_error_default
    raise HTTPError(req.full_url, code, msg, hdrs, fp)
urllib.error.HTTPError: HTTP Error 500: Internal Server Error
Error: failed to send plot to http://127.0.0.1:63342
Traceback (most recent call last):
  File "D:\02_PyCharm\PyCharm 2022.3.2\plugins\python\helpers\pycharm_display\datalore\display\display_.py", line 86, in _send_display_message
    urllib_request.urlopen(url, buffer)
  File "D:\01_Anaconda\envs\ADDMo-Extra\Lib\urllib\request.py", line 216, in urlopen
    return opener.open(url, data, timeout)
           ^^^^^^^^^^^^^^^^^^^^^^^^^^^^^^^
  File "D:\01_Anaconda\envs\ADDMo-Extra\Lib\urllib\request.py", line 525, in open
    response = meth(req, response)
               ^^^^^^^^^^^^^^^^^^^
  File "D:\01_Anaconda\envs\ADDMo-Extra\Lib\urllib\request.py", line 634, in http_response
    response = self.parent.error(
               ^^^^^^^^^^^^^^^^^^
  File "D:\01_Anaconda\envs\ADDMo-Extra\Lib\urllib\request.py", line 563, in error
    return self._call_chain(*args)
           ^^^^^^^^^^^^^^^^^^^^^^^
  File "D:\01_Anaconda\envs\ADDMo-Extra\Lib\urllib\request.py", line 496, in _call_chain
    result = func(*args)
             ^^^^^^^^^^^
  File "D:\01_Anaconda\envs\ADDMo-Extra\Lib\urllib\request.py", line 643, in http_error_default
    raise HTTPError(req.full_url, code, msg, hdrs, fp)
urllib.error.HTTPError: HTTP Error 500: Internal Server Error
During handling of the above exception, another exception occurred:
Traceback (most recent call last):
  File "D:\02_PyCharm\PyCharm 2022.3.2\plugins\python\helpers\pycharm_display\datalore\display\display_.py", line 61, in try_empty_proxy
    urllib_request.urlopen(url, buffer)
  File "D:\01_Anaconda\envs\ADDMo-Extra\Lib\urllib\request.py", line 216, in urlopen
    return opener.open(url, data, timeout)
           ^^^^^^^^^^^^^^^^^^^^^^^^^^^^^^^
  File "D:\01_Anaconda\envs\ADDMo-Extra\Lib\urllib\request.py", line 525, in open
    response = meth(req, response)
               ^^^^^^^^^^^^^^^^^^^
  File "D:\01_Anaconda\envs\ADDMo-Extra\Lib\urllib\request.py", line 634, in http_response
    response = self.parent.error(
               ^^^^^^^^^^^^^^^^^^
  File "D:\01_Anaconda\envs\ADDMo-Extra\Lib\urllib\request.py", line 563, in error
    return self._call_chain(*args)
           ^^^^^^^^^^^^^^^^^^^^^^^
  File "D:\01_Anaconda\envs\ADDMo-Extra\Lib\urllib\request.py", line 496, in _call_chain
    result = func(*args)
             ^^^^^^^^^^^
  File "D:\01_Anaconda\envs\ADDMo-Extra\Lib\urllib\request.py", line 643, in http_error_default
    raise HTTPError(req.full_url, code, msg, hdrs, fp)
urllib.error.HTTPError: HTTP Error 500: Internal Server Error
Error: failed to send plot to http://127.0.0.1:63342
Traceback (most recent call last):
  File "D:\02_PyCharm\PyCharm 2022.3.2\plugins\python\helpers\pycharm_display\datalore\display\display_.py", line 86, in _send_display_message
    urllib_request.urlopen(url, buffer)
  File "D:\01_Anaconda\envs\ADDMo-Extra\Lib\urllib\request.py", line 216, in urlopen
    return opener.open(url, data, timeout)
           ^^^^^^^^^^^^^^^^^^^^^^^^^^^^^^^
  File "D:\01_Anaconda\envs\ADDMo-Extra\Lib\urllib\request.py", line 525, in open
    response = meth(req, response)
               ^^^^^^^^^^^^^^^^^^^
  File "D:\01_Anaconda\envs\ADDMo-Extra\Lib\urllib\request.py", line 634, in http_response
    response = self.parent.error(
               ^^^^^^^^^^^^^^^^^^
  File "D:\01_Anaconda\envs\ADDMo-Extra\Lib\urllib\request.py", line 563, in error
    return self._call_chain(*args)
           ^^^^^^^^^^^^^^^^^^^^^^^
  File "D:\01_Anaconda\envs\ADDMo-Extra\Lib\urllib\request.py", line 496, in _call_chain
    result = func(*args)
             ^^^^^^^^^^^
  File "D:\01_Anaconda\envs\ADDMo-Extra\Lib\urllib\request.py", line 643, in http_error_default
    raise HTTPError(req.full_url, code, msg, hdrs, fp)
urllib.error.HTTPError: HTTP Error 500: Internal Server Error
During handling of the above exception, another exception occurred:
Traceback (most recent call last):
  File "D:\02_PyCharm\PyCharm 2022.3.2\plugins\python\helpers\pycharm_display\datalore\display\display_.py", line 61, in try_empty_proxy
    urllib_request.urlopen(url, buffer)
  File "D:\01_Anaconda\envs\ADDMo-Extra\Lib\urllib\request.py", line 216, in urlopen
    return opener.open(url, data, timeout)
           ^^^^^^^^^^^^^^^^^^^^^^^^^^^^^^^
  File "D:\01_Anaconda\envs\ADDMo-Extra\Lib\urllib\request.py", line 525, in open
    response = meth(req, response)
               ^^^^^^^^^^^^^^^^^^^
  File "D:\01_Anaconda\envs\ADDMo-Extra\Lib\urllib\request.py", line 634, in http_response
    response = self.parent.error(
               ^^^^^^^^^^^^^^^^^^
  File "D:\01_Anaconda\envs\ADDMo-Extra\Lib\urllib\request.py", line 563, in error
    return self._call_chain(*args)
           ^^^^^^^^^^^^^^^^^^^^^^^
  File "D:\01_Anaconda\envs\ADDMo-Extra\Lib\urllib\request.py", line 496, in _call_chain
    result = func(*args)
             ^^^^^^^^^^^
  File "D:\01_Anaconda\envs\ADDMo-Extra\Lib\urllib\request.py", line 643, in http_error_default
    raise HTTPError(req.full_url, code, msg, hdrs, fp)
urllib.error.HTTPError: HTTP Error 500: Internal Server Error
Error: failed to send plot to http://127.0.0.1:63342
Traceback (most recent call last):
  File "D:\02_PyCharm\PyCharm 2022.3.2\plugins\python\helpers\pycharm_display\datalore\display\display_.py", line 86, in _send_display_message
    urllib_request.urlopen(url, buffer)
  File "D:\01_Anaconda\envs\ADDMo-Extra\Lib\urllib\request.py", line 216, in urlopen
    return opener.open(url, data, timeout)
           ^^^^^^^^^^^^^^^^^^^^^^^^^^^^^^^
  File "D:\01_Anaconda\envs\ADDMo-Extra\Lib\urllib\request.py", line 525, in open
    response = meth(req, response)
               ^^^^^^^^^^^^^^^^^^^
  File "D:\01_Anaconda\envs\ADDMo-Extra\Lib\urllib\request.py", line 634, in http_response
    response = self.parent.error(
               ^^^^^^^^^^^^^^^^^^
  File "D:\01_Anaconda\envs\ADDMo-Extra\Lib\urllib\request.py", line 563, in error
    return self._call_chain(*args)
           ^^^^^^^^^^^^^^^^^^^^^^^
  File "D:\01_Anaconda\envs\ADDMo-Extra\Lib\urllib\request.py", line 496, in _call_chain
    result = func(*args)
             ^^^^^^^^^^^
  File "D:\01_Anaconda\envs\ADDMo-Extra\Lib\urllib\request.py", line 643, in http_error_default
    raise HTTPError(req.full_url, code, msg, hdrs, fp)
urllib.error.HTTPError: HTTP Error 500: Internal Server Error
During handling of the above exception, another exception occurred:
Traceback (most recent call last):
  File "D:\02_PyCharm\PyCharm 2022.3.2\plugins\python\helpers\pycharm_display\datalore\display\display_.py", line 61, in try_empty_proxy
    urllib_request.urlopen(url, buffer)
  File "D:\01_Anaconda\envs\ADDMo-Extra\Lib\urllib\request.py", line 216, in urlopen
    return opener.open(url, data, timeout)
           ^^^^^^^^^^^^^^^^^^^^^^^^^^^^^^^
  File "D:\01_Anaconda\envs\ADDMo-Extra\Lib\urllib\request.py", line 525, in open
    response = meth(req, response)
               ^^^^^^^^^^^^^^^^^^^
  File "D:\01_Anaconda\envs\ADDMo-Extra\Lib\urllib\request.py", line 634, in http_response
    response = self.parent.error(
               ^^^^^^^^^^^^^^^^^^
  File "D:\01_Anaconda\envs\ADDMo-Extra\Lib\urllib\request.py", line 563, in error
    return self._call_chain(*args)
           ^^^^^^^^^^^^^^^^^^^^^^^
  File "D:\01_Anaconda\envs\ADDMo-Extra\Lib\urllib\request.py", line 496, in _call_chain
    result = func(*args)
             ^^^^^^^^^^^
  File "D:\01_Anaconda\envs\ADDMo-Extra\Lib\urllib\request.py", line 643, in http_error_default
    raise HTTPError(req.full_url, code, msg, hdrs, fp)
urllib.error.HTTPError: HTTP Error 500: Internal Server Error
Error: failed to send plot to http://127.0.0.1:63342
Traceback (most recent call last):
  File "D:\02_PyCharm\PyCharm 2022.3.2\plugins\python\helpers\pycharm_display\datalore\display\display_.py", line 86, in _send_display_message
    urllib_request.urlopen(url, buffer)
  File "D:\01_Anaconda\envs\ADDMo-Extra\Lib\urllib\request.py", line 216, in urlopen
    return opener.open(url, data, timeout)
           ^^^^^^^^^^^^^^^^^^^^^^^^^^^^^^^
  File "D:\01_Anaconda\envs\ADDMo-Extra\Lib\urllib\request.py", line 525, in open
    response = meth(req, response)
               ^^^^^^^^^^^^^^^^^^^
  File "D:\01_Anaconda\envs\ADDMo-Extra\Lib\urllib\request.py", line 634, in http_response
    response = self.parent.error(
               ^^^^^^^^^^^^^^^^^^
  File "D:\01_Anaconda\envs\ADDMo-Extra\Lib\urllib\request.py", line 563, in error
    return self._call_chain(*args)
           ^^^^^^^^^^^^^^^^^^^^^^^
  File "D:\01_Anaconda\envs\ADDMo-Extra\Lib\urllib\request.py", line 496, in _call_chain
    result = func(*args)
             ^^^^^^^^^^^
  File "D:\01_Anaconda\envs\ADDMo-Extra\Lib\urllib\request.py", line 643, in http_error_default
    raise HTTPError(req.full_url, code, msg, hdrs, fp)
urllib.error.HTTPError: HTTP Error 500: Internal Server Error
During handling of the above exception, another exception occurred:
Traceback (most recent call last):
  File "D:\02_PyCharm\PyCharm 2022.3.2\plugins\python\helpers\pycharm_display\datalore\display\display_.py", line 61, in try_empty_proxy
    urllib_request.urlopen(url, buffer)
  File "D:\01_Anaconda\envs\ADDMo-Extra\Lib\urllib\request.py", line 216, in urlopen
    return opener.open(url, data, timeout)
           ^^^^^^^^^^^^^^^^^^^^^^^^^^^^^^^
  File "D:\01_Anaconda\envs\ADDMo-Extra\Lib\urllib\request.py", line 525, in open
    response = meth(req, response)
               ^^^^^^^^^^^^^^^^^^^
  File "D:\01_Anaconda\envs\ADDMo-Extra\Lib\urllib\request.py", line 634, in http_response
    response = self.parent.error(
               ^^^^^^^^^^^^^^^^^^
  File "D:\01_Anaconda\envs\ADDMo-Extra\Lib\urllib\request.py", line 563, in error
    return self._call_chain(*args)
           ^^^^^^^^^^^^^^^^^^^^^^^
  File "D:\01_Anaconda\envs\ADDMo-Extra\Lib\urllib\request.py", line 496, in _call_chain
    result = func(*args)
             ^^^^^^^^^^^
  File "D:\01_Anaconda\envs\ADDMo-Extra\Lib\urllib\request.py", line 643, in http_error_default
    raise HTTPError(req.full_url, code, msg, hdrs, fp)
urllib.error.HTTPError: HTTP Error 500: Internal Server Error
Error: failed to send plot to http://127.0.0.1:63342
Traceback (most recent call last):
  File "D:\02_PyCharm\PyCharm 2022.3.2\plugins\python\helpers\pycharm_display\datalore\display\display_.py", line 86, in _send_display_message
    urllib_request.urlopen(url, buffer)
  File "D:\01_Anaconda\envs\ADDMo-Extra\Lib\urllib\request.py", line 216, in urlopen
    return opener.open(url, data, timeout)
           ^^^^^^^^^^^^^^^^^^^^^^^^^^^^^^^
  File "D:\01_Anaconda\envs\ADDMo-Extra\Lib\urllib\request.py", line 525, in open
    response = meth(req, response)
               ^^^^^^^^^^^^^^^^^^^
  File "D:\01_Anaconda\envs\ADDMo-Extra\Lib\urllib\request.py", line 634, in http_response
    response = self.parent.error(
               ^^^^^^^^^^^^^^^^^^
  File "D:\01_Anaconda\envs\ADDMo-Extra\Lib\urllib\request.py", line 563, in error
    return self._call_chain(*args)
           ^^^^^^^^^^^^^^^^^^^^^^^
  File "D:\01_Anaconda\envs\ADDMo-Extra\Lib\urllib\request.py", line 496, in _call_chain
    result = func(*args)
             ^^^^^^^^^^^
  File "D:\01_Anaconda\envs\ADDMo-Extra\Lib\urllib\request.py", line 643, in http_error_default
    raise HTTPError(req.full_url, code, msg, hdrs, fp)
urllib.error.HTTPError: HTTP Error 500: Internal Server Error
During handling of the above exception, another exception occurred:
Traceback (most recent call last):
  File "D:\02_PyCharm\PyCharm 2022.3.2\plugins\python\helpers\pycharm_display\datalore\display\display_.py", line 61, in try_empty_proxy
    urllib_request.urlopen(url, buffer)
  File "D:\01_Anaconda\envs\ADDMo-Extra\Lib\urllib\request.py", line 216, in urlopen
    return opener.open(url, data, timeout)
           ^^^^^^^^^^^^^^^^^^^^^^^^^^^^^^^
  File "D:\01_Anaconda\envs\ADDMo-Extra\Lib\urllib\request.py", line 525, in open
    response = meth(req, response)
               ^^^^^^^^^^^^^^^^^^^
  File "D:\01_Anaconda\envs\ADDMo-Extra\Lib\urllib\request.py", line 634, in http_response
    response = self.parent.error(
               ^^^^^^^^^^^^^^^^^^
  File "D:\01_Anaconda\envs\ADDMo-Extra\Lib\urllib\request.py", line 563, in error
    return self._call_chain(*args)
           ^^^^^^^^^^^^^^^^^^^^^^^
  File "D:\01_Anaconda\envs\ADDMo-Extra\Lib\urllib\request.py", line 496, in _call_chain
    result = func(*args)
             ^^^^^^^^^^^
  File "D:\01_Anaconda\envs\ADDMo-Extra\Lib\urllib\request.py", line 643, in http_error_default
    raise HTTPError(req.full_url, code, msg, hdrs, fp)
urllib.error.HTTPError: HTTP Error 500: Internal Server Error
Error: failed to send plot to http://127.0.0.1:63342
Traceback (most recent call last):
  File "D:\02_PyCharm\PyCharm 2022.3.2\plugins\python\helpers\pycharm_display\datalore\display\display_.py", line 86, in _send_display_message
    urllib_request.urlopen(url, buffer)
  File "D:\01_Anaconda\envs\ADDMo-Extra\Lib\urllib\request.py", line 216, in urlopen
    return opener.open(url, data, timeout)
           ^^^^^^^^^^^^^^^^^^^^^^^^^^^^^^^
  File "D:\01_Anaconda\envs\ADDMo-Extra\Lib\urllib\request.py", line 525, in open
    response = meth(req, response)
               ^^^^^^^^^^^^^^^^^^^
  File "D:\01_Anaconda\envs\ADDMo-Extra\Lib\urllib\request.py", line 634, in http_response
    response = self.parent.error(
               ^^^^^^^^^^^^^^^^^^
  File "D:\01_Anaconda\envs\ADDMo-Extra\Lib\urllib\request.py", line 563, in error
    return self._call_chain(*args)
           ^^^^^^^^^^^^^^^^^^^^^^^
  File "D:\01_Anaconda\envs\ADDMo-Extra\Lib\urllib\request.py", line 496, in _call_chain
    result = func(*args)
             ^^^^^^^^^^^
  File "D:\01_Anaconda\envs\ADDMo-Extra\Lib\urllib\request.py", line 643, in http_error_default
    raise HTTPError(req.full_url, code, msg, hdrs, fp)
urllib.error.HTTPError: HTTP Error 500: Internal Server Error
During handling of the above exception, another exception occurred:
Traceback (most recent call last):
  File "D:\02_PyCharm\PyCharm 2022.3.2\plugins\python\helpers\pycharm_display\datalore\display\display_.py", line 61, in try_empty_proxy
    urllib_request.urlopen(url, buffer)
  File "D:\01_Anaconda\envs\ADDMo-Extra\Lib\urllib\request.py", line 216, in urlopen
    return opener.open(url, data, timeout)
           ^^^^^^^^^^^^^^^^^^^^^^^^^^^^^^^
  File "D:\01_Anaconda\envs\ADDMo-Extra\Lib\urllib\request.py", line 525, in open
    response = meth(req, response)
               ^^^^^^^^^^^^^^^^^^^
  File "D:\01_Anaconda\envs\ADDMo-Extra\Lib\urllib\request.py", line 634, in http_response
    response = self.parent.error(
               ^^^^^^^^^^^^^^^^^^
  File "D:\01_Anaconda\envs\ADDMo-Extra\Lib\urllib\request.py", line 563, in error
    return self._call_chain(*args)
           ^^^^^^^^^^^^^^^^^^^^^^^
  File "D:\01_Anaconda\envs\ADDMo-Extra\Lib\urllib\request.py", line 496, in _call_chain
    result = func(*args)
             ^^^^^^^^^^^
  File "D:\01_Anaconda\envs\ADDMo-Extra\Lib\urllib\request.py", line 643, in http_error_default
    raise HTTPError(req.full_url, code, msg, hdrs, fp)
urllib.error.HTTPError: HTTP Error 500: Internal Server Error
Error: failed to send plot to http://127.0.0.1:63342
Traceback (most recent call last):
  File "D:\02_PyCharm\PyCharm 2022.3.2\plugins\python\helpers\pycharm_display\datalore\display\display_.py", line 86, in _send_display_message
    urllib_request.urlopen(url, buffer)
  File "D:\01_Anaconda\envs\ADDMo-Extra\Lib\urllib\request.py", line 216, in urlopen
    return opener.open(url, data, timeout)
           ^^^^^^^^^^^^^^^^^^^^^^^^^^^^^^^
  File "D:\01_Anaconda\envs\ADDMo-Extra\Lib\urllib\request.py", line 525, in open
    response = meth(req, response)
               ^^^^^^^^^^^^^^^^^^^
  File "D:\01_Anaconda\envs\ADDMo-Extra\Lib\urllib\request.py", line 634, in http_response
    response = self.parent.error(
               ^^^^^^^^^^^^^^^^^^
  File "D:\01_Anaconda\envs\ADDMo-Extra\Lib\urllib\request.py", line 563, in error
    return self._call_chain(*args)
           ^^^^^^^^^^^^^^^^^^^^^^^
  File "D:\01_Anaconda\envs\ADDMo-Extra\Lib\urllib\request.py", line 496, in _call_chain
    result = func(*args)
             ^^^^^^^^^^^
  File "D:\01_Anaconda\envs\ADDMo-Extra\Lib\urllib\request.py", line 643, in http_error_default
    raise HTTPError(req.full_url, code, msg, hdrs, fp)
urllib.error.HTTPError: HTTP Error 500: Internal Server Error
During handling of the above exception, another exception occurred:
Traceback (most recent call last):
  File "D:\02_PyCharm\PyCharm 2022.3.2\plugins\python\helpers\pycharm_display\datalore\display\display_.py", line 61, in try_empty_proxy
    urllib_request.urlopen(url, buffer)
  File "D:\01_Anaconda\envs\ADDMo-Extra\Lib\urllib\request.py", line 216, in urlopen
    return opener.open(url, data, timeout)
           ^^^^^^^^^^^^^^^^^^^^^^^^^^^^^^^
  File "D:\01_Anaconda\envs\ADDMo-Extra\Lib\urllib\request.py", line 525, in open
    response = meth(req, response)
               ^^^^^^^^^^^^^^^^^^^
  File "D:\01_Anaconda\envs\ADDMo-Extra\Lib\urllib\request.py", line 634, in http_response
    response = self.parent.error(
               ^^^^^^^^^^^^^^^^^^
  File "D:\01_Anaconda\envs\ADDMo-Extra\Lib\urllib\request.py", line 563, in error
    return self._call_chain(*args)
           ^^^^^^^^^^^^^^^^^^^^^^^
  File "D:\01_Anaconda\envs\ADDMo-Extra\Lib\urllib\request.py", line 496, in _call_chain
    result = func(*args)
             ^^^^^^^^^^^
  File "D:\01_Anaconda\envs\ADDMo-Extra\Lib\urllib\request.py", line 643, in http_error_default
    raise HTTPError(req.full_url, code, msg, hdrs, fp)
urllib.error.HTTPError: HTTP Error 500: Internal Server Error
Error: failed to send plot to http://127.0.0.1:63342
Traceback (most recent call last):
  File "D:\02_PyCharm\PyCharm 2022.3.2\plugins\python\helpers\pycharm_display\datalore\display\display_.py", line 86, in _send_display_message
    urllib_request.urlopen(url, buffer)
  File "D:\01_Anaconda\envs\ADDMo-Extra\Lib\urllib\request.py", line 216, in urlopen
    return opener.open(url, data, timeout)
           ^^^^^^^^^^^^^^^^^^^^^^^^^^^^^^^
  File "D:\01_Anaconda\envs\ADDMo-Extra\Lib\urllib\request.py", line 525, in open
    response = meth(req, response)
               ^^^^^^^^^^^^^^^^^^^
  File "D:\01_Anaconda\envs\ADDMo-Extra\Lib\urllib\request.py", line 634, in http_response
    response = self.parent.error(
               ^^^^^^^^^^^^^^^^^^
  File "D:\01_Anaconda\envs\ADDMo-Extra\Lib\urllib\request.py", line 563, in error
    return self._call_chain(*args)
           ^^^^^^^^^^^^^^^^^^^^^^^
  File "D:\01_Anaconda\envs\ADDMo-Extra\Lib\urllib\request.py", line 496, in _call_chain
    result = func(*args)
             ^^^^^^^^^^^
  File "D:\01_Anaconda\envs\ADDMo-Extra\Lib\urllib\request.py", line 643, in http_error_default
    raise HTTPError(req.full_url, code, msg, hdrs, fp)
urllib.error.HTTPError: HTTP Error 500: Internal Server Error
During handling of the above exception, another exception occurred:
Traceback (most recent call last):
  File "D:\02_PyCharm\PyCharm 2022.3.2\plugins\python\helpers\pycharm_display\datalore\display\display_.py", line 61, in try_empty_proxy
    urllib_request.urlopen(url, buffer)
  File "D:\01_Anaconda\envs\ADDMo-Extra\Lib\urllib\request.py", line 216, in urlopen
    return opener.open(url, data, timeout)
           ^^^^^^^^^^^^^^^^^^^^^^^^^^^^^^^
  File "D:\01_Anaconda\envs\ADDMo-Extra\Lib\urllib\request.py", line 525, in open
    response = meth(req, response)
               ^^^^^^^^^^^^^^^^^^^
  File "D:\01_Anaconda\envs\ADDMo-Extra\Lib\urllib\request.py", line 634, in http_response
    response = self.parent.error(
               ^^^^^^^^^^^^^^^^^^
  File "D:\01_Anaconda\envs\ADDMo-Extra\Lib\urllib\request.py", line 563, in error
    return self._call_chain(*args)
           ^^^^^^^^^^^^^^^^^^^^^^^
  File "D:\01_Anaconda\envs\ADDMo-Extra\Lib\urllib\request.py", line 496, in _call_chain
    result = func(*args)
             ^^^^^^^^^^^
  File "D:\01_Anaconda\envs\ADDMo-Extra\Lib\urllib\request.py", line 643, in http_error_default
    raise HTTPError(req.full_url, code, msg, hdrs, fp)
urllib.error.HTTPError: HTTP Error 500: Internal Server Error
Error: failed to send plot to http://127.0.0.1:63342
Traceback (most recent call last):
  File "D:\02_PyCharm\PyCharm 2022.3.2\plugins\python\helpers\pycharm_display\datalore\display\display_.py", line 86, in _send_display_message
    urllib_request.urlopen(url, buffer)
  File "D:\01_Anaconda\envs\ADDMo-Extra\Lib\urllib\request.py", line 216, in urlopen
    return opener.open(url, data, timeout)
           ^^^^^^^^^^^^^^^^^^^^^^^^^^^^^^^
  File "D:\01_Anaconda\envs\ADDMo-Extra\Lib\urllib\request.py", line 525, in open
    response = meth(req, response)
               ^^^^^^^^^^^^^^^^^^^
  File "D:\01_Anaconda\envs\ADDMo-Extra\Lib\urllib\request.py", line 634, in http_response
    response = self.parent.error(
               ^^^^^^^^^^^^^^^^^^
  File "D:\01_Anaconda\envs\ADDMo-Extra\Lib\urllib\request.py", line 563, in error
    return self._call_chain(*args)
           ^^^^^^^^^^^^^^^^^^^^^^^
  File "D:\01_Anaconda\envs\ADDMo-Extra\Lib\urllib\request.py", line 496, in _call_chain
    result = func(*args)
             ^^^^^^^^^^^
  File "D:\01_Anaconda\envs\ADDMo-Extra\Lib\urllib\request.py", line 643, in http_error_default
    raise HTTPError(req.full_url, code, msg, hdrs, fp)
urllib.error.HTTPError: HTTP Error 500: Internal Server Error
During handling of the above exception, another exception occurred:
Traceback (most recent call last):
  File "D:\02_PyCharm\PyCharm 2022.3.2\plugins\python\helpers\pycharm_display\datalore\display\display_.py", line 61, in try_empty_proxy
    urllib_request.urlopen(url, buffer)
  File "D:\01_Anaconda\envs\ADDMo-Extra\Lib\urllib\request.py", line 216, in urlopen
    return opener.open(url, data, timeout)
           ^^^^^^^^^^^^^^^^^^^^^^^^^^^^^^^
  File "D:\01_Anaconda\envs\ADDMo-Extra\Lib\urllib\request.py", line 525, in open
    response = meth(req, response)
               ^^^^^^^^^^^^^^^^^^^
  File "D:\01_Anaconda\envs\ADDMo-Extra\Lib\urllib\request.py", line 634, in http_response
    response = self.parent.error(
               ^^^^^^^^^^^^^^^^^^
  File "D:\01_Anaconda\envs\ADDMo-Extra\Lib\urllib\request.py", line 563, in error
    return self._call_chain(*args)
           ^^^^^^^^^^^^^^^^^^^^^^^
  File "D:\01_Anaconda\envs\ADDMo-Extra\Lib\urllib\request.py", line 496, in _call_chain
    result = func(*args)
             ^^^^^^^^^^^
  File "D:\01_Anaconda\envs\ADDMo-Extra\Lib\urllib\request.py", line 643, in http_error_default
    raise HTTPError(req.full_url, code, msg, hdrs, fp)
urllib.error.HTTPError: HTTP Error 500: Internal Server Error
Error: failed to send plot to http://127.0.0.1:63342
Traceback (most recent call last):
  File "D:\02_PyCharm\PyCharm 2022.3.2\plugins\python\helpers\pycharm_display\datalore\display\display_.py", line 86, in _send_display_message
    urllib_request.urlopen(url, buffer)
  File "D:\01_Anaconda\envs\ADDMo-Extra\Lib\urllib\request.py", line 216, in urlopen
    return opener.open(url, data, timeout)
           ^^^^^^^^^^^^^^^^^^^^^^^^^^^^^^^
  File "D:\01_Anaconda\envs\ADDMo-Extra\Lib\urllib\request.py", line 525, in open
    response = meth(req, response)
               ^^^^^^^^^^^^^^^^^^^
  File "D:\01_Anaconda\envs\ADDMo-Extra\Lib\urllib\request.py", line 634, in http_response
    response = self.parent.error(
               ^^^^^^^^^^^^^^^^^^
  File "D:\01_Anaconda\envs\ADDMo-Extra\Lib\urllib\request.py", line 563, in error
    return self._call_chain(*args)
           ^^^^^^^^^^^^^^^^^^^^^^^
  File "D:\01_Anaconda\envs\ADDMo-Extra\Lib\urllib\request.py", line 496, in _call_chain
    result = func(*args)
             ^^^^^^^^^^^
  File "D:\01_Anaconda\envs\ADDMo-Extra\Lib\urllib\request.py", line 643, in http_error_default
    raise HTTPError(req.full_url, code, msg, hdrs, fp)
urllib.error.HTTPError: HTTP Error 500: Internal Server Error
During handling of the above exception, another exception occurred:
Traceback (most recent call last):
  File "D:\02_PyCharm\PyCharm 2022.3.2\plugins\python\helpers\pycharm_display\datalore\display\display_.py", line 61, in try_empty_proxy
    urllib_request.urlopen(url, buffer)
  File "D:\01_Anaconda\envs\ADDMo-Extra\Lib\urllib\request.py", line 216, in urlopen
    return opener.open(url, data, timeout)
           ^^^^^^^^^^^^^^^^^^^^^^^^^^^^^^^
  File "D:\01_Anaconda\envs\ADDMo-Extra\Lib\urllib\request.py", line 525, in open
    response = meth(req, response)
               ^^^^^^^^^^^^^^^^^^^
  File "D:\01_Anaconda\envs\ADDMo-Extra\Lib\urllib\request.py", line 634, in http_response
    response = self.parent.error(
               ^^^^^^^^^^^^^^^^^^
  File "D:\01_Anaconda\envs\ADDMo-Extra\Lib\urllib\request.py", line 563, in error
    return self._call_chain(*args)
           ^^^^^^^^^^^^^^^^^^^^^^^
  File "D:\01_Anaconda\envs\ADDMo-Extra\Lib\urllib\request.py", line 496, in _call_chain
    result = func(*args)
             ^^^^^^^^^^^
  File "D:\01_Anaconda\envs\ADDMo-Extra\Lib\urllib\request.py", line 643, in http_error_default
    raise HTTPError(req.full_url, code, msg, hdrs, fp)
urllib.error.HTTPError: HTTP Error 500: Internal Server Error
Error: failed to send plot to http://127.0.0.1:63342
Traceback (most recent call last):
  File "D:\02_PyCharm\PyCharm 2022.3.2\plugins\python\helpers\pycharm_display\datalore\display\display_.py", line 86, in _send_display_message
    urllib_request.urlopen(url, buffer)
  File "D:\01_Anaconda\envs\ADDMo-Extra\Lib\urllib\request.py", line 216, in urlopen
    return opener.open(url, data, timeout)
           ^^^^^^^^^^^^^^^^^^^^^^^^^^^^^^^
  File "D:\01_Anaconda\envs\ADDMo-Extra\Lib\urllib\request.py", line 525, in open
    response = meth(req, response)
               ^^^^^^^^^^^^^^^^^^^
  File "D:\01_Anaconda\envs\ADDMo-Extra\Lib\urllib\request.py", line 634, in http_response
    response = self.parent.error(
               ^^^^^^^^^^^^^^^^^^
  File "D:\01_Anaconda\envs\ADDMo-Extra\Lib\urllib\request.py", line 563, in error
    return self._call_chain(*args)
           ^^^^^^^^^^^^^^^^^^^^^^^
  File "D:\01_Anaconda\envs\ADDMo-Extra\Lib\urllib\request.py", line 496, in _call_chain
    result = func(*args)
             ^^^^^^^^^^^
  File "D:\01_Anaconda\envs\ADDMo-Extra\Lib\urllib\request.py", line 643, in http_error_default
    raise HTTPError(req.full_url, code, msg, hdrs, fp)
urllib.error.HTTPError: HTTP Error 500: Internal Server Error
During handling of the above exception, another exception occurred:
Traceback (most recent call last):
  File "D:\02_PyCharm\PyCharm 2022.3.2\plugins\python\helpers\pycharm_display\datalore\display\display_.py", line 61, in try_empty_proxy
    urllib_request.urlopen(url, buffer)
  File "D:\01_Anaconda\envs\ADDMo-Extra\Lib\urllib\request.py", line 216, in urlopen
    return opener.open(url, data, timeout)
           ^^^^^^^^^^^^^^^^^^^^^^^^^^^^^^^
  File "D:\01_Anaconda\envs\ADDMo-Extra\Lib\urllib\request.py", line 525, in open
    response = meth(req, response)
               ^^^^^^^^^^^^^^^^^^^
  File "D:\01_Anaconda\envs\ADDMo-Extra\Lib\urllib\request.py", line 634, in http_response
    response = self.parent.error(
               ^^^^^^^^^^^^^^^^^^
  File "D:\01_Anaconda\envs\ADDMo-Extra\Lib\urllib\request.py", line 563, in error
    return self._call_chain(*args)
           ^^^^^^^^^^^^^^^^^^^^^^^
  File "D:\01_Anaconda\envs\ADDMo-Extra\Lib\urllib\request.py", line 496, in _call_chain
    result = func(*args)
             ^^^^^^^^^^^
  File "D:\01_Anaconda\envs\ADDMo-Extra\Lib\urllib\request.py", line 643, in http_error_default
    raise HTTPError(req.full_url, code, msg, hdrs, fp)
urllib.error.HTTPError: HTTP Error 500: Internal Server Error
Error: failed to send plot to http://127.0.0.1:63342
Traceback (most recent call last):
  File "D:\02_PyCharm\PyCharm 2022.3.2\plugins\python\helpers\pycharm_display\datalore\display\display_.py", line 86, in _send_display_message
    urllib_request.urlopen(url, buffer)
  File "D:\01_Anaconda\envs\ADDMo-Extra\Lib\urllib\request.py", line 216, in urlopen
    return opener.open(url, data, timeout)
           ^^^^^^^^^^^^^^^^^^^^^^^^^^^^^^^
  File "D:\01_Anaconda\envs\ADDMo-Extra\Lib\urllib\request.py", line 525, in open
    response = meth(req, response)
               ^^^^^^^^^^^^^^^^^^^
  File "D:\01_Anaconda\envs\ADDMo-Extra\Lib\urllib\request.py", line 634, in http_response
    response = self.parent.error(
               ^^^^^^^^^^^^^^^^^^
  File "D:\01_Anaconda\envs\ADDMo-Extra\Lib\urllib\request.py", line 563, in error
    return self._call_chain(*args)
           ^^^^^^^^^^^^^^^^^^^^^^^
  File "D:\01_Anaconda\envs\ADDMo-Extra\Lib\urllib\request.py", line 496, in _call_chain
    result = func(*args)
             ^^^^^^^^^^^
  File "D:\01_Anaconda\envs\ADDMo-Extra\Lib\urllib\request.py", line 643, in http_error_default
    raise HTTPError(req.full_url, code, msg, hdrs, fp)
urllib.error.HTTPError: HTTP Error 500: Internal Server Error
During handling of the above exception, another exception occurred:
Traceback (most recent call last):
  File "D:\02_PyCharm\PyCharm 2022.3.2\plugins\python\helpers\pycharm_display\datalore\display\display_.py", line 61, in try_empty_proxy
    urllib_request.urlopen(url, buffer)
  File "D:\01_Anaconda\envs\ADDMo-Extra\Lib\urllib\request.py", line 216, in urlopen
    return opener.open(url, data, timeout)
           ^^^^^^^^^^^^^^^^^^^^^^^^^^^^^^^
  File "D:\01_Anaconda\envs\ADDMo-Extra\Lib\urllib\request.py", line 525, in open
    response = meth(req, response)
               ^^^^^^^^^^^^^^^^^^^
  File "D:\01_Anaconda\envs\ADDMo-Extra\Lib\urllib\request.py", line 634, in http_response
    response = self.parent.error(
               ^^^^^^^^^^^^^^^^^^
  File "D:\01_Anaconda\envs\ADDMo-Extra\Lib\urllib\request.py", line 563, in error
    return self._call_chain(*args)
           ^^^^^^^^^^^^^^^^^^^^^^^
  File "D:\01_Anaconda\envs\ADDMo-Extra\Lib\urllib\request.py", line 496, in _call_chain
    result = func(*args)
             ^^^^^^^^^^^
  File "D:\01_Anaconda\envs\ADDMo-Extra\Lib\urllib\request.py", line 643, in http_error_default
    raise HTTPError(req.full_url, code, msg, hdrs, fp)
urllib.error.HTTPError: HTTP Error 500: Internal Server Error
Error: failed to send plot to http://127.0.0.1:63342
Traceback (most recent call last):
  File "D:\02_PyCharm\PyCharm 2022.3.2\plugins\python\helpers\pycharm_display\datalore\display\display_.py", line 86, in _send_display_message
    urllib_request.urlopen(url, buffer)
  File "D:\01_Anaconda\envs\ADDMo-Extra\Lib\urllib\request.py", line 216, in urlopen
    return opener.open(url, data, timeout)
           ^^^^^^^^^^^^^^^^^^^^^^^^^^^^^^^
  File "D:\01_Anaconda\envs\ADDMo-Extra\Lib\urllib\request.py", line 525, in open
    response = meth(req, response)
               ^^^^^^^^^^^^^^^^^^^
  File "D:\01_Anaconda\envs\ADDMo-Extra\Lib\urllib\request.py", line 634, in http_response
    response = self.parent.error(
               ^^^^^^^^^^^^^^^^^^
  File "D:\01_Anaconda\envs\ADDMo-Extra\Lib\urllib\request.py", line 563, in error
    return self._call_chain(*args)
           ^^^^^^^^^^^^^^^^^^^^^^^
  File "D:\01_Anaconda\envs\ADDMo-Extra\Lib\urllib\request.py", line 496, in _call_chain
    result = func(*args)
             ^^^^^^^^^^^
  File "D:\01_Anaconda\envs\ADDMo-Extra\Lib\urllib\request.py", line 643, in http_error_default
    raise HTTPError(req.full_url, code, msg, hdrs, fp)
urllib.error.HTTPError: HTTP Error 500: Internal Server Error
During handling of the above exception, another exception occurred:
Traceback (most recent call last):
  File "D:\02_PyCharm\PyCharm 2022.3.2\plugins\python\helpers\pycharm_display\datalore\display\display_.py", line 61, in try_empty_proxy
    urllib_request.urlopen(url, buffer)
  File "D:\01_Anaconda\envs\ADDMo-Extra\Lib\urllib\request.py", line 216, in urlopen
    return opener.open(url, data, timeout)
           ^^^^^^^^^^^^^^^^^^^^^^^^^^^^^^^
  File "D:\01_Anaconda\envs\ADDMo-Extra\Lib\urllib\request.py", line 525, in open
    response = meth(req, response)
               ^^^^^^^^^^^^^^^^^^^
  File "D:\01_Anaconda\envs\ADDMo-Extra\Lib\urllib\request.py", line 634, in http_response
    response = self.parent.error(
               ^^^^^^^^^^^^^^^^^^
  File "D:\01_Anaconda\envs\ADDMo-Extra\Lib\urllib\request.py", line 563, in error
    return self._call_chain(*args)
           ^^^^^^^^^^^^^^^^^^^^^^^
  File "D:\01_Anaconda\envs\ADDMo-Extra\Lib\urllib\request.py", line 496, in _call_chain
    result = func(*args)
             ^^^^^^^^^^^
  File "D:\01_Anaconda\envs\ADDMo-Extra\Lib\urllib\request.py", line 643, in http_error_default
    raise HTTPError(req.full_url, code, msg, hdrs, fp)
urllib.error.HTTPError: HTTP Error 500: Internal Server Error
Error: failed to send plot to http://127.0.0.1:63342
Traceback (most recent call last):
  File "D:\02_PyCharm\PyCharm 2022.3.2\plugins\python\helpers\pycharm_display\datalore\display\display_.py", line 86, in _send_display_message
    urllib_request.urlopen(url, buffer)
  File "D:\01_Anaconda\envs\ADDMo-Extra\Lib\urllib\request.py", line 216, in urlopen
    return opener.open(url, data, timeout)
           ^^^^^^^^^^^^^^^^^^^^^^^^^^^^^^^
  File "D:\01_Anaconda\envs\ADDMo-Extra\Lib\urllib\request.py", line 525, in open
    response = meth(req, response)
               ^^^^^^^^^^^^^^^^^^^
  File "D:\01_Anaconda\envs\ADDMo-Extra\Lib\urllib\request.py", line 634, in http_response
    response = self.parent.error(
               ^^^^^^^^^^^^^^^^^^
  File "D:\01_Anaconda\envs\ADDMo-Extra\Lib\urllib\request.py", line 563, in error
    return self._call_chain(*args)
           ^^^^^^^^^^^^^^^^^^^^^^^
  File "D:\01_Anaconda\envs\ADDMo-Extra\Lib\urllib\request.py", line 496, in _call_chain
    result = func(*args)
             ^^^^^^^^^^^
  File "D:\01_Anaconda\envs\ADDMo-Extra\Lib\urllib\request.py", line 643, in http_error_default
    raise HTTPError(req.full_url, code, msg, hdrs, fp)
urllib.error.HTTPError: HTTP Error 500: Internal Server Error
During handling of the above exception, another exception occurred:
Traceback (most recent call last):
  File "D:\02_PyCharm\PyCharm 2022.3.2\plugins\python\helpers\pycharm_display\datalore\display\display_.py", line 61, in try_empty_proxy
    urllib_request.urlopen(url, buffer)
  File "D:\01_Anaconda\envs\ADDMo-Extra\Lib\urllib\request.py", line 216, in urlopen
    return opener.open(url, data, timeout)
           ^^^^^^^^^^^^^^^^^^^^^^^^^^^^^^^
  File "D:\01_Anaconda\envs\ADDMo-Extra\Lib\urllib\request.py", line 525, in open
    response = meth(req, response)
               ^^^^^^^^^^^^^^^^^^^
  File "D:\01_Anaconda\envs\ADDMo-Extra\Lib\urllib\request.py", line 634, in http_response
    response = self.parent.error(
               ^^^^^^^^^^^^^^^^^^
  File "D:\01_Anaconda\envs\ADDMo-Extra\Lib\urllib\request.py", line 563, in error
    return self._call_chain(*args)
           ^^^^^^^^^^^^^^^^^^^^^^^
  File "D:\01_Anaconda\envs\ADDMo-Extra\Lib\urllib\request.py", line 496, in _call_chain
    result = func(*args)
             ^^^^^^^^^^^
  File "D:\01_Anaconda\envs\ADDMo-Extra\Lib\urllib\request.py", line 643, in http_error_default
    raise HTTPError(req.full_url, code, msg, hdrs, fp)
urllib.error.HTTPError: HTTP Error 500: Internal Server Error
Error: failed to send plot to http://127.0.0.1:63342
Traceback (most recent call last):
  File "D:\02_PyCharm\PyCharm 2022.3.2\plugins\python\helpers\pycharm_display\datalore\display\display_.py", line 86, in _send_display_message
    urllib_request.urlopen(url, buffer)
  File "D:\01_Anaconda\envs\ADDMo-Extra\Lib\urllib\request.py", line 216, in urlopen
    return opener.open(url, data, timeout)
           ^^^^^^^^^^^^^^^^^^^^^^^^^^^^^^^
  File "D:\01_Anaconda\envs\ADDMo-Extra\Lib\urllib\request.py", line 525, in open
    response = meth(req, response)
               ^^^^^^^^^^^^^^^^^^^
  File "D:\01_Anaconda\envs\ADDMo-Extra\Lib\urllib\request.py", line 634, in http_response
    response = self.parent.error(
               ^^^^^^^^^^^^^^^^^^
  File "D:\01_Anaconda\envs\ADDMo-Extra\Lib\urllib\request.py", line 563, in error
    return self._call_chain(*args)
           ^^^^^^^^^^^^^^^^^^^^^^^
  File "D:\01_Anaconda\envs\ADDMo-Extra\Lib\urllib\request.py", line 496, in _call_chain
    result = func(*args)
             ^^^^^^^^^^^
  File "D:\01_Anaconda\envs\ADDMo-Extra\Lib\urllib\request.py", line 643, in http_error_default
    raise HTTPError(req.full_url, code, msg, hdrs, fp)
urllib.error.HTTPError: HTTP Error 500: Internal Server Error
During handling of the above exception, another exception occurred:
Traceback (most recent call last):
  File "D:\02_PyCharm\PyCharm 2022.3.2\plugins\python\helpers\pycharm_display\datalore\display\display_.py", line 61, in try_empty_proxy
    urllib_request.urlopen(url, buffer)
  File "D:\01_Anaconda\envs\ADDMo-Extra\Lib\urllib\request.py", line 216, in urlopen
    return opener.open(url, data, timeout)
           ^^^^^^^^^^^^^^^^^^^^^^^^^^^^^^^
  File "D:\01_Anaconda\envs\ADDMo-Extra\Lib\urllib\request.py", line 525, in open
    response = meth(req, response)
               ^^^^^^^^^^^^^^^^^^^
  File "D:\01_Anaconda\envs\ADDMo-Extra\Lib\urllib\request.py", line 634, in http_response
    response = self.parent.error(
               ^^^^^^^^^^^^^^^^^^
  File "D:\01_Anaconda\envs\ADDMo-Extra\Lib\urllib\request.py", line 563, in error
    return self._call_chain(*args)
           ^^^^^^^^^^^^^^^^^^^^^^^
  File "D:\01_Anaconda\envs\ADDMo-Extra\Lib\urllib\request.py", line 496, in _call_chain
    result = func(*args)
             ^^^^^^^^^^^
  File "D:\01_Anaconda\envs\ADDMo-Extra\Lib\urllib\request.py", line 643, in http_error_default
    raise HTTPError(req.full_url, code, msg, hdrs, fp)
urllib.error.HTTPError: HTTP Error 500: Internal Server Error
Error: failed to send plot to http://127.0.0.1:63342
Traceback (most recent call last):
  File "D:\02_PyCharm\PyCharm 2022.3.2\plugins\python\helpers\pycharm_display\datalore\display\display_.py", line 86, in _send_display_message
    urllib_request.urlopen(url, buffer)
  File "D:\01_Anaconda\envs\ADDMo-Extra\Lib\urllib\request.py", line 216, in urlopen
    return opener.open(url, data, timeout)
           ^^^^^^^^^^^^^^^^^^^^^^^^^^^^^^^
  File "D:\01_Anaconda\envs\ADDMo-Extra\Lib\urllib\request.py", line 525, in open
    response = meth(req, response)
               ^^^^^^^^^^^^^^^^^^^
  File "D:\01_Anaconda\envs\ADDMo-Extra\Lib\urllib\request.py", line 634, in http_response
    response = self.parent.error(
               ^^^^^^^^^^^^^^^^^^
  File "D:\01_Anaconda\envs\ADDMo-Extra\Lib\urllib\request.py", line 563, in error
    return self._call_chain(*args)
           ^^^^^^^^^^^^^^^^^^^^^^^
  File "D:\01_Anaconda\envs\ADDMo-Extra\Lib\urllib\request.py", line 496, in _call_chain
    result = func(*args)
             ^^^^^^^^^^^
  File "D:\01_Anaconda\envs\ADDMo-Extra\Lib\urllib\request.py", line 643, in http_error_default
    raise HTTPError(req.full_url, code, msg, hdrs, fp)
urllib.error.HTTPError: HTTP Error 500: Internal Server Error
During handling of the above exception, another exception occurred:
Traceback (most recent call last):
  File "D:\02_PyCharm\PyCharm 2022.3.2\plugins\python\helpers\pycharm_display\datalore\display\display_.py", line 61, in try_empty_proxy
    urllib_request.urlopen(url, buffer)
  File "D:\01_Anaconda\envs\ADDMo-Extra\Lib\urllib\request.py", line 216, in urlopen
    return opener.open(url, data, timeout)
           ^^^^^^^^^^^^^^^^^^^^^^^^^^^^^^^
  File "D:\01_Anaconda\envs\ADDMo-Extra\Lib\urllib\request.py", line 525, in open
    response = meth(req, response)
               ^^^^^^^^^^^^^^^^^^^
  File "D:\01_Anaconda\envs\ADDMo-Extra\Lib\urllib\request.py", line 634, in http_response
    response = self.parent.error(
               ^^^^^^^^^^^^^^^^^^
  File "D:\01_Anaconda\envs\ADDMo-Extra\Lib\urllib\request.py", line 563, in error
    return self._call_chain(*args)
           ^^^^^^^^^^^^^^^^^^^^^^^
  File "D:\01_Anaconda\envs\ADDMo-Extra\Lib\urllib\request.py", line 496, in _call_chain
    result = func(*args)
             ^^^^^^^^^^^
  File "D:\01_Anaconda\envs\ADDMo-Extra\Lib\urllib\request.py", line 643, in http_error_default
    raise HTTPError(req.full_url, code, msg, hdrs, fp)
urllib.error.HTTPError: HTTP Error 500: Internal Server Error
Error: failed to send plot to http://127.0.0.1:63342
Traceback (most recent call last):
  File "D:\02_PyCharm\PyCharm 2022.3.2\plugins\python\helpers\pycharm_display\datalore\display\display_.py", line 86, in _send_display_message
    urllib_request.urlopen(url, buffer)
  File "D:\01_Anaconda\envs\ADDMo-Extra\Lib\urllib\request.py", line 216, in urlopen
    return opener.open(url, data, timeout)
           ^^^^^^^^^^^^^^^^^^^^^^^^^^^^^^^
  File "D:\01_Anaconda\envs\ADDMo-Extra\Lib\urllib\request.py", line 525, in open
    response = meth(req, response)
               ^^^^^^^^^^^^^^^^^^^
  File "D:\01_Anaconda\envs\ADDMo-Extra\Lib\urllib\request.py", line 634, in http_response
    response = self.parent.error(
               ^^^^^^^^^^^^^^^^^^
  File "D:\01_Anaconda\envs\ADDMo-Extra\Lib\urllib\request.py", line 563, in error
    return self._call_chain(*args)
           ^^^^^^^^^^^^^^^^^^^^^^^
  File "D:\01_Anaconda\envs\ADDMo-Extra\Lib\urllib\request.py", line 496, in _call_chain
    result = func(*args)
             ^^^^^^^^^^^
  File "D:\01_Anaconda\envs\ADDMo-Extra\Lib\urllib\request.py", line 643, in http_error_default
    raise HTTPError(req.full_url, code, msg, hdrs, fp)
urllib.error.HTTPError: HTTP Error 500: Internal Server Error
During handling of the above exception, another exception occurred:
Traceback (most recent call last):
  File "D:\02_PyCharm\PyCharm 2022.3.2\plugins\python\helpers\pycharm_display\datalore\display\display_.py", line 61, in try_empty_proxy
    urllib_request.urlopen(url, buffer)
  File "D:\01_Anaconda\envs\ADDMo-Extra\Lib\urllib\request.py", line 216, in urlopen
    return opener.open(url, data, timeout)
           ^^^^^^^^^^^^^^^^^^^^^^^^^^^^^^^
  File "D:\01_Anaconda\envs\ADDMo-Extra\Lib\urllib\request.py", line 525, in open
    response = meth(req, response)
               ^^^^^^^^^^^^^^^^^^^
  File "D:\01_Anaconda\envs\ADDMo-Extra\Lib\urllib\request.py", line 634, in http_response
    response = self.parent.error(
               ^^^^^^^^^^^^^^^^^^
  File "D:\01_Anaconda\envs\ADDMo-Extra\Lib\urllib\request.py", line 563, in error
    return self._call_chain(*args)
           ^^^^^^^^^^^^^^^^^^^^^^^
  File "D:\01_Anaconda\envs\ADDMo-Extra\Lib\urllib\request.py", line 496, in _call_chain
    result = func(*args)
             ^^^^^^^^^^^
  File "D:\01_Anaconda\envs\ADDMo-Extra\Lib\urllib\request.py", line 643, in http_error_default
    raise HTTPError(req.full_url, code, msg, hdrs, fp)
urllib.error.HTTPError: HTTP Error 500: Internal Server Error
Error: failed to send plot to http://127.0.0.1:63342
Traceback (most recent call last):
  File "D:\02_PyCharm\PyCharm 2022.3.2\plugins\python\helpers\pycharm_display\datalore\display\display_.py", line 86, in _send_display_message
    urllib_request.urlopen(url, buffer)
  File "D:\01_Anaconda\envs\ADDMo-Extra\Lib\urllib\request.py", line 216, in urlopen
    return opener.open(url, data, timeout)
           ^^^^^^^^^^^^^^^^^^^^^^^^^^^^^^^
  File "D:\01_Anaconda\envs\ADDMo-Extra\Lib\urllib\request.py", line 525, in open
    response = meth(req, response)
               ^^^^^^^^^^^^^^^^^^^
  File "D:\01_Anaconda\envs\ADDMo-Extra\Lib\urllib\request.py", line 634, in http_response
    response = self.parent.error(
               ^^^^^^^^^^^^^^^^^^
  File "D:\01_Anaconda\envs\ADDMo-Extra\Lib\urllib\request.py", line 563, in error
    return self._call_chain(*args)
           ^^^^^^^^^^^^^^^^^^^^^^^
  File "D:\01_Anaconda\envs\ADDMo-Extra\Lib\urllib\request.py", line 496, in _call_chain
    result = func(*args)
             ^^^^^^^^^^^
  File "D:\01_Anaconda\envs\ADDMo-Extra\Lib\urllib\request.py", line 643, in http_error_default
    raise HTTPError(req.full_url, code, msg, hdrs, fp)
urllib.error.HTTPError: HTTP Error 500: Internal Server Error
During handling of the above exception, another exception occurred:
Traceback (most recent call last):
  File "D:\02_PyCharm\PyCharm 2022.3.2\plugins\python\helpers\pycharm_display\datalore\display\display_.py", line 61, in try_empty_proxy
    urllib_request.urlopen(url, buffer)
  File "D:\01_Anaconda\envs\ADDMo-Extra\Lib\urllib\request.py", line 216, in urlopen
    return opener.open(url, data, timeout)
           ^^^^^^^^^^^^^^^^^^^^^^^^^^^^^^^
  File "D:\01_Anaconda\envs\ADDMo-Extra\Lib\urllib\request.py", line 525, in open
    response = meth(req, response)
               ^^^^^^^^^^^^^^^^^^^
  File "D:\01_Anaconda\envs\ADDMo-Extra\Lib\urllib\request.py", line 634, in http_response
    response = self.parent.error(
               ^^^^^^^^^^^^^^^^^^
  File "D:\01_Anaconda\envs\ADDMo-Extra\Lib\urllib\request.py", line 563, in error
    return self._call_chain(*args)
           ^^^^^^^^^^^^^^^^^^^^^^^
  File "D:\01_Anaconda\envs\ADDMo-Extra\Lib\urllib\request.py", line 496, in _call_chain
    result = func(*args)
             ^^^^^^^^^^^
  File "D:\01_Anaconda\envs\ADDMo-Extra\Lib\urllib\request.py", line 643, in http_error_default
    raise HTTPError(req.full_url, code, msg, hdrs, fp)
urllib.error.HTTPError: HTTP Error 500: Internal Server Error
Error: failed to send plot to http://127.0.0.1:63342
Traceback (most recent call last):
  File "D:\02_PyCharm\PyCharm 2022.3.2\plugins\python\helpers\pycharm_display\datalore\display\display_.py", line 86, in _send_display_message
    urllib_request.urlopen(url, buffer)
  File "D:\01_Anaconda\envs\ADDMo-Extra\Lib\urllib\request.py", line 216, in urlopen
    return opener.open(url, data, timeout)
           ^^^^^^^^^^^^^^^^^^^^^^^^^^^^^^^
  File "D:\01_Anaconda\envs\ADDMo-Extra\Lib\urllib\request.py", line 525, in open
    response = meth(req, response)
               ^^^^^^^^^^^^^^^^^^^
  File "D:\01_Anaconda\envs\ADDMo-Extra\Lib\urllib\request.py", line 634, in http_response
    response = self.parent.error(
               ^^^^^^^^^^^^^^^^^^
  File "D:\01_Anaconda\envs\ADDMo-Extra\Lib\urllib\request.py", line 563, in error
    return self._call_chain(*args)
           ^^^^^^^^^^^^^^^^^^^^^^^
  File "D:\01_Anaconda\envs\ADDMo-Extra\Lib\urllib\request.py", line 496, in _call_chain
    result = func(*args)
             ^^^^^^^^^^^
  File "D:\01_Anaconda\envs\ADDMo-Extra\Lib\urllib\request.py", line 643, in http_error_default
    raise HTTPError(req.full_url, code, msg, hdrs, fp)
urllib.error.HTTPError: HTTP Error 500: Internal Server Error
During handling of the above exception, another exception occurred:
Traceback (most recent call last):
  File "D:\02_PyCharm\PyCharm 2022.3.2\plugins\python\helpers\pycharm_display\datalore\display\display_.py", line 61, in try_empty_proxy
    urllib_request.urlopen(url, buffer)
  File "D:\01_Anaconda\envs\ADDMo-Extra\Lib\urllib\request.py", line 216, in urlopen
    return opener.open(url, data, timeout)
           ^^^^^^^^^^^^^^^^^^^^^^^^^^^^^^^
  File "D:\01_Anaconda\envs\ADDMo-Extra\Lib\urllib\request.py", line 525, in open
    response = meth(req, response)
               ^^^^^^^^^^^^^^^^^^^
  File "D:\01_Anaconda\envs\ADDMo-Extra\Lib\urllib\request.py", line 634, in http_response
    response = self.parent.error(
               ^^^^^^^^^^^^^^^^^^
  File "D:\01_Anaconda\envs\ADDMo-Extra\Lib\urllib\request.py", line 563, in error
    return self._call_chain(*args)
           ^^^^^^^^^^^^^^^^^^^^^^^
  File "D:\01_Anaconda\envs\ADDMo-Extra\Lib\urllib\request.py", line 496, in _call_chain
    result = func(*args)
             ^^^^^^^^^^^
  File "D:\01_Anaconda\envs\ADDMo-Extra\Lib\urllib\request.py", line 643, in http_error_default
    raise HTTPError(req.full_url, code, msg, hdrs, fp)
urllib.error.HTTPError: HTTP Error 500: Internal Server Error
Error: failed to send plot to http://127.0.0.1:63342
Traceback (most recent call last):
  File "D:\02_PyCharm\PyCharm 2022.3.2\plugins\python\helpers\pycharm_display\datalore\display\display_.py", line 86, in _send_display_message
    urllib_request.urlopen(url, buffer)
  File "D:\01_Anaconda\envs\ADDMo-Extra\Lib\urllib\request.py", line 216, in urlopen
    return opener.open(url, data, timeout)
           ^^^^^^^^^^^^^^^^^^^^^^^^^^^^^^^
  File "D:\01_Anaconda\envs\ADDMo-Extra\Lib\urllib\request.py", line 525, in open
    response = meth(req, response)
               ^^^^^^^^^^^^^^^^^^^
  File "D:\01_Anaconda\envs\ADDMo-Extra\Lib\urllib\request.py", line 634, in http_response
    response = self.parent.error(
               ^^^^^^^^^^^^^^^^^^
  File "D:\01_Anaconda\envs\ADDMo-Extra\Lib\urllib\request.py", line 563, in error
    return self._call_chain(*args)
           ^^^^^^^^^^^^^^^^^^^^^^^
  File "D:\01_Anaconda\envs\ADDMo-Extra\Lib\urllib\request.py", line 496, in _call_chain
    result = func(*args)
             ^^^^^^^^^^^
  File "D:\01_Anaconda\envs\ADDMo-Extra\Lib\urllib\request.py", line 643, in http_error_default
    raise HTTPError(req.full_url, code, msg, hdrs, fp)
urllib.error.HTTPError: HTTP Error 500: Internal Server Error
During handling of the above exception, another exception occurred:
Traceback (most recent call last):
  File "D:\02_PyCharm\PyCharm 2022.3.2\plugins\python\helpers\pycharm_display\datalore\display\display_.py", line 61, in try_empty_proxy
    urllib_request.urlopen(url, buffer)
  File "D:\01_Anaconda\envs\ADDMo-Extra\Lib\urllib\request.py", line 216, in urlopen
    return opener.open(url, data, timeout)
           ^^^^^^^^^^^^^^^^^^^^^^^^^^^^^^^
  File "D:\01_Anaconda\envs\ADDMo-Extra\Lib\urllib\request.py", line 525, in open
    response = meth(req, response)
               ^^^^^^^^^^^^^^^^^^^
  File "D:\01_Anaconda\envs\ADDMo-Extra\Lib\urllib\request.py", line 634, in http_response
    response = self.parent.error(
               ^^^^^^^^^^^^^^^^^^
  File "D:\01_Anaconda\envs\ADDMo-Extra\Lib\urllib\request.py", line 563, in error
    return self._call_chain(*args)
           ^^^^^^^^^^^^^^^^^^^^^^^
  File "D:\01_Anaconda\envs\ADDMo-Extra\Lib\urllib\request.py", line 496, in _call_chain
    result = func(*args)
             ^^^^^^^^^^^
  File "D:\01_Anaconda\envs\ADDMo-Extra\Lib\urllib\request.py", line 643, in http_error_default
    raise HTTPError(req.full_url, code, msg, hdrs, fp)
urllib.error.HTTPError: HTTP Error 500: Internal Server Error
Error: failed to send plot to http://127.0.0.1:63342
Traceback (most recent call last):
  File "D:\02_PyCharm\PyCharm 2022.3.2\plugins\python\helpers\pycharm_display\datalore\display\display_.py", line 86, in _send_display_message
    urllib_request.urlopen(url, buffer)
  File "D:\01_Anaconda\envs\ADDMo-Extra\Lib\urllib\request.py", line 216, in urlopen
    return opener.open(url, data, timeout)
           ^^^^^^^^^^^^^^^^^^^^^^^^^^^^^^^
  File "D:\01_Anaconda\envs\ADDMo-Extra\Lib\urllib\request.py", line 525, in open
    response = meth(req, response)
               ^^^^^^^^^^^^^^^^^^^
  File "D:\01_Anaconda\envs\ADDMo-Extra\Lib\urllib\request.py", line 634, in http_response
    response = self.parent.error(
               ^^^^^^^^^^^^^^^^^^
  File "D:\01_Anaconda\envs\ADDMo-Extra\Lib\urllib\request.py", line 563, in error
    return self._call_chain(*args)
           ^^^^^^^^^^^^^^^^^^^^^^^
  File "D:\01_Anaconda\envs\ADDMo-Extra\Lib\urllib\request.py", line 496, in _call_chain
    result = func(*args)
             ^^^^^^^^^^^
  File "D:\01_Anaconda\envs\ADDMo-Extra\Lib\urllib\request.py", line 643, in http_error_default
    raise HTTPError(req.full_url, code, msg, hdrs, fp)
urllib.error.HTTPError: HTTP Error 500: Internal Server Error
During handling of the above exception, another exception occurred:
Traceback (most recent call last):
  File "D:\02_PyCharm\PyCharm 2022.3.2\plugins\python\helpers\pycharm_display\datalore\display\display_.py", line 61, in try_empty_proxy
    urllib_request.urlopen(url, buffer)
  File "D:\01_Anaconda\envs\ADDMo-Extra\Lib\urllib\request.py", line 216, in urlopen
    return opener.open(url, data, timeout)
           ^^^^^^^^^^^^^^^^^^^^^^^^^^^^^^^
  File "D:\01_Anaconda\envs\ADDMo-Extra\Lib\urllib\request.py", line 525, in open
    response = meth(req, response)
               ^^^^^^^^^^^^^^^^^^^
  File "D:\01_Anaconda\envs\ADDMo-Extra\Lib\urllib\request.py", line 634, in http_response
    response = self.parent.error(
               ^^^^^^^^^^^^^^^^^^
  File "D:\01_Anaconda\envs\ADDMo-Extra\Lib\urllib\request.py", line 563, in error
    return self._call_chain(*args)
           ^^^^^^^^^^^^^^^^^^^^^^^
  File "D:\01_Anaconda\envs\ADDMo-Extra\Lib\urllib\request.py", line 496, in _call_chain
    result = func(*args)
             ^^^^^^^^^^^
  File "D:\01_Anaconda\envs\ADDMo-Extra\Lib\urllib\request.py", line 643, in http_error_default
    raise HTTPError(req.full_url, code, msg, hdrs, fp)
urllib.error.HTTPError: HTTP Error 500: Internal Server Error
Error: failed to send plot to http://127.0.0.1:63342
Traceback (most recent call last):
  File "D:\02_PyCharm\PyCharm 2022.3.2\plugins\python\helpers\pycharm_display\datalore\display\display_.py", line 86, in _send_display_message
    urllib_request.urlopen(url, buffer)
  File "D:\01_Anaconda\envs\ADDMo-Extra\Lib\urllib\request.py", line 216, in urlopen
    return opener.open(url, data, timeout)
           ^^^^^^^^^^^^^^^^^^^^^^^^^^^^^^^
  File "D:\01_Anaconda\envs\ADDMo-Extra\Lib\urllib\request.py", line 525, in open
    response = meth(req, response)
               ^^^^^^^^^^^^^^^^^^^
  File "D:\01_Anaconda\envs\ADDMo-Extra\Lib\urllib\request.py", line 634, in http_response
    response = self.parent.error(
               ^^^^^^^^^^^^^^^^^^
  File "D:\01_Anaconda\envs\ADDMo-Extra\Lib\urllib\request.py", line 563, in error
    return self._call_chain(*args)
           ^^^^^^^^^^^^^^^^^^^^^^^
  File "D:\01_Anaconda\envs\ADDMo-Extra\Lib\urllib\request.py", line 496, in _call_chain
    result = func(*args)
             ^^^^^^^^^^^
  File "D:\01_Anaconda\envs\ADDMo-Extra\Lib\urllib\request.py", line 643, in http_error_default
    raise HTTPError(req.full_url, code, msg, hdrs, fp)
urllib.error.HTTPError: HTTP Error 500: Internal Server Error
During handling of the above exception, another exception occurred:
Traceback (most recent call last):
  File "D:\02_PyCharm\PyCharm 2022.3.2\plugins\python\helpers\pycharm_display\datalore\display\display_.py", line 61, in try_empty_proxy
    urllib_request.urlopen(url, buffer)
  File "D:\01_Anaconda\envs\ADDMo-Extra\Lib\urllib\request.py", line 216, in urlopen
    return opener.open(url, data, timeout)
           ^^^^^^^^^^^^^^^^^^^^^^^^^^^^^^^
  File "D:\01_Anaconda\envs\ADDMo-Extra\Lib\urllib\request.py", line 525, in open
    response = meth(req, response)
               ^^^^^^^^^^^^^^^^^^^
  File "D:\01_Anaconda\envs\ADDMo-Extra\Lib\urllib\request.py", line 634, in http_response
    response = self.parent.error(
               ^^^^^^^^^^^^^^^^^^
  File "D:\01_Anaconda\envs\ADDMo-Extra\Lib\urllib\request.py", line 563, in error
    return self._call_chain(*args)
           ^^^^^^^^^^^^^^^^^^^^^^^
  File "D:\01_Anaconda\envs\ADDMo-Extra\Lib\urllib\request.py", line 496, in _call_chain
    result = func(*args)
             ^^^^^^^^^^^
  File "D:\01_Anaconda\envs\ADDMo-Extra\Lib\urllib\request.py", line 643, in http_error_default
    raise HTTPError(req.full_url, code, msg, hdrs, fp)
urllib.error.HTTPError: HTTP Error 500: Internal Server Error
Error: failed to send plot to http://127.0.0.1:63342
Traceback (most recent call last):
  File "D:\02_PyCharm\PyCharm 2022.3.2\plugins\python\helpers\pycharm_display\datalore\display\display_.py", line 86, in _send_display_message
    urllib_request.urlopen(url, buffer)
  File "D:\01_Anaconda\envs\ADDMo-Extra\Lib\urllib\request.py", line 216, in urlopen
    return opener.open(url, data, timeout)
           ^^^^^^^^^^^^^^^^^^^^^^^^^^^^^^^
  File "D:\01_Anaconda\envs\ADDMo-Extra\Lib\urllib\request.py", line 525, in open
    response = meth(req, response)
               ^^^^^^^^^^^^^^^^^^^
  File "D:\01_Anaconda\envs\ADDMo-Extra\Lib\urllib\request.py", line 634, in http_response
    response = self.parent.error(
               ^^^^^^^^^^^^^^^^^^
  File "D:\01_Anaconda\envs\ADDMo-Extra\Lib\urllib\request.py", line 563, in error
    return self._call_chain(*args)
           ^^^^^^^^^^^^^^^^^^^^^^^
  File "D:\01_Anaconda\envs\ADDMo-Extra\Lib\urllib\request.py", line 496, in _call_chain
    result = func(*args)
             ^^^^^^^^^^^
  File "D:\01_Anaconda\envs\ADDMo-Extra\Lib\urllib\request.py", line 643, in http_error_default
    raise HTTPError(req.full_url, code, msg, hdrs, fp)
urllib.error.HTTPError: HTTP Error 500: Internal Server Error
During handling of the above exception, another exception occurred:
Traceback (most recent call last):
  File "D:\02_PyCharm\PyCharm 2022.3.2\plugins\python\helpers\pycharm_display\datalore\display\display_.py", line 61, in try_empty_proxy
    urllib_request.urlopen(url, buffer)
  File "D:\01_Anaconda\envs\ADDMo-Extra\Lib\urllib\request.py", line 216, in urlopen
    return opener.open(url, data, timeout)
           ^^^^^^^^^^^^^^^^^^^^^^^^^^^^^^^
  File "D:\01_Anaconda\envs\ADDMo-Extra\Lib\urllib\request.py", line 525, in open
    response = meth(req, response)
               ^^^^^^^^^^^^^^^^^^^
  File "D:\01_Anaconda\envs\ADDMo-Extra\Lib\urllib\request.py", line 634, in http_response
    response = self.parent.error(
               ^^^^^^^^^^^^^^^^^^
  File "D:\01_Anaconda\envs\ADDMo-Extra\Lib\urllib\request.py", line 563, in error
    return self._call_chain(*args)
           ^^^^^^^^^^^^^^^^^^^^^^^
  File "D:\01_Anaconda\envs\ADDMo-Extra\Lib\urllib\request.py", line 496, in _call_chain
    result = func(*args)
             ^^^^^^^^^^^
  File "D:\01_Anaconda\envs\ADDMo-Extra\Lib\urllib\request.py", line 643, in http_error_default
    raise HTTPError(req.full_url, code, msg, hdrs, fp)
urllib.error.HTTPError: HTTP Error 500: Internal Server Error
Error: failed to send plot to http://127.0.0.1:63342
Traceback (most recent call last):
  File "D:\02_PyCharm\PyCharm 2022.3.2\plugins\python\helpers\pycharm_display\datalore\display\display_.py", line 86, in _send_display_message
    urllib_request.urlopen(url, buffer)
  File "D:\01_Anaconda\envs\ADDMo-Extra\Lib\urllib\request.py", line 216, in urlopen
    return opener.open(url, data, timeout)
           ^^^^^^^^^^^^^^^^^^^^^^^^^^^^^^^
  File "D:\01_Anaconda\envs\ADDMo-Extra\Lib\urllib\request.py", line 525, in open
    response = meth(req, response)
               ^^^^^^^^^^^^^^^^^^^
  File "D:\01_Anaconda\envs\ADDMo-Extra\Lib\urllib\request.py", line 634, in http_response
    response = self.parent.error(
               ^^^^^^^^^^^^^^^^^^
  File "D:\01_Anaconda\envs\ADDMo-Extra\Lib\urllib\request.py", line 563, in error
    return self._call_chain(*args)
           ^^^^^^^^^^^^^^^^^^^^^^^
  File "D:\01_Anaconda\envs\ADDMo-Extra\Lib\urllib\request.py", line 496, in _call_chain
    result = func(*args)
             ^^^^^^^^^^^
  File "D:\01_Anaconda\envs\ADDMo-Extra\Lib\urllib\request.py", line 643, in http_error_default
    raise HTTPError(req.full_url, code, msg, hdrs, fp)
urllib.error.HTTPError: HTTP Error 500: Internal Server Error
During handling of the above exception, another exception occurred:
Traceback (most recent call last):
  File "D:\02_PyCharm\PyCharm 2022.3.2\plugins\python\helpers\pycharm_display\datalore\display\display_.py", line 61, in try_empty_proxy
    urllib_request.urlopen(url, buffer)
  File "D:\01_Anaconda\envs\ADDMo-Extra\Lib\urllib\request.py", line 216, in urlopen
    return opener.open(url, data, timeout)
           ^^^^^^^^^^^^^^^^^^^^^^^^^^^^^^^
  File "D:\01_Anaconda\envs\ADDMo-Extra\Lib\urllib\request.py", line 525, in open
    response = meth(req, response)
               ^^^^^^^^^^^^^^^^^^^
  File "D:\01_Anaconda\envs\ADDMo-Extra\Lib\urllib\request.py", line 634, in http_response
    response = self.parent.error(
               ^^^^^^^^^^^^^^^^^^
  File "D:\01_Anaconda\envs\ADDMo-Extra\Lib\urllib\request.py", line 563, in error
    return self._call_chain(*args)
           ^^^^^^^^^^^^^^^^^^^^^^^
  File "D:\01_Anaconda\envs\ADDMo-Extra\Lib\urllib\request.py", line 496, in _call_chain
    result = func(*args)
             ^^^^^^^^^^^
  File "D:\01_Anaconda\envs\ADDMo-Extra\Lib\urllib\request.py", line 643, in http_error_default
    raise HTTPError(req.full_url, code, msg, hdrs, fp)
urllib.error.HTTPError: HTTP Error 500: Internal Server Error
Error: failed to send plot to http://127.0.0.1:63342
Traceback (most recent call last):
  File "D:\02_PyCharm\PyCharm 2022.3.2\plugins\python\helpers\pycharm_display\datalore\display\display_.py", line 86, in _send_display_message
    urllib_request.urlopen(url, buffer)
  File "D:\01_Anaconda\envs\ADDMo-Extra\Lib\urllib\request.py", line 216, in urlopen
    return opener.open(url, data, timeout)
           ^^^^^^^^^^^^^^^^^^^^^^^^^^^^^^^
  File "D:\01_Anaconda\envs\ADDMo-Extra\Lib\urllib\request.py", line 525, in open
    response = meth(req, response)
               ^^^^^^^^^^^^^^^^^^^
  File "D:\01_Anaconda\envs\ADDMo-Extra\Lib\urllib\request.py", line 634, in http_response
    response = self.parent.error(
               ^^^^^^^^^^^^^^^^^^
  File "D:\01_Anaconda\envs\ADDMo-Extra\Lib\urllib\request.py", line 563, in error
    return self._call_chain(*args)
           ^^^^^^^^^^^^^^^^^^^^^^^
  File "D:\01_Anaconda\envs\ADDMo-Extra\Lib\urllib\request.py", line 496, in _call_chain
    result = func(*args)
             ^^^^^^^^^^^
  File "D:\01_Anaconda\envs\ADDMo-Extra\Lib\urllib\request.py", line 643, in http_error_default
    raise HTTPError(req.full_url, code, msg, hdrs, fp)
urllib.error.HTTPError: HTTP Error 500: Internal Server Error
During handling of the above exception, another exception occurred:
Traceback (most recent call last):
  File "D:\02_PyCharm\PyCharm 2022.3.2\plugins\python\helpers\pycharm_display\datalore\display\display_.py", line 61, in try_empty_proxy
    urllib_request.urlopen(url, buffer)
  File "D:\01_Anaconda\envs\ADDMo-Extra\Lib\urllib\request.py", line 216, in urlopen
    return opener.open(url, data, timeout)
           ^^^^^^^^^^^^^^^^^^^^^^^^^^^^^^^
  File "D:\01_Anaconda\envs\ADDMo-Extra\Lib\urllib\request.py", line 525, in open
    response = meth(req, response)
               ^^^^^^^^^^^^^^^^^^^
  File "D:\01_Anaconda\envs\ADDMo-Extra\Lib\urllib\request.py", line 634, in http_response
    response = self.parent.error(
               ^^^^^^^^^^^^^^^^^^
  File "D:\01_Anaconda\envs\ADDMo-Extra\Lib\urllib\request.py", line 563, in error
    return self._call_chain(*args)
           ^^^^^^^^^^^^^^^^^^^^^^^
  File "D:\01_Anaconda\envs\ADDMo-Extra\Lib\urllib\request.py", line 496, in _call_chain
    result = func(*args)
             ^^^^^^^^^^^
  File "D:\01_Anaconda\envs\ADDMo-Extra\Lib\urllib\request.py", line 643, in http_error_default
    raise HTTPError(req.full_url, code, msg, hdrs, fp)
urllib.error.HTTPError: HTTP Error 500: Internal Server Error
Error: failed to send plot to http://127.0.0.1:63342
Traceback (most recent call last):
  File "D:\02_PyCharm\PyCharm 2022.3.2\plugins\python\helpers\pycharm_display\datalore\display\display_.py", line 86, in _send_display_message
    urllib_request.urlopen(url, buffer)
  File "D:\01_Anaconda\envs\ADDMo-Extra\Lib\urllib\request.py", line 216, in urlopen
    return opener.open(url, data, timeout)
           ^^^^^^^^^^^^^^^^^^^^^^^^^^^^^^^
  File "D:\01_Anaconda\envs\ADDMo-Extra\Lib\urllib\request.py", line 525, in open
    response = meth(req, response)
               ^^^^^^^^^^^^^^^^^^^
  File "D:\01_Anaconda\envs\ADDMo-Extra\Lib\urllib\request.py", line 634, in http_response
    response = self.parent.error(
               ^^^^^^^^^^^^^^^^^^
  File "D:\01_Anaconda\envs\ADDMo-Extra\Lib\urllib\request.py", line 563, in error
    return self._call_chain(*args)
           ^^^^^^^^^^^^^^^^^^^^^^^
  File "D:\01_Anaconda\envs\ADDMo-Extra\Lib\urllib\request.py", line 496, in _call_chain
    result = func(*args)
             ^^^^^^^^^^^
  File "D:\01_Anaconda\envs\ADDMo-Extra\Lib\urllib\request.py", line 643, in http_error_default
    raise HTTPError(req.full_url, code, msg, hdrs, fp)
urllib.error.HTTPError: HTTP Error 500: Internal Server Error
During handling of the above exception, another exception occurred:
Traceback (most recent call last):
  File "D:\02_PyCharm\PyCharm 2022.3.2\plugins\python\helpers\pycharm_display\datalore\display\display_.py", line 61, in try_empty_proxy
    urllib_request.urlopen(url, buffer)
  File "D:\01_Anaconda\envs\ADDMo-Extra\Lib\urllib\request.py", line 216, in urlopen
    return opener.open(url, data, timeout)
           ^^^^^^^^^^^^^^^^^^^^^^^^^^^^^^^
  File "D:\01_Anaconda\envs\ADDMo-Extra\Lib\urllib\request.py", line 525, in open
    response = meth(req, response)
               ^^^^^^^^^^^^^^^^^^^
  File "D:\01_Anaconda\envs\ADDMo-Extra\Lib\urllib\request.py", line 634, in http_response
    response = self.parent.error(
               ^^^^^^^^^^^^^^^^^^
  File "D:\01_Anaconda\envs\ADDMo-Extra\Lib\urllib\request.py", line 563, in error
    return self._call_chain(*args)
           ^^^^^^^^^^^^^^^^^^^^^^^
  File "D:\01_Anaconda\envs\ADDMo-Extra\Lib\urllib\request.py", line 496, in _call_chain
    result = func(*args)
             ^^^^^^^^^^^
  File "D:\01_Anaconda\envs\ADDMo-Extra\Lib\urllib\request.py", line 643, in http_error_default
    raise HTTPError(req.full_url, code, msg, hdrs, fp)
urllib.error.HTTPError: HTTP Error 500: Internal Server Error
Error: failed to send plot to http://127.0.0.1:63342
Traceback (most recent call last):
  File "D:\02_PyCharm\PyCharm 2022.3.2\plugins\python\helpers\pycharm_display\datalore\display\display_.py", line 86, in _send_display_message
    urllib_request.urlopen(url, buffer)
  File "D:\01_Anaconda\envs\ADDMo-Extra\Lib\urllib\request.py", line 216, in urlopen
    return opener.open(url, data, timeout)
           ^^^^^^^^^^^^^^^^^^^^^^^^^^^^^^^
  File "D:\01_Anaconda\envs\ADDMo-Extra\Lib\urllib\request.py", line 525, in open
    response = meth(req, response)
               ^^^^^^^^^^^^^^^^^^^
  File "D:\01_Anaconda\envs\ADDMo-Extra\Lib\urllib\request.py", line 634, in http_response
    response = self.parent.error(
               ^^^^^^^^^^^^^^^^^^
  File "D:\01_Anaconda\envs\ADDMo-Extra\Lib\urllib\request.py", line 563, in error
    return self._call_chain(*args)
           ^^^^^^^^^^^^^^^^^^^^^^^
  File "D:\01_Anaconda\envs\ADDMo-Extra\Lib\urllib\request.py", line 496, in _call_chain
    result = func(*args)
             ^^^^^^^^^^^
  File "D:\01_Anaconda\envs\ADDMo-Extra\Lib\urllib\request.py", line 643, in http_error_default
    raise HTTPError(req.full_url, code, msg, hdrs, fp)
urllib.error.HTTPError: HTTP Error 500: Internal Server Error
During handling of the above exception, another exception occurred:
Traceback (most recent call last):
  File "D:\02_PyCharm\PyCharm 2022.3.2\plugins\python\helpers\pycharm_display\datalore\display\display_.py", line 61, in try_empty_proxy
    urllib_request.urlopen(url, buffer)
  File "D:\01_Anaconda\envs\ADDMo-Extra\Lib\urllib\request.py", line 216, in urlopen
    return opener.open(url, data, timeout)
           ^^^^^^^^^^^^^^^^^^^^^^^^^^^^^^^
  File "D:\01_Anaconda\envs\ADDMo-Extra\Lib\urllib\request.py", line 525, in open
    response = meth(req, response)
               ^^^^^^^^^^^^^^^^^^^
  File "D:\01_Anaconda\envs\ADDMo-Extra\Lib\urllib\request.py", line 634, in http_response
    response = self.parent.error(
               ^^^^^^^^^^^^^^^^^^
  File "D:\01_Anaconda\envs\ADDMo-Extra\Lib\urllib\request.py", line 563, in error
    return self._call_chain(*args)
           ^^^^^^^^^^^^^^^^^^^^^^^
  File "D:\01_Anaconda\envs\ADDMo-Extra\Lib\urllib\request.py", line 496, in _call_chain
    result = func(*args)
             ^^^^^^^^^^^
  File "D:\01_Anaconda\envs\ADDMo-Extra\Lib\urllib\request.py", line 643, in http_error_default
    raise HTTPError(req.full_url, code, msg, hdrs, fp)
urllib.error.HTTPError: HTTP Error 500: Internal Server Error
Error: failed to send plot to http://127.0.0.1:63342
Traceback (most recent call last):
  File "D:\02_PyCharm\PyCharm 2022.3.2\plugins\python\helpers\pycharm_display\datalore\display\display_.py", line 86, in _send_display_message
    urllib_request.urlopen(url, buffer)
  File "D:\01_Anaconda\envs\ADDMo-Extra\Lib\urllib\request.py", line 216, in urlopen
    return opener.open(url, data, timeout)
           ^^^^^^^^^^^^^^^^^^^^^^^^^^^^^^^
  File "D:\01_Anaconda\envs\ADDMo-Extra\Lib\urllib\request.py", line 525, in open
    response = meth(req, response)
               ^^^^^^^^^^^^^^^^^^^
  File "D:\01_Anaconda\envs\ADDMo-Extra\Lib\urllib\request.py", line 634, in http_response
    response = self.parent.error(
               ^^^^^^^^^^^^^^^^^^
  File "D:\01_Anaconda\envs\ADDMo-Extra\Lib\urllib\request.py", line 563, in error
    return self._call_chain(*args)
           ^^^^^^^^^^^^^^^^^^^^^^^
  File "D:\01_Anaconda\envs\ADDMo-Extra\Lib\urllib\request.py", line 496, in _call_chain
    result = func(*args)
             ^^^^^^^^^^^
  File "D:\01_Anaconda\envs\ADDMo-Extra\Lib\urllib\request.py", line 643, in http_error_default
    raise HTTPError(req.full_url, code, msg, hdrs, fp)
urllib.error.HTTPError: HTTP Error 500: Internal Server Error
During handling of the above exception, another exception occurred:
Traceback (most recent call last):
  File "D:\02_PyCharm\PyCharm 2022.3.2\plugins\python\helpers\pycharm_display\datalore\display\display_.py", line 61, in try_empty_proxy
    urllib_request.urlopen(url, buffer)
  File "D:\01_Anaconda\envs\ADDMo-Extra\Lib\urllib\request.py", line 216, in urlopen
    return opener.open(url, data, timeout)
           ^^^^^^^^^^^^^^^^^^^^^^^^^^^^^^^
  File "D:\01_Anaconda\envs\ADDMo-Extra\Lib\urllib\request.py", line 525, in open
    response = meth(req, response)
               ^^^^^^^^^^^^^^^^^^^
  File "D:\01_Anaconda\envs\ADDMo-Extra\Lib\urllib\request.py", line 634, in http_response
    response = self.parent.error(
               ^^^^^^^^^^^^^^^^^^
  File "D:\01_Anaconda\envs\ADDMo-Extra\Lib\urllib\request.py", line 563, in error
    return self._call_chain(*args)
           ^^^^^^^^^^^^^^^^^^^^^^^
  File "D:\01_Anaconda\envs\ADDMo-Extra\Lib\urllib\request.py", line 496, in _call_chain
    result = func(*args)
             ^^^^^^^^^^^
  File "D:\01_Anaconda\envs\ADDMo-Extra\Lib\urllib\request.py", line 643, in http_error_default
    raise HTTPError(req.full_url, code, msg, hdrs, fp)
urllib.error.HTTPError: HTTP Error 500: Internal Server Error
Error: failed to send plot to http://127.0.0.1:63342
Traceback (most recent call last):
  File "D:\02_PyCharm\PyCharm 2022.3.2\plugins\python\helpers\pycharm_display\datalore\display\display_.py", line 86, in _send_display_message
    urllib_request.urlopen(url, buffer)
  File "D:\01_Anaconda\envs\ADDMo-Extra\Lib\urllib\request.py", line 216, in urlopen
    return opener.open(url, data, timeout)
           ^^^^^^^^^^^^^^^^^^^^^^^^^^^^^^^
  File "D:\01_Anaconda\envs\ADDMo-Extra\Lib\urllib\request.py", line 525, in open
    response = meth(req, response)
               ^^^^^^^^^^^^^^^^^^^
  File "D:\01_Anaconda\envs\ADDMo-Extra\Lib\urllib\request.py", line 634, in http_response
    response = self.parent.error(
               ^^^^^^^^^^^^^^^^^^
  File "D:\01_Anaconda\envs\ADDMo-Extra\Lib\urllib\request.py", line 563, in error
    return self._call_chain(*args)
           ^^^^^^^^^^^^^^^^^^^^^^^
  File "D:\01_Anaconda\envs\ADDMo-Extra\Lib\urllib\request.py", line 496, in _call_chain
    result = func(*args)
             ^^^^^^^^^^^
  File "D:\01_Anaconda\envs\ADDMo-Extra\Lib\urllib\request.py", line 643, in http_error_default
    raise HTTPError(req.full_url, code, msg, hdrs, fp)
urllib.error.HTTPError: HTTP Error 500: Internal Server Error
During handling of the above exception, another exception occurred:
Traceback (most recent call last):
  File "D:\02_PyCharm\PyCharm 2022.3.2\plugins\python\helpers\pycharm_display\datalore\display\display_.py", line 61, in try_empty_proxy
    urllib_request.urlopen(url, buffer)
  File "D:\01_Anaconda\envs\ADDMo-Extra\Lib\urllib\request.py", line 216, in urlopen
    return opener.open(url, data, timeout)
           ^^^^^^^^^^^^^^^^^^^^^^^^^^^^^^^
  File "D:\01_Anaconda\envs\ADDMo-Extra\Lib\urllib\request.py", line 525, in open
    response = meth(req, response)
               ^^^^^^^^^^^^^^^^^^^
  File "D:\01_Anaconda\envs\ADDMo-Extra\Lib\urllib\request.py", line 634, in http_response
    response = self.parent.error(
               ^^^^^^^^^^^^^^^^^^
  File "D:\01_Anaconda\envs\ADDMo-Extra\Lib\urllib\request.py", line 563, in error
    return self._call_chain(*args)
           ^^^^^^^^^^^^^^^^^^^^^^^
  File "D:\01_Anaconda\envs\ADDMo-Extra\Lib\urllib\request.py", line 496, in _call_chain
    result = func(*args)
             ^^^^^^^^^^^
  File "D:\01_Anaconda\envs\ADDMo-Extra\Lib\urllib\request.py", line 643, in http_error_default
    raise HTTPError(req.full_url, code, msg, hdrs, fp)
urllib.error.HTTPError: HTTP Error 500: Internal Server Error
Error: failed to send plot to http://127.0.0.1:63342
Traceback (most recent call last):
  File "D:\02_PyCharm\PyCharm 2022.3.2\plugins\python\helpers\pycharm_display\datalore\display\display_.py", line 86, in _send_display_message
    urllib_request.urlopen(url, buffer)
  File "D:\01_Anaconda\envs\ADDMo-Extra\Lib\urllib\request.py", line 216, in urlopen
    return opener.open(url, data, timeout)
           ^^^^^^^^^^^^^^^^^^^^^^^^^^^^^^^
  File "D:\01_Anaconda\envs\ADDMo-Extra\Lib\urllib\request.py", line 525, in open
    response = meth(req, response)
               ^^^^^^^^^^^^^^^^^^^
  File "D:\01_Anaconda\envs\ADDMo-Extra\Lib\urllib\request.py", line 634, in http_response
    response = self.parent.error(
               ^^^^^^^^^^^^^^^^^^
  File "D:\01_Anaconda\envs\ADDMo-Extra\Lib\urllib\request.py", line 563, in error
    return self._call_chain(*args)
           ^^^^^^^^^^^^^^^^^^^^^^^
  File "D:\01_Anaconda\envs\ADDMo-Extra\Lib\urllib\request.py", line 496, in _call_chain
    result = func(*args)
             ^^^^^^^^^^^
  File "D:\01_Anaconda\envs\ADDMo-Extra\Lib\urllib\request.py", line 643, in http_error_default
    raise HTTPError(req.full_url, code, msg, hdrs, fp)
urllib.error.HTTPError: HTTP Error 500: Internal Server Error
During handling of the above exception, another exception occurred:
Traceback (most recent call last):
  File "D:\02_PyCharm\PyCharm 2022.3.2\plugins\python\helpers\pycharm_display\datalore\display\display_.py", line 61, in try_empty_proxy
    urllib_request.urlopen(url, buffer)
  File "D:\01_Anaconda\envs\ADDMo-Extra\Lib\urllib\request.py", line 216, in urlopen
    return opener.open(url, data, timeout)
           ^^^^^^^^^^^^^^^^^^^^^^^^^^^^^^^
  File "D:\01_Anaconda\envs\ADDMo-Extra\Lib\urllib\request.py", line 525, in open
    response = meth(req, response)
               ^^^^^^^^^^^^^^^^^^^
  File "D:\01_Anaconda\envs\ADDMo-Extra\Lib\urllib\request.py", line 634, in http_response
    response = self.parent.error(
               ^^^^^^^^^^^^^^^^^^
  File "D:\01_Anaconda\envs\ADDMo-Extra\Lib\urllib\request.py", line 563, in error
    return self._call_chain(*args)
           ^^^^^^^^^^^^^^^^^^^^^^^
  File "D:\01_Anaconda\envs\ADDMo-Extra\Lib\urllib\request.py", line 496, in _call_chain
    result = func(*args)
             ^^^^^^^^^^^
  File "D:\01_Anaconda\envs\ADDMo-Extra\Lib\urllib\request.py", line 643, in http_error_default
    raise HTTPError(req.full_url, code, msg, hdrs, fp)
urllib.error.HTTPError: HTTP Error 500: Internal Server Error
Error: failed to send plot to http://127.0.0.1:63342
Traceback (most recent call last):
  File "D:\02_PyCharm\PyCharm 2022.3.2\plugins\python\helpers\pycharm_display\datalore\display\display_.py", line 86, in _send_display_message
    urllib_request.urlopen(url, buffer)
  File "D:\01_Anaconda\envs\ADDMo-Extra\Lib\urllib\request.py", line 216, in urlopen
    return opener.open(url, data, timeout)
           ^^^^^^^^^^^^^^^^^^^^^^^^^^^^^^^
  File "D:\01_Anaconda\envs\ADDMo-Extra\Lib\urllib\request.py", line 525, in open
    response = meth(req, response)
               ^^^^^^^^^^^^^^^^^^^
  File "D:\01_Anaconda\envs\ADDMo-Extra\Lib\urllib\request.py", line 634, in http_response
    response = self.parent.error(
               ^^^^^^^^^^^^^^^^^^
  File "D:\01_Anaconda\envs\ADDMo-Extra\Lib\urllib\request.py", line 563, in error
    return self._call_chain(*args)
           ^^^^^^^^^^^^^^^^^^^^^^^
  File "D:\01_Anaconda\envs\ADDMo-Extra\Lib\urllib\request.py", line 496, in _call_chain
    result = func(*args)
             ^^^^^^^^^^^
  File "D:\01_Anaconda\envs\ADDMo-Extra\Lib\urllib\request.py", line 643, in http_error_default
    raise HTTPError(req.full_url, code, msg, hdrs, fp)
urllib.error.HTTPError: HTTP Error 500: Internal Server Error
During handling of the above exception, another exception occurred:
Traceback (most recent call last):
  File "D:\02_PyCharm\PyCharm 2022.3.2\plugins\python\helpers\pycharm_display\datalore\display\display_.py", line 61, in try_empty_proxy
    urllib_request.urlopen(url, buffer)
  File "D:\01_Anaconda\envs\ADDMo-Extra\Lib\urllib\request.py", line 216, in urlopen
    return opener.open(url, data, timeout)
           ^^^^^^^^^^^^^^^^^^^^^^^^^^^^^^^
  File "D:\01_Anaconda\envs\ADDMo-Extra\Lib\urllib\request.py", line 525, in open
    response = meth(req, response)
               ^^^^^^^^^^^^^^^^^^^
  File "D:\01_Anaconda\envs\ADDMo-Extra\Lib\urllib\request.py", line 634, in http_response
    response = self.parent.error(
               ^^^^^^^^^^^^^^^^^^
  File "D:\01_Anaconda\envs\ADDMo-Extra\Lib\urllib\request.py", line 563, in error
    return self._call_chain(*args)
           ^^^^^^^^^^^^^^^^^^^^^^^
  File "D:\01_Anaconda\envs\ADDMo-Extra\Lib\urllib\request.py", line 496, in _call_chain
    result = func(*args)
             ^^^^^^^^^^^
  File "D:\01_Anaconda\envs\ADDMo-Extra\Lib\urllib\request.py", line 643, in http_error_default
    raise HTTPError(req.full_url, code, msg, hdrs, fp)
urllib.error.HTTPError: HTTP Error 500: Internal Server Error
Error: failed to send plot to http://127.0.0.1:63342
Traceback (most recent call last):
  File "D:\02_PyCharm\PyCharm 2022.3.2\plugins\python\helpers\pycharm_display\datalore\display\display_.py", line 86, in _send_display_message
    urllib_request.urlopen(url, buffer)
  File "D:\01_Anaconda\envs\ADDMo-Extra\Lib\urllib\request.py", line 216, in urlopen
    return opener.open(url, data, timeout)
           ^^^^^^^^^^^^^^^^^^^^^^^^^^^^^^^
  File "D:\01_Anaconda\envs\ADDMo-Extra\Lib\urllib\request.py", line 525, in open
    response = meth(req, response)
               ^^^^^^^^^^^^^^^^^^^
  File "D:\01_Anaconda\envs\ADDMo-Extra\Lib\urllib\request.py", line 634, in http_response
    response = self.parent.error(
               ^^^^^^^^^^^^^^^^^^
  File "D:\01_Anaconda\envs\ADDMo-Extra\Lib\urllib\request.py", line 563, in error
    return self._call_chain(*args)
           ^^^^^^^^^^^^^^^^^^^^^^^
  File "D:\01_Anaconda\envs\ADDMo-Extra\Lib\urllib\request.py", line 496, in _call_chain
    result = func(*args)
             ^^^^^^^^^^^
  File "D:\01_Anaconda\envs\ADDMo-Extra\Lib\urllib\request.py", line 643, in http_error_default
    raise HTTPError(req.full_url, code, msg, hdrs, fp)
urllib.error.HTTPError: HTTP Error 500: Internal Server Error
During handling of the above exception, another exception occurred:
Traceback (most recent call last):
  File "D:\02_PyCharm\PyCharm 2022.3.2\plugins\python\helpers\pycharm_display\datalore\display\display_.py", line 61, in try_empty_proxy
    urllib_request.urlopen(url, buffer)
  File "D:\01_Anaconda\envs\ADDMo-Extra\Lib\urllib\request.py", line 216, in urlopen
    return opener.open(url, data, timeout)
           ^^^^^^^^^^^^^^^^^^^^^^^^^^^^^^^
  File "D:\01_Anaconda\envs\ADDMo-Extra\Lib\urllib\request.py", line 525, in open
    response = meth(req, response)
               ^^^^^^^^^^^^^^^^^^^
  File "D:\01_Anaconda\envs\ADDMo-Extra\Lib\urllib\request.py", line 634, in http_response
    response = self.parent.error(
               ^^^^^^^^^^^^^^^^^^
  File "D:\01_Anaconda\envs\ADDMo-Extra\Lib\urllib\request.py", line 563, in error
    return self._call_chain(*args)
           ^^^^^^^^^^^^^^^^^^^^^^^
  File "D:\01_Anaconda\envs\ADDMo-Extra\Lib\urllib\request.py", line 496, in _call_chain
    result = func(*args)
             ^^^^^^^^^^^
  File "D:\01_Anaconda\envs\ADDMo-Extra\Lib\urllib\request.py", line 643, in http_error_default
    raise HTTPError(req.full_url, code, msg, hdrs, fp)
urllib.error.HTTPError: HTTP Error 500: Internal Server Error
Error: failed to send plot to http://127.0.0.1:63342
Traceback (most recent call last):
  File "D:\02_PyCharm\PyCharm 2022.3.2\plugins\python\helpers\pycharm_display\datalore\display\display_.py", line 86, in _send_display_message
    urllib_request.urlopen(url, buffer)
  File "D:\01_Anaconda\envs\ADDMo-Extra\Lib\urllib\request.py", line 216, in urlopen
    return opener.open(url, data, timeout)
           ^^^^^^^^^^^^^^^^^^^^^^^^^^^^^^^
  File "D:\01_Anaconda\envs\ADDMo-Extra\Lib\urllib\request.py", line 525, in open
    response = meth(req, response)
               ^^^^^^^^^^^^^^^^^^^
  File "D:\01_Anaconda\envs\ADDMo-Extra\Lib\urllib\request.py", line 634, in http_response
    response = self.parent.error(
               ^^^^^^^^^^^^^^^^^^
  File "D:\01_Anaconda\envs\ADDMo-Extra\Lib\urllib\request.py", line 563, in error
    return self._call_chain(*args)
           ^^^^^^^^^^^^^^^^^^^^^^^
  File "D:\01_Anaconda\envs\ADDMo-Extra\Lib\urllib\request.py", line 496, in _call_chain
    result = func(*args)
             ^^^^^^^^^^^
  File "D:\01_Anaconda\envs\ADDMo-Extra\Lib\urllib\request.py", line 643, in http_error_default
    raise HTTPError(req.full_url, code, msg, hdrs, fp)
urllib.error.HTTPError: HTTP Error 500: Internal Server Error
During handling of the above exception, another exception occurred:
Traceback (most recent call last):
  File "D:\02_PyCharm\PyCharm 2022.3.2\plugins\python\helpers\pycharm_display\datalore\display\display_.py", line 61, in try_empty_proxy
    urllib_request.urlopen(url, buffer)
  File "D:\01_Anaconda\envs\ADDMo-Extra\Lib\urllib\request.py", line 216, in urlopen
    return opener.open(url, data, timeout)
           ^^^^^^^^^^^^^^^^^^^^^^^^^^^^^^^
  File "D:\01_Anaconda\envs\ADDMo-Extra\Lib\urllib\request.py", line 525, in open
    response = meth(req, response)
               ^^^^^^^^^^^^^^^^^^^
  File "D:\01_Anaconda\envs\ADDMo-Extra\Lib\urllib\request.py", line 634, in http_response
    response = self.parent.error(
               ^^^^^^^^^^^^^^^^^^
  File "D:\01_Anaconda\envs\ADDMo-Extra\Lib\urllib\request.py", line 563, in error
    return self._call_chain(*args)
           ^^^^^^^^^^^^^^^^^^^^^^^
  File "D:\01_Anaconda\envs\ADDMo-Extra\Lib\urllib\request.py", line 496, in _call_chain
    result = func(*args)
             ^^^^^^^^^^^
  File "D:\01_Anaconda\envs\ADDMo-Extra\Lib\urllib\request.py", line 643, in http_error_default
    raise HTTPError(req.full_url, code, msg, hdrs, fp)
urllib.error.HTTPError: HTTP Error 500: Internal Server Error
Error: failed to send plot to http://127.0.0.1:63342
Traceback (most recent call last):
  File "D:\02_PyCharm\PyCharm 2022.3.2\plugins\python\helpers\pycharm_display\datalore\display\display_.py", line 86, in _send_display_message
    urllib_request.urlopen(url, buffer)
  File "D:\01_Anaconda\envs\ADDMo-Extra\Lib\urllib\request.py", line 216, in urlopen
    return opener.open(url, data, timeout)
           ^^^^^^^^^^^^^^^^^^^^^^^^^^^^^^^
  File "D:\01_Anaconda\envs\ADDMo-Extra\Lib\urllib\request.py", line 525, in open
    response = meth(req, response)
               ^^^^^^^^^^^^^^^^^^^
  File "D:\01_Anaconda\envs\ADDMo-Extra\Lib\urllib\request.py", line 634, in http_response
    response = self.parent.error(
               ^^^^^^^^^^^^^^^^^^
  File "D:\01_Anaconda\envs\ADDMo-Extra\Lib\urllib\request.py", line 563, in error
    return self._call_chain(*args)
           ^^^^^^^^^^^^^^^^^^^^^^^
  File "D:\01_Anaconda\envs\ADDMo-Extra\Lib\urllib\request.py", line 496, in _call_chain
    result = func(*args)
             ^^^^^^^^^^^
  File "D:\01_Anaconda\envs\ADDMo-Extra\Lib\urllib\request.py", line 643, in http_error_default
    raise HTTPError(req.full_url, code, msg, hdrs, fp)
urllib.error.HTTPError: HTTP Error 500: Internal Server Error
During handling of the above exception, another exception occurred:
Traceback (most recent call last):
  File "D:\02_PyCharm\PyCharm 2022.3.2\plugins\python\helpers\pycharm_display\datalore\display\display_.py", line 61, in try_empty_proxy
    urllib_request.urlopen(url, buffer)
  File "D:\01_Anaconda\envs\ADDMo-Extra\Lib\urllib\request.py", line 216, in urlopen
    return opener.open(url, data, timeout)
           ^^^^^^^^^^^^^^^^^^^^^^^^^^^^^^^
  File "D:\01_Anaconda\envs\ADDMo-Extra\Lib\urllib\request.py", line 525, in open
    response = meth(req, response)
               ^^^^^^^^^^^^^^^^^^^
  File "D:\01_Anaconda\envs\ADDMo-Extra\Lib\urllib\request.py", line 634, in http_response
    response = self.parent.error(
               ^^^^^^^^^^^^^^^^^^
  File "D:\01_Anaconda\envs\ADDMo-Extra\Lib\urllib\request.py", line 563, in error
    return self._call_chain(*args)
           ^^^^^^^^^^^^^^^^^^^^^^^
  File "D:\01_Anaconda\envs\ADDMo-Extra\Lib\urllib\request.py", line 496, in _call_chain
    result = func(*args)
             ^^^^^^^^^^^
  File "D:\01_Anaconda\envs\ADDMo-Extra\Lib\urllib\request.py", line 643, in http_error_default
    raise HTTPError(req.full_url, code, msg, hdrs, fp)
urllib.error.HTTPError: HTTP Error 500: Internal Server Error
Error: failed to send plot to http://127.0.0.1:63342
Traceback (most recent call last):
  File "D:\02_PyCharm\PyCharm 2022.3.2\plugins\python\helpers\pycharm_display\datalore\display\display_.py", line 86, in _send_display_message
    urllib_request.urlopen(url, buffer)
  File "D:\01_Anaconda\envs\ADDMo-Extra\Lib\urllib\request.py", line 216, in urlopen
    return opener.open(url, data, timeout)
           ^^^^^^^^^^^^^^^^^^^^^^^^^^^^^^^
  File "D:\01_Anaconda\envs\ADDMo-Extra\Lib\urllib\request.py", line 525, in open
    response = meth(req, response)
               ^^^^^^^^^^^^^^^^^^^
  File "D:\01_Anaconda\envs\ADDMo-Extra\Lib\urllib\request.py", line 634, in http_response
    response = self.parent.error(
               ^^^^^^^^^^^^^^^^^^
  File "D:\01_Anaconda\envs\ADDMo-Extra\Lib\urllib\request.py", line 563, in error
    return self._call_chain(*args)
           ^^^^^^^^^^^^^^^^^^^^^^^
  File "D:\01_Anaconda\envs\ADDMo-Extra\Lib\urllib\request.py", line 496, in _call_chain
    result = func(*args)
             ^^^^^^^^^^^
  File "D:\01_Anaconda\envs\ADDMo-Extra\Lib\urllib\request.py", line 643, in http_error_default
    raise HTTPError(req.full_url, code, msg, hdrs, fp)
urllib.error.HTTPError: HTTP Error 500: Internal Server Error
During handling of the above exception, another exception occurred:
Traceback (most recent call last):
  File "D:\02_PyCharm\PyCharm 2022.3.2\plugins\python\helpers\pycharm_display\datalore\display\display_.py", line 61, in try_empty_proxy
    urllib_request.urlopen(url, buffer)
  File "D:\01_Anaconda\envs\ADDMo-Extra\Lib\urllib\request.py", line 216, in urlopen
    return opener.open(url, data, timeout)
           ^^^^^^^^^^^^^^^^^^^^^^^^^^^^^^^
  File "D:\01_Anaconda\envs\ADDMo-Extra\Lib\urllib\request.py", line 525, in open
    response = meth(req, response)
               ^^^^^^^^^^^^^^^^^^^
  File "D:\01_Anaconda\envs\ADDMo-Extra\Lib\urllib\request.py", line 634, in http_response
    response = self.parent.error(
               ^^^^^^^^^^^^^^^^^^
  File "D:\01_Anaconda\envs\ADDMo-Extra\Lib\urllib\request.py", line 563, in error
    return self._call_chain(*args)
           ^^^^^^^^^^^^^^^^^^^^^^^
  File "D:\01_Anaconda\envs\ADDMo-Extra\Lib\urllib\request.py", line 496, in _call_chain
    result = func(*args)
             ^^^^^^^^^^^
  File "D:\01_Anaconda\envs\ADDMo-Extra\Lib\urllib\request.py", line 643, in http_error_default
    raise HTTPError(req.full_url, code, msg, hdrs, fp)
urllib.error.HTTPError: HTTP Error 500: Internal Server Error
Error: failed to send plot to http://127.0.0.1:63342
Traceback (most recent call last):
  File "D:\02_PyCharm\PyCharm 2022.3.2\plugins\python\helpers\pycharm_display\datalore\display\display_.py", line 86, in _send_display_message
    urllib_request.urlopen(url, buffer)
  File "D:\01_Anaconda\envs\ADDMo-Extra\Lib\urllib\request.py", line 216, in urlopen
    return opener.open(url, data, timeout)
           ^^^^^^^^^^^^^^^^^^^^^^^^^^^^^^^
  File "D:\01_Anaconda\envs\ADDMo-Extra\Lib\urllib\request.py", line 525, in open
    response = meth(req, response)
               ^^^^^^^^^^^^^^^^^^^
  File "D:\01_Anaconda\envs\ADDMo-Extra\Lib\urllib\request.py", line 634, in http_response
    response = self.parent.error(
               ^^^^^^^^^^^^^^^^^^
  File "D:\01_Anaconda\envs\ADDMo-Extra\Lib\urllib\request.py", line 563, in error
    return self._call_chain(*args)
           ^^^^^^^^^^^^^^^^^^^^^^^
  File "D:\01_Anaconda\envs\ADDMo-Extra\Lib\urllib\request.py", line 496, in _call_chain
    result = func(*args)
             ^^^^^^^^^^^
  File "D:\01_Anaconda\envs\ADDMo-Extra\Lib\urllib\request.py", line 643, in http_error_default
    raise HTTPError(req.full_url, code, msg, hdrs, fp)
urllib.error.HTTPError: HTTP Error 500: Internal Server Error
During handling of the above exception, another exception occurred:
Traceback (most recent call last):
  File "D:\02_PyCharm\PyCharm 2022.3.2\plugins\python\helpers\pycharm_display\datalore\display\display_.py", line 61, in try_empty_proxy
    urllib_request.urlopen(url, buffer)
  File "D:\01_Anaconda\envs\ADDMo-Extra\Lib\urllib\request.py", line 216, in urlopen
    return opener.open(url, data, timeout)
           ^^^^^^^^^^^^^^^^^^^^^^^^^^^^^^^
  File "D:\01_Anaconda\envs\ADDMo-Extra\Lib\urllib\request.py", line 525, in open
    response = meth(req, response)
               ^^^^^^^^^^^^^^^^^^^
  File "D:\01_Anaconda\envs\ADDMo-Extra\Lib\urllib\request.py", line 634, in http_response
    response = self.parent.error(
               ^^^^^^^^^^^^^^^^^^
  File "D:\01_Anaconda\envs\ADDMo-Extra\Lib\urllib\request.py", line 563, in error
    return self._call_chain(*args)
           ^^^^^^^^^^^^^^^^^^^^^^^
  File "D:\01_Anaconda\envs\ADDMo-Extra\Lib\urllib\request.py", line 496, in _call_chain
    result = func(*args)
             ^^^^^^^^^^^
  File "D:\01_Anaconda\envs\ADDMo-Extra\Lib\urllib\request.py", line 643, in http_error_default
    raise HTTPError(req.full_url, code, msg, hdrs, fp)
urllib.error.HTTPError: HTTP Error 500: Internal Server Error
Error: failed to send plot to http://127.0.0.1:63342
Traceback (most recent call last):
  File "D:\02_PyCharm\PyCharm 2022.3.2\plugins\python\helpers\pycharm_display\datalore\display\display_.py", line 86, in _send_display_message
    urllib_request.urlopen(url, buffer)
  File "D:\01_Anaconda\envs\ADDMo-Extra\Lib\urllib\request.py", line 216, in urlopen
    return opener.open(url, data, timeout)
           ^^^^^^^^^^^^^^^^^^^^^^^^^^^^^^^
  File "D:\01_Anaconda\envs\ADDMo-Extra\Lib\urllib\request.py", line 525, in open
    response = meth(req, response)
               ^^^^^^^^^^^^^^^^^^^
  File "D:\01_Anaconda\envs\ADDMo-Extra\Lib\urllib\request.py", line 634, in http_response
    response = self.parent.error(
               ^^^^^^^^^^^^^^^^^^
  File "D:\01_Anaconda\envs\ADDMo-Extra\Lib\urllib\request.py", line 563, in error
    return self._call_chain(*args)
           ^^^^^^^^^^^^^^^^^^^^^^^
  File "D:\01_Anaconda\envs\ADDMo-Extra\Lib\urllib\request.py", line 496, in _call_chain
    result = func(*args)
             ^^^^^^^^^^^
  File "D:\01_Anaconda\envs\ADDMo-Extra\Lib\urllib\request.py", line 643, in http_error_default
    raise HTTPError(req.full_url, code, msg, hdrs, fp)
urllib.error.HTTPError: HTTP Error 500: Internal Server Error
During handling of the above exception, another exception occurred:
Traceback (most recent call last):
  File "D:\02_PyCharm\PyCharm 2022.3.2\plugins\python\helpers\pycharm_display\datalore\display\display_.py", line 61, in try_empty_proxy
    urllib_request.urlopen(url, buffer)
  File "D:\01_Anaconda\envs\ADDMo-Extra\Lib\urllib\request.py", line 216, in urlopen
    return opener.open(url, data, timeout)
           ^^^^^^^^^^^^^^^^^^^^^^^^^^^^^^^
  File "D:\01_Anaconda\envs\ADDMo-Extra\Lib\urllib\request.py", line 525, in open
    response = meth(req, response)
               ^^^^^^^^^^^^^^^^^^^
  File "D:\01_Anaconda\envs\ADDMo-Extra\Lib\urllib\request.py", line 634, in http_response
    response = self.parent.error(
               ^^^^^^^^^^^^^^^^^^
  File "D:\01_Anaconda\envs\ADDMo-Extra\Lib\urllib\request.py", line 563, in error
    return self._call_chain(*args)
           ^^^^^^^^^^^^^^^^^^^^^^^
  File "D:\01_Anaconda\envs\ADDMo-Extra\Lib\urllib\request.py", line 496, in _call_chain
    result = func(*args)
             ^^^^^^^^^^^
  File "D:\01_Anaconda\envs\ADDMo-Extra\Lib\urllib\request.py", line 643, in http_error_default
    raise HTTPError(req.full_url, code, msg, hdrs, fp)
urllib.error.HTTPError: HTTP Error 500: Internal Server Error
Error: failed to send plot to http://127.0.0.1:63342
Traceback (most recent call last):
  File "D:\02_PyCharm\PyCharm 2022.3.2\plugins\python\helpers\pycharm_display\datalore\display\display_.py", line 86, in _send_display_message
    urllib_request.urlopen(url, buffer)
  File "D:\01_Anaconda\envs\ADDMo-Extra\Lib\urllib\request.py", line 216, in urlopen
    return opener.open(url, data, timeout)
           ^^^^^^^^^^^^^^^^^^^^^^^^^^^^^^^
  File "D:\01_Anaconda\envs\ADDMo-Extra\Lib\urllib\request.py", line 525, in open
    response = meth(req, response)
               ^^^^^^^^^^^^^^^^^^^
  File "D:\01_Anaconda\envs\ADDMo-Extra\Lib\urllib\request.py", line 634, in http_response
    response = self.parent.error(
               ^^^^^^^^^^^^^^^^^^
  File "D:\01_Anaconda\envs\ADDMo-Extra\Lib\urllib\request.py", line 563, in error
    return self._call_chain(*args)
           ^^^^^^^^^^^^^^^^^^^^^^^
  File "D:\01_Anaconda\envs\ADDMo-Extra\Lib\urllib\request.py", line 496, in _call_chain
    result = func(*args)
             ^^^^^^^^^^^
  File "D:\01_Anaconda\envs\ADDMo-Extra\Lib\urllib\request.py", line 643, in http_error_default
    raise HTTPError(req.full_url, code, msg, hdrs, fp)
urllib.error.HTTPError: HTTP Error 500: Internal Server Error
During handling of the above exception, another exception occurred:
Traceback (most recent call last):
  File "D:\02_PyCharm\PyCharm 2022.3.2\plugins\python\helpers\pycharm_display\datalore\display\display_.py", line 61, in try_empty_proxy
    urllib_request.urlopen(url, buffer)
  File "D:\01_Anaconda\envs\ADDMo-Extra\Lib\urllib\request.py", line 216, in urlopen
    return opener.open(url, data, timeout)
           ^^^^^^^^^^^^^^^^^^^^^^^^^^^^^^^
  File "D:\01_Anaconda\envs\ADDMo-Extra\Lib\urllib\request.py", line 525, in open
    response = meth(req, response)
               ^^^^^^^^^^^^^^^^^^^
  File "D:\01_Anaconda\envs\ADDMo-Extra\Lib\urllib\request.py", line 634, in http_response
    response = self.parent.error(
               ^^^^^^^^^^^^^^^^^^
  File "D:\01_Anaconda\envs\ADDMo-Extra\Lib\urllib\request.py", line 563, in error
    return self._call_chain(*args)
           ^^^^^^^^^^^^^^^^^^^^^^^
  File "D:\01_Anaconda\envs\ADDMo-Extra\Lib\urllib\request.py", line 496, in _call_chain
    result = func(*args)
             ^^^^^^^^^^^
  File "D:\01_Anaconda\envs\ADDMo-Extra\Lib\urllib\request.py", line 643, in http_error_default
    raise HTTPError(req.full_url, code, msg, hdrs, fp)
urllib.error.HTTPError: HTTP Error 500: Internal Server Error
Error: failed to send plot to http://127.0.0.1:63342
Traceback (most recent call last):
  File "D:\02_PyCharm\PyCharm 2022.3.2\plugins\python\helpers\pycharm_display\datalore\display\display_.py", line 86, in _send_display_message
    urllib_request.urlopen(url, buffer)
  File "D:\01_Anaconda\envs\ADDMo-Extra\Lib\urllib\request.py", line 216, in urlopen
    return opener.open(url, data, timeout)
           ^^^^^^^^^^^^^^^^^^^^^^^^^^^^^^^
  File "D:\01_Anaconda\envs\ADDMo-Extra\Lib\urllib\request.py", line 525, in open
    response = meth(req, response)
               ^^^^^^^^^^^^^^^^^^^
  File "D:\01_Anaconda\envs\ADDMo-Extra\Lib\urllib\request.py", line 634, in http_response
    response = self.parent.error(
               ^^^^^^^^^^^^^^^^^^
  File "D:\01_Anaconda\envs\ADDMo-Extra\Lib\urllib\request.py", line 563, in error
    return self._call_chain(*args)
           ^^^^^^^^^^^^^^^^^^^^^^^
  File "D:\01_Anaconda\envs\ADDMo-Extra\Lib\urllib\request.py", line 496, in _call_chain
    result = func(*args)
             ^^^^^^^^^^^
  File "D:\01_Anaconda\envs\ADDMo-Extra\Lib\urllib\request.py", line 643, in http_error_default
    raise HTTPError(req.full_url, code, msg, hdrs, fp)
urllib.error.HTTPError: HTTP Error 500: Internal Server Error
During handling of the above exception, another exception occurred:
Traceback (most recent call last):
  File "D:\02_PyCharm\PyCharm 2022.3.2\plugins\python\helpers\pycharm_display\datalore\display\display_.py", line 61, in try_empty_proxy
    urllib_request.urlopen(url, buffer)
  File "D:\01_Anaconda\envs\ADDMo-Extra\Lib\urllib\request.py", line 216, in urlopen
    return opener.open(url, data, timeout)
           ^^^^^^^^^^^^^^^^^^^^^^^^^^^^^^^
  File "D:\01_Anaconda\envs\ADDMo-Extra\Lib\urllib\request.py", line 525, in open
    response = meth(req, response)
               ^^^^^^^^^^^^^^^^^^^
  File "D:\01_Anaconda\envs\ADDMo-Extra\Lib\urllib\request.py", line 634, in http_response
    response = self.parent.error(
               ^^^^^^^^^^^^^^^^^^
  File "D:\01_Anaconda\envs\ADDMo-Extra\Lib\urllib\request.py", line 563, in error
    return self._call_chain(*args)
           ^^^^^^^^^^^^^^^^^^^^^^^
  File "D:\01_Anaconda\envs\ADDMo-Extra\Lib\urllib\request.py", line 496, in _call_chain
    result = func(*args)
             ^^^^^^^^^^^
  File "D:\01_Anaconda\envs\ADDMo-Extra\Lib\urllib\request.py", line 643, in http_error_default
    raise HTTPError(req.full_url, code, msg, hdrs, fp)
urllib.error.HTTPError: HTTP Error 500: Internal Server Error
Error: failed to send plot to http://127.0.0.1:63342
Traceback (most recent call last):
  File "D:\02_PyCharm\PyCharm 2022.3.2\plugins\python\helpers\pycharm_display\datalore\display\display_.py", line 86, in _send_display_message
    urllib_request.urlopen(url, buffer)
  File "D:\01_Anaconda\envs\ADDMo-Extra\Lib\urllib\request.py", line 216, in urlopen
    return opener.open(url, data, timeout)
           ^^^^^^^^^^^^^^^^^^^^^^^^^^^^^^^
  File "D:\01_Anaconda\envs\ADDMo-Extra\Lib\urllib\request.py", line 525, in open
    response = meth(req, response)
               ^^^^^^^^^^^^^^^^^^^
  File "D:\01_Anaconda\envs\ADDMo-Extra\Lib\urllib\request.py", line 634, in http_response
    response = self.parent.error(
               ^^^^^^^^^^^^^^^^^^
  File "D:\01_Anaconda\envs\ADDMo-Extra\Lib\urllib\request.py", line 563, in error
    return self._call_chain(*args)
           ^^^^^^^^^^^^^^^^^^^^^^^
  File "D:\01_Anaconda\envs\ADDMo-Extra\Lib\urllib\request.py", line 496, in _call_chain
    result = func(*args)
             ^^^^^^^^^^^
  File "D:\01_Anaconda\envs\ADDMo-Extra\Lib\urllib\request.py", line 643, in http_error_default
    raise HTTPError(req.full_url, code, msg, hdrs, fp)
urllib.error.HTTPError: HTTP Error 500: Internal Server Error
During handling of the above exception, another exception occurred:
Traceback (most recent call last):
  File "D:\02_PyCharm\PyCharm 2022.3.2\plugins\python\helpers\pycharm_display\datalore\display\display_.py", line 61, in try_empty_proxy
    urllib_request.urlopen(url, buffer)
  File "D:\01_Anaconda\envs\ADDMo-Extra\Lib\urllib\request.py", line 216, in urlopen
    return opener.open(url, data, timeout)
           ^^^^^^^^^^^^^^^^^^^^^^^^^^^^^^^
  File "D:\01_Anaconda\envs\ADDMo-Extra\Lib\urllib\request.py", line 525, in open
    response = meth(req, response)
               ^^^^^^^^^^^^^^^^^^^
  File "D:\01_Anaconda\envs\ADDMo-Extra\Lib\urllib\request.py", line 634, in http_response
    response = self.parent.error(
               ^^^^^^^^^^^^^^^^^^
  File "D:\01_Anaconda\envs\ADDMo-Extra\Lib\urllib\request.py", line 563, in error
    return self._call_chain(*args)
           ^^^^^^^^^^^^^^^^^^^^^^^
  File "D:\01_Anaconda\envs\ADDMo-Extra\Lib\urllib\request.py", line 496, in _call_chain
    result = func(*args)
             ^^^^^^^^^^^
  File "D:\01_Anaconda\envs\ADDMo-Extra\Lib\urllib\request.py", line 643, in http_error_default
    raise HTTPError(req.full_url, code, msg, hdrs, fp)
urllib.error.HTTPError: HTTP Error 500: Internal Server Error
Error: failed to send plot to http://127.0.0.1:63342
Traceback (most recent call last):
  File "D:\02_PyCharm\PyCharm 2022.3.2\plugins\python\helpers\pycharm_display\datalore\display\display_.py", line 86, in _send_display_message
    urllib_request.urlopen(url, buffer)
  File "D:\01_Anaconda\envs\ADDMo-Extra\Lib\urllib\request.py", line 216, in urlopen
    return opener.open(url, data, timeout)
           ^^^^^^^^^^^^^^^^^^^^^^^^^^^^^^^
  File "D:\01_Anaconda\envs\ADDMo-Extra\Lib\urllib\request.py", line 525, in open
    response = meth(req, response)
               ^^^^^^^^^^^^^^^^^^^
  File "D:\01_Anaconda\envs\ADDMo-Extra\Lib\urllib\request.py", line 634, in http_response
    response = self.parent.error(
               ^^^^^^^^^^^^^^^^^^
  File "D:\01_Anaconda\envs\ADDMo-Extra\Lib\urllib\request.py", line 563, in error
    return self._call_chain(*args)
           ^^^^^^^^^^^^^^^^^^^^^^^
  File "D:\01_Anaconda\envs\ADDMo-Extra\Lib\urllib\request.py", line 496, in _call_chain
    result = func(*args)
             ^^^^^^^^^^^
  File "D:\01_Anaconda\envs\ADDMo-Extra\Lib\urllib\request.py", line 643, in http_error_default
    raise HTTPError(req.full_url, code, msg, hdrs, fp)
urllib.error.HTTPError: HTTP Error 500: Internal Server Error
During handling of the above exception, another exception occurred:
Traceback (most recent call last):
  File "D:\02_PyCharm\PyCharm 2022.3.2\plugins\python\helpers\pycharm_display\datalore\display\display_.py", line 61, in try_empty_proxy
    urllib_request.urlopen(url, buffer)
  File "D:\01_Anaconda\envs\ADDMo-Extra\Lib\urllib\request.py", line 216, in urlopen
    return opener.open(url, data, timeout)
           ^^^^^^^^^^^^^^^^^^^^^^^^^^^^^^^
  File "D:\01_Anaconda\envs\ADDMo-Extra\Lib\urllib\request.py", line 525, in open
    response = meth(req, response)
               ^^^^^^^^^^^^^^^^^^^
  File "D:\01_Anaconda\envs\ADDMo-Extra\Lib\urllib\request.py", line 634, in http_response
    response = self.parent.error(
               ^^^^^^^^^^^^^^^^^^
  File "D:\01_Anaconda\envs\ADDMo-Extra\Lib\urllib\request.py", line 563, in error
    return self._call_chain(*args)
           ^^^^^^^^^^^^^^^^^^^^^^^
  File "D:\01_Anaconda\envs\ADDMo-Extra\Lib\urllib\request.py", line 496, in _call_chain
    result = func(*args)
             ^^^^^^^^^^^
  File "D:\01_Anaconda\envs\ADDMo-Extra\Lib\urllib\request.py", line 643, in http_error_default
    raise HTTPError(req.full_url, code, msg, hdrs, fp)
urllib.error.HTTPError: HTTP Error 500: Internal Server Error
Error: failed to send plot to http://127.0.0.1:63342
Traceback (most recent call last):
  File "D:\02_PyCharm\PyCharm 2022.3.2\plugins\python\helpers\pycharm_display\datalore\display\display_.py", line 86, in _send_display_message
    urllib_request.urlopen(url, buffer)
  File "D:\01_Anaconda\envs\ADDMo-Extra\Lib\urllib\request.py", line 216, in urlopen
    return opener.open(url, data, timeout)
           ^^^^^^^^^^^^^^^^^^^^^^^^^^^^^^^
  File "D:\01_Anaconda\envs\ADDMo-Extra\Lib\urllib\request.py", line 525, in open
    response = meth(req, response)
               ^^^^^^^^^^^^^^^^^^^
  File "D:\01_Anaconda\envs\ADDMo-Extra\Lib\urllib\request.py", line 634, in http_response
    response = self.parent.error(
               ^^^^^^^^^^^^^^^^^^
  File "D:\01_Anaconda\envs\ADDMo-Extra\Lib\urllib\request.py", line 563, in error
    return self._call_chain(*args)
           ^^^^^^^^^^^^^^^^^^^^^^^
  File "D:\01_Anaconda\envs\ADDMo-Extra\Lib\urllib\request.py", line 496, in _call_chain
    result = func(*args)
             ^^^^^^^^^^^
  File "D:\01_Anaconda\envs\ADDMo-Extra\Lib\urllib\request.py", line 643, in http_error_default
    raise HTTPError(req.full_url, code, msg, hdrs, fp)
urllib.error.HTTPError: HTTP Error 500: Internal Server Error
During handling of the above exception, another exception occurred:
Traceback (most recent call last):
  File "D:\02_PyCharm\PyCharm 2022.3.2\plugins\python\helpers\pycharm_display\datalore\display\display_.py", line 61, in try_empty_proxy
    urllib_request.urlopen(url, buffer)
  File "D:\01_Anaconda\envs\ADDMo-Extra\Lib\urllib\request.py", line 216, in urlopen
    return opener.open(url, data, timeout)
           ^^^^^^^^^^^^^^^^^^^^^^^^^^^^^^^
  File "D:\01_Anaconda\envs\ADDMo-Extra\Lib\urllib\request.py", line 525, in open
    response = meth(req, response)
               ^^^^^^^^^^^^^^^^^^^
  File "D:\01_Anaconda\envs\ADDMo-Extra\Lib\urllib\request.py", line 634, in http_response
    response = self.parent.error(
               ^^^^^^^^^^^^^^^^^^
  File "D:\01_Anaconda\envs\ADDMo-Extra\Lib\urllib\request.py", line 563, in error
    return self._call_chain(*args)
           ^^^^^^^^^^^^^^^^^^^^^^^
  File "D:\01_Anaconda\envs\ADDMo-Extra\Lib\urllib\request.py", line 496, in _call_chain
    result = func(*args)
             ^^^^^^^^^^^
  File "D:\01_Anaconda\envs\ADDMo-Extra\Lib\urllib\request.py", line 643, in http_error_default
    raise HTTPError(req.full_url, code, msg, hdrs, fp)
urllib.error.HTTPError: HTTP Error 500: Internal Server Error
Error: failed to send plot to http://127.0.0.1:63342
Traceback (most recent call last):
  File "D:\02_PyCharm\PyCharm 2022.3.2\plugins\python\helpers\pycharm_display\datalore\display\display_.py", line 86, in _send_display_message
    urllib_request.urlopen(url, buffer)
  File "D:\01_Anaconda\envs\ADDMo-Extra\Lib\urllib\request.py", line 216, in urlopen
    return opener.open(url, data, timeout)
           ^^^^^^^^^^^^^^^^^^^^^^^^^^^^^^^
  File "D:\01_Anaconda\envs\ADDMo-Extra\Lib\urllib\request.py", line 525, in open
    response = meth(req, response)
               ^^^^^^^^^^^^^^^^^^^
  File "D:\01_Anaconda\envs\ADDMo-Extra\Lib\urllib\request.py", line 634, in http_response
    response = self.parent.error(
               ^^^^^^^^^^^^^^^^^^
  File "D:\01_Anaconda\envs\ADDMo-Extra\Lib\urllib\request.py", line 563, in error
    return self._call_chain(*args)
           ^^^^^^^^^^^^^^^^^^^^^^^
  File "D:\01_Anaconda\envs\ADDMo-Extra\Lib\urllib\request.py", line 496, in _call_chain
    result = func(*args)
             ^^^^^^^^^^^
  File "D:\01_Anaconda\envs\ADDMo-Extra\Lib\urllib\request.py", line 643, in http_error_default
    raise HTTPError(req.full_url, code, msg, hdrs, fp)
urllib.error.HTTPError: HTTP Error 500: Internal Server Error
During handling of the above exception, another exception occurred:
Traceback (most recent call last):
  File "D:\02_PyCharm\PyCharm 2022.3.2\plugins\python\helpers\pycharm_display\datalore\display\display_.py", line 61, in try_empty_proxy
    urllib_request.urlopen(url, buffer)
  File "D:\01_Anaconda\envs\ADDMo-Extra\Lib\urllib\request.py", line 216, in urlopen
    return opener.open(url, data, timeout)
           ^^^^^^^^^^^^^^^^^^^^^^^^^^^^^^^
  File "D:\01_Anaconda\envs\ADDMo-Extra\Lib\urllib\request.py", line 525, in open
    response = meth(req, response)
               ^^^^^^^^^^^^^^^^^^^
  File "D:\01_Anaconda\envs\ADDMo-Extra\Lib\urllib\request.py", line 634, in http_response
    response = self.parent.error(
               ^^^^^^^^^^^^^^^^^^
  File "D:\01_Anaconda\envs\ADDMo-Extra\Lib\urllib\request.py", line 563, in error
    return self._call_chain(*args)
           ^^^^^^^^^^^^^^^^^^^^^^^
  File "D:\01_Anaconda\envs\ADDMo-Extra\Lib\urllib\request.py", line 496, in _call_chain
    result = func(*args)
             ^^^^^^^^^^^
  File "D:\01_Anaconda\envs\ADDMo-Extra\Lib\urllib\request.py", line 643, in http_error_default
    raise HTTPError(req.full_url, code, msg, hdrs, fp)
urllib.error.HTTPError: HTTP Error 500: Internal Server Error
Error: failed to send plot to http://127.0.0.1:63342
Traceback (most recent call last):
  File "D:\02_PyCharm\PyCharm 2022.3.2\plugins\python\helpers\pycharm_display\datalore\display\display_.py", line 86, in _send_display_message
    urllib_request.urlopen(url, buffer)
  File "D:\01_Anaconda\envs\ADDMo-Extra\Lib\urllib\request.py", line 216, in urlopen
    return opener.open(url, data, timeout)
           ^^^^^^^^^^^^^^^^^^^^^^^^^^^^^^^
  File "D:\01_Anaconda\envs\ADDMo-Extra\Lib\urllib\request.py", line 525, in open
    response = meth(req, response)
               ^^^^^^^^^^^^^^^^^^^
  File "D:\01_Anaconda\envs\ADDMo-Extra\Lib\urllib\request.py", line 634, in http_response
    response = self.parent.error(
               ^^^^^^^^^^^^^^^^^^
  File "D:\01_Anaconda\envs\ADDMo-Extra\Lib\urllib\request.py", line 563, in error
    return self._call_chain(*args)
           ^^^^^^^^^^^^^^^^^^^^^^^
  File "D:\01_Anaconda\envs\ADDMo-Extra\Lib\urllib\request.py", line 496, in _call_chain
    result = func(*args)
             ^^^^^^^^^^^
  File "D:\01_Anaconda\envs\ADDMo-Extra\Lib\urllib\request.py", line 643, in http_error_default
    raise HTTPError(req.full_url, code, msg, hdrs, fp)
urllib.error.HTTPError: HTTP Error 500: Internal Server Error
During handling of the above exception, another exception occurred:
Traceback (most recent call last):
  File "D:\02_PyCharm\PyCharm 2022.3.2\plugins\python\helpers\pycharm_display\datalore\display\display_.py", line 61, in try_empty_proxy
    urllib_request.urlopen(url, buffer)
  File "D:\01_Anaconda\envs\ADDMo-Extra\Lib\urllib\request.py", line 216, in urlopen
    return opener.open(url, data, timeout)
           ^^^^^^^^^^^^^^^^^^^^^^^^^^^^^^^
  File "D:\01_Anaconda\envs\ADDMo-Extra\Lib\urllib\request.py", line 525, in open
    response = meth(req, response)
               ^^^^^^^^^^^^^^^^^^^
  File "D:\01_Anaconda\envs\ADDMo-Extra\Lib\urllib\request.py", line 634, in http_response
    response = self.parent.error(
               ^^^^^^^^^^^^^^^^^^
  File "D:\01_Anaconda\envs\ADDMo-Extra\Lib\urllib\request.py", line 563, in error
    return self._call_chain(*args)
           ^^^^^^^^^^^^^^^^^^^^^^^
  File "D:\01_Anaconda\envs\ADDMo-Extra\Lib\urllib\request.py", line 496, in _call_chain
    result = func(*args)
             ^^^^^^^^^^^
  File "D:\01_Anaconda\envs\ADDMo-Extra\Lib\urllib\request.py", line 643, in http_error_default
    raise HTTPError(req.full_url, code, msg, hdrs, fp)
urllib.error.HTTPError: HTTP Error 500: Internal Server Error
100%|##########| 50/50 [00:00<00:00, 905.06trial/s, best loss: -0.07658959537572255]
Error: failed to send plot to http://127.0.0.1:63342
Traceback (most recent call last):
  File "D:\02_PyCharm\PyCharm 2022.3.2\plugins\python\helpers\pycharm_display\datalore\display\display_.py", line 86, in _send_display_message
    urllib_request.urlopen(url, buffer)
  File "D:\01_Anaconda\envs\ADDMo-Extra\Lib\urllib\request.py", line 216, in urlopen
    return opener.open(url, data, timeout)
           ^^^^^^^^^^^^^^^^^^^^^^^^^^^^^^^
  File "D:\01_Anaconda\envs\ADDMo-Extra\Lib\urllib\request.py", line 525, in open
    response = meth(req, response)
               ^^^^^^^^^^^^^^^^^^^
  File "D:\01_Anaconda\envs\ADDMo-Extra\Lib\urllib\request.py", line 634, in http_response
    response = self.parent.error(
               ^^^^^^^^^^^^^^^^^^
  File "D:\01_Anaconda\envs\ADDMo-Extra\Lib\urllib\request.py", line 563, in error
    return self._call_chain(*args)
           ^^^^^^^^^^^^^^^^^^^^^^^
  File "D:\01_Anaconda\envs\ADDMo-Extra\Lib\urllib\request.py", line 496, in _call_chain
    result = func(*args)
             ^^^^^^^^^^^
  File "D:\01_Anaconda\envs\ADDMo-Extra\Lib\urllib\request.py", line 643, in http_error_default
    raise HTTPError(req.full_url, code, msg, hdrs, fp)
urllib.error.HTTPError: HTTP Error 500: Internal Server Error
During handling of the above exception, another exception occurred:
Traceback (most recent call last):
  File "D:\02_PyCharm\PyCharm 2022.3.2\plugins\python\helpers\pycharm_display\datalore\display\display_.py", line 61, in try_empty_proxy
    urllib_request.urlopen(url, buffer)
  File "D:\01_Anaconda\envs\ADDMo-Extra\Lib\urllib\request.py", line 216, in urlopen
    return opener.open(url, data, timeout)
           ^^^^^^^^^^^^^^^^^^^^^^^^^^^^^^^
  File "D:\01_Anaconda\envs\ADDMo-Extra\Lib\urllib\request.py", line 525, in open
    response = meth(req, response)
               ^^^^^^^^^^^^^^^^^^^
  File "D:\01_Anaconda\envs\ADDMo-Extra\Lib\urllib\request.py", line 634, in http_response
    response = self.parent.error(
               ^^^^^^^^^^^^^^^^^^
  File "D:\01_Anaconda\envs\ADDMo-Extra\Lib\urllib\request.py", line 563, in error
    return self._call_chain(*args)
           ^^^^^^^^^^^^^^^^^^^^^^^
  File "D:\01_Anaconda\envs\ADDMo-Extra\Lib\urllib\request.py", line 496, in _call_chain
    result = func(*args)
             ^^^^^^^^^^^
  File "D:\01_Anaconda\envs\ADDMo-Extra\Lib\urllib\request.py", line 643, in http_error_default
    raise HTTPError(req.full_url, code, msg, hdrs, fp)
urllib.error.HTTPError: HTTP Error 500: Internal Server Error
Error: failed to send plot to http://127.0.0.1:63342
Traceback (most recent call last):
  File "D:\02_PyCharm\PyCharm 2022.3.2\plugins\python\helpers\pycharm_display\datalore\display\display_.py", line 86, in _send_display_message
    urllib_request.urlopen(url, buffer)
  File "D:\01_Anaconda\envs\ADDMo-Extra\Lib\urllib\request.py", line 216, in urlopen
    return opener.open(url, data, timeout)
           ^^^^^^^^^^^^^^^^^^^^^^^^^^^^^^^
  File "D:\01_Anaconda\envs\ADDMo-Extra\Lib\urllib\request.py", line 525, in open
    response = meth(req, response)
               ^^^^^^^^^^^^^^^^^^^
  File "D:\01_Anaconda\envs\ADDMo-Extra\Lib\urllib\request.py", line 634, in http_response
    response = self.parent.error(
               ^^^^^^^^^^^^^^^^^^
  File "D:\01_Anaconda\envs\ADDMo-Extra\Lib\urllib\request.py", line 563, in error
    return self._call_chain(*args)
           ^^^^^^^^^^^^^^^^^^^^^^^
  File "D:\01_Anaconda\envs\ADDMo-Extra\Lib\urllib\request.py", line 496, in _call_chain
    result = func(*args)
             ^^^^^^^^^^^
  File "D:\01_Anaconda\envs\ADDMo-Extra\Lib\urllib\request.py", line 643, in http_error_default
    raise HTTPError(req.full_url, code, msg, hdrs, fp)
urllib.error.HTTPError: HTTP Error 500: Internal Server Error
During handling of the above exception, another exception occurred:
Traceback (most recent call last):
  File "D:\02_PyCharm\PyCharm 2022.3.2\plugins\python\helpers\pycharm_display\datalore\display\display_.py", line 61, in try_empty_proxy
    urllib_request.urlopen(url, buffer)
  File "D:\01_Anaconda\envs\ADDMo-Extra\Lib\urllib\request.py", line 216, in urlopen
    return opener.open(url, data, timeout)
           ^^^^^^^^^^^^^^^^^^^^^^^^^^^^^^^
  File "D:\01_Anaconda\envs\ADDMo-Extra\Lib\urllib\request.py", line 525, in open
    response = meth(req, response)
               ^^^^^^^^^^^^^^^^^^^
  File "D:\01_Anaconda\envs\ADDMo-Extra\Lib\urllib\request.py", line 634, in http_response
    response = self.parent.error(
               ^^^^^^^^^^^^^^^^^^
  File "D:\01_Anaconda\envs\ADDMo-Extra\Lib\urllib\request.py", line 563, in error
    return self._call_chain(*args)
           ^^^^^^^^^^^^^^^^^^^^^^^
  File "D:\01_Anaconda\envs\ADDMo-Extra\Lib\urllib\request.py", line 496, in _call_chain
    result = func(*args)
             ^^^^^^^^^^^
  File "D:\01_Anaconda\envs\ADDMo-Extra\Lib\urllib\request.py", line 643, in http_error_default
    raise HTTPError(req.full_url, code, msg, hdrs, fp)
urllib.error.HTTPError: HTTP Error 500: Internal Server Error
Error: failed to send plot to http://127.0.0.1:63342
Traceback (most recent call last):
  File "D:\02_PyCharm\PyCharm 2022.3.2\plugins\python\helpers\pycharm_display\datalore\display\display_.py", line 86, in _send_display_message
    urllib_request.urlopen(url, buffer)
  File "D:\01_Anaconda\envs\ADDMo-Extra\Lib\urllib\request.py", line 216, in urlopen
    return opener.open(url, data, timeout)
           ^^^^^^^^^^^^^^^^^^^^^^^^^^^^^^^
  File "D:\01_Anaconda\envs\ADDMo-Extra\Lib\urllib\request.py", line 525, in open
    response = meth(req, response)
               ^^^^^^^^^^^^^^^^^^^
  File "D:\01_Anaconda\envs\ADDMo-Extra\Lib\urllib\request.py", line 634, in http_response
    response = self.parent.error(
               ^^^^^^^^^^^^^^^^^^
  File "D:\01_Anaconda\envs\ADDMo-Extra\Lib\urllib\request.py", line 563, in error
    return self._call_chain(*args)
           ^^^^^^^^^^^^^^^^^^^^^^^
  File "D:\01_Anaconda\envs\ADDMo-Extra\Lib\urllib\request.py", line 496, in _call_chain
    result = func(*args)
             ^^^^^^^^^^^
  File "D:\01_Anaconda\envs\ADDMo-Extra\Lib\urllib\request.py", line 643, in http_error_default
    raise HTTPError(req.full_url, code, msg, hdrs, fp)
urllib.error.HTTPError: HTTP Error 500: Internal Server Error
During handling of the above exception, another exception occurred:
Traceback (most recent call last):
  File "D:\02_PyCharm\PyCharm 2022.3.2\plugins\python\helpers\pycharm_display\datalore\display\display_.py", line 61, in try_empty_proxy
    urllib_request.urlopen(url, buffer)
  File "D:\01_Anaconda\envs\ADDMo-Extra\Lib\urllib\request.py", line 216, in urlopen
    return opener.open(url, data, timeout)
           ^^^^^^^^^^^^^^^^^^^^^^^^^^^^^^^
  File "D:\01_Anaconda\envs\ADDMo-Extra\Lib\urllib\request.py", line 525, in open
    response = meth(req, response)
               ^^^^^^^^^^^^^^^^^^^
  File "D:\01_Anaconda\envs\ADDMo-Extra\Lib\urllib\request.py", line 634, in http_response
    response = self.parent.error(
               ^^^^^^^^^^^^^^^^^^
  File "D:\01_Anaconda\envs\ADDMo-Extra\Lib\urllib\request.py", line 563, in error
    return self._call_chain(*args)
           ^^^^^^^^^^^^^^^^^^^^^^^
  File "D:\01_Anaconda\envs\ADDMo-Extra\Lib\urllib\request.py", line 496, in _call_chain
    result = func(*args)
             ^^^^^^^^^^^
  File "D:\01_Anaconda\envs\ADDMo-Extra\Lib\urllib\request.py", line 643, in http_error_default
    raise HTTPError(req.full_url, code, msg, hdrs, fp)
urllib.error.HTTPError: HTTP Error 500: Internal Server Error
Error: failed to send plot to http://127.0.0.1:63342
Traceback (most recent call last):
  File "D:\02_PyCharm\PyCharm 2022.3.2\plugins\python\helpers\pycharm_display\datalore\display\display_.py", line 86, in _send_display_message
    urllib_request.urlopen(url, buffer)
  File "D:\01_Anaconda\envs\ADDMo-Extra\Lib\urllib\request.py", line 216, in urlopen
    return opener.open(url, data, timeout)
           ^^^^^^^^^^^^^^^^^^^^^^^^^^^^^^^
  File "D:\01_Anaconda\envs\ADDMo-Extra\Lib\urllib\request.py", line 525, in open
    response = meth(req, response)
               ^^^^^^^^^^^^^^^^^^^
  File "D:\01_Anaconda\envs\ADDMo-Extra\Lib\urllib\request.py", line 634, in http_response
    response = self.parent.error(
               ^^^^^^^^^^^^^^^^^^
  File "D:\01_Anaconda\envs\ADDMo-Extra\Lib\urllib\request.py", line 563, in error
    return self._call_chain(*args)
           ^^^^^^^^^^^^^^^^^^^^^^^
  File "D:\01_Anaconda\envs\ADDMo-Extra\Lib\urllib\request.py", line 496, in _call_chain
    result = func(*args)
             ^^^^^^^^^^^
  File "D:\01_Anaconda\envs\ADDMo-Extra\Lib\urllib\request.py", line 643, in http_error_default
    raise HTTPError(req.full_url, code, msg, hdrs, fp)
urllib.error.HTTPError: HTTP Error 500: Internal Server Error
During handling of the above exception, another exception occurred:
Traceback (most recent call last):
  File "D:\02_PyCharm\PyCharm 2022.3.2\plugins\python\helpers\pycharm_display\datalore\display\display_.py", line 61, in try_empty_proxy
    urllib_request.urlopen(url, buffer)
  File "D:\01_Anaconda\envs\ADDMo-Extra\Lib\urllib\request.py", line 216, in urlopen
    return opener.open(url, data, timeout)
           ^^^^^^^^^^^^^^^^^^^^^^^^^^^^^^^
  File "D:\01_Anaconda\envs\ADDMo-Extra\Lib\urllib\request.py", line 525, in open
    response = meth(req, response)
               ^^^^^^^^^^^^^^^^^^^
  File "D:\01_Anaconda\envs\ADDMo-Extra\Lib\urllib\request.py", line 634, in http_response
    response = self.parent.error(
               ^^^^^^^^^^^^^^^^^^
  File "D:\01_Anaconda\envs\ADDMo-Extra\Lib\urllib\request.py", line 563, in error
    return self._call_chain(*args)
           ^^^^^^^^^^^^^^^^^^^^^^^
  File "D:\01_Anaconda\envs\ADDMo-Extra\Lib\urllib\request.py", line 496, in _call_chain
    result = func(*args)
             ^^^^^^^^^^^
  File "D:\01_Anaconda\envs\ADDMo-Extra\Lib\urllib\request.py", line 643, in http_error_default
    raise HTTPError(req.full_url, code, msg, hdrs, fp)
urllib.error.HTTPError: HTTP Error 500: Internal Server Error
Error: failed to send plot to http://127.0.0.1:63342
Traceback (most recent call last):
  File "D:\02_PyCharm\PyCharm 2022.3.2\plugins\python\helpers\pycharm_display\datalore\display\display_.py", line 86, in _send_display_message
    urllib_request.urlopen(url, buffer)
  File "D:\01_Anaconda\envs\ADDMo-Extra\Lib\urllib\request.py", line 216, in urlopen
    return opener.open(url, data, timeout)
           ^^^^^^^^^^^^^^^^^^^^^^^^^^^^^^^
  File "D:\01_Anaconda\envs\ADDMo-Extra\Lib\urllib\request.py", line 525, in open
    response = meth(req, response)
               ^^^^^^^^^^^^^^^^^^^
  File "D:\01_Anaconda\envs\ADDMo-Extra\Lib\urllib\request.py", line 634, in http_response
    response = self.parent.error(
               ^^^^^^^^^^^^^^^^^^
  File "D:\01_Anaconda\envs\ADDMo-Extra\Lib\urllib\request.py", line 563, in error
    return self._call_chain(*args)
           ^^^^^^^^^^^^^^^^^^^^^^^
  File "D:\01_Anaconda\envs\ADDMo-Extra\Lib\urllib\request.py", line 496, in _call_chain
    result = func(*args)
             ^^^^^^^^^^^
  File "D:\01_Anaconda\envs\ADDMo-Extra\Lib\urllib\request.py", line 643, in http_error_default
    raise HTTPError(req.full_url, code, msg, hdrs, fp)
urllib.error.HTTPError: HTTP Error 500: Internal Server Error
During handling of the above exception, another exception occurred:
Traceback (most recent call last):
  File "D:\02_PyCharm\PyCharm 2022.3.2\plugins\python\helpers\pycharm_display\datalore\display\display_.py", line 61, in try_empty_proxy
    urllib_request.urlopen(url, buffer)
  File "D:\01_Anaconda\envs\ADDMo-Extra\Lib\urllib\request.py", line 216, in urlopen
    return opener.open(url, data, timeout)
           ^^^^^^^^^^^^^^^^^^^^^^^^^^^^^^^
  File "D:\01_Anaconda\envs\ADDMo-Extra\Lib\urllib\request.py", line 525, in open
    response = meth(req, response)
               ^^^^^^^^^^^^^^^^^^^
  File "D:\01_Anaconda\envs\ADDMo-Extra\Lib\urllib\request.py", line 634, in http_response
    response = self.parent.error(
               ^^^^^^^^^^^^^^^^^^
  File "D:\01_Anaconda\envs\ADDMo-Extra\Lib\urllib\request.py", line 563, in error
    return self._call_chain(*args)
           ^^^^^^^^^^^^^^^^^^^^^^^
  File "D:\01_Anaconda\envs\ADDMo-Extra\Lib\urllib\request.py", line 496, in _call_chain
    result = func(*args)
             ^^^^^^^^^^^
  File "D:\01_Anaconda\envs\ADDMo-Extra\Lib\urllib\request.py", line 643, in http_error_default
    raise HTTPError(req.full_url, code, msg, hdrs, fp)
urllib.error.HTTPError: HTTP Error 500: Internal Server Error
100%|##########| 50/50 [00:00<00:00, 905.06trial/s, best loss: -0.07658959537572255]
Error: failed to send plot to http://127.0.0.1:63342
Traceback (most recent call last):
  File "D:\02_PyCharm\PyCharm 2022.3.2\plugins\python\helpers\pycharm_display\datalore\display\display_.py", line 86, in _send_display_message
    urllib_request.urlopen(url, buffer)
  File "D:\01_Anaconda\envs\ADDMo-Extra\Lib\urllib\request.py", line 216, in urlopen
    return opener.open(url, data, timeout)
           ^^^^^^^^^^^^^^^^^^^^^^^^^^^^^^^
  File "D:\01_Anaconda\envs\ADDMo-Extra\Lib\urllib\request.py", line 525, in open
    response = meth(req, response)
               ^^^^^^^^^^^^^^^^^^^
  File "D:\01_Anaconda\envs\ADDMo-Extra\Lib\urllib\request.py", line 634, in http_response
    response = self.parent.error(
               ^^^^^^^^^^^^^^^^^^
  File "D:\01_Anaconda\envs\ADDMo-Extra\Lib\urllib\request.py", line 563, in error
    return self._call_chain(*args)
           ^^^^^^^^^^^^^^^^^^^^^^^
  File "D:\01_Anaconda\envs\ADDMo-Extra\Lib\urllib\request.py", line 496, in _call_chain
    result = func(*args)
             ^^^^^^^^^^^
  File "D:\01_Anaconda\envs\ADDMo-Extra\Lib\urllib\request.py", line 643, in http_error_default
    raise HTTPError(req.full_url, code, msg, hdrs, fp)
urllib.error.HTTPError: HTTP Error 500: Internal Server Error
During handling of the above exception, another exception occurred:
Traceback (most recent call last):
  File "D:\02_PyCharm\PyCharm 2022.3.2\plugins\python\helpers\pycharm_display\datalore\display\display_.py", line 61, in try_empty_proxy
    urllib_request.urlopen(url, buffer)
  File "D:\01_Anaconda\envs\ADDMo-Extra\Lib\urllib\request.py", line 216, in urlopen
    return opener.open(url, data, timeout)
           ^^^^^^^^^^^^^^^^^^^^^^^^^^^^^^^
  File "D:\01_Anaconda\envs\ADDMo-Extra\Lib\urllib\request.py", line 525, in open
    response = meth(req, response)
               ^^^^^^^^^^^^^^^^^^^
  File "D:\01_Anaconda\envs\ADDMo-Extra\Lib\urllib\request.py", line 634, in http_response
    response = self.parent.error(
               ^^^^^^^^^^^^^^^^^^
  File "D:\01_Anaconda\envs\ADDMo-Extra\Lib\urllib\request.py", line 563, in error
    return self._call_chain(*args)
           ^^^^^^^^^^^^^^^^^^^^^^^
  File "D:\01_Anaconda\envs\ADDMo-Extra\Lib\urllib\request.py", line 496, in _call_chain
    result = func(*args)
             ^^^^^^^^^^^
  File "D:\01_Anaconda\envs\ADDMo-Extra\Lib\urllib\request.py", line 643, in http_error_default
    raise HTTPError(req.full_url, code, msg, hdrs, fp)
urllib.error.HTTPError: HTTP Error 500: Internal Server Error